Workbook
Name MANDARINA_SEASON: WEEKLY_TEAMS!$A$1:$CY$52
Name PLAYER_STAT_TABLE: PLAYER_STAT!$1:$984
Name LeagueStandingsTable: LEAGUE_STANDINGS!$B$13:$L$110

Sheet MATCH_DATES
B1: Season to start 9/4/25
A2: 45904 | B2: MATCH DAY 1
A3: 45911 | B3: MATCH DAY 2
A4: 45918 | B4: MATCH DAY 3
A5: 45925 | B5: MATCH DAY 4
A6: 45932 | B6: MATCH DAY 5
A7: 45939 | B7: MATCH DAY 6
A8: 45946 | B8: MATCH DAY 7
A9: 45953 | B9: MATCH DAY 8
A15: WHAT IS THE PRIORITY SORTING FOR THIS
A17: With the updated formula I provided, the priority sorting is as follows:
A19: Total Points (CQ) - Highest priority, sorted in descending order.
A21: Wins (CR) - Second priority, sorted in descending order.
A23: Draws (CS) - Third priority, sorted in descending order.
A25: Losses (CT) - Fourth priority, sorted in descending order.
A27: Goals (CU) - Fifth priority, sorted in descending order.
A29: Clean Sheets (CV) - Sixth priority, sorted in descending order.
A31: Attendance (Matches Played) (CP) - Last priority, sorted in descending order.
A33: This order ensures that Total Points will always take precedence, followed by the other criteria in the order specified. This way, even if a player or team has high values in goals or clean sheets, the primary sorting criterion will still be Total Points.

Sheet PLAYER_PROFILE
A1: Timestamp | B1: PlayerName | C1: Nickname | D1: MemberStatus | E1: Agreed
A2: 45897.806 | B2: Joseph Muro | D2: With a Buddy / Con un Buddy | E2: Yes
A3: 45897.808 | B3: Juan Pablo Valladares | C3: Juanpi | D3: Weekly Player / Jugador Semanal | E3: Yes
A4: 45897.81 | B4: Iury Da Silva | C4: Da Silva | D4: With a Buddy / Con un Buddy | E4: Yes
A5: 45897.812 | B5: José Blanco | C5: Isco | D5: Weekly Player / Jugador Semanal | E5: Yes
A6: 45897.812 | B6: Gerardo Mendizabal | D6: Weekly Player / Jugador Semanal | E6: Yes
A7: 45897.822 | B7: Carlos Haro | D7: With a Buddy / Con un Buddy | E7: Yes
A8: 45897.832 | B8: Carlos Silva | C8: Carlos | D8: Weekly Player / Jugador Semanal | E8: Yes
A9: 45897.836 | B9: Walter Acero | D9: Sub / Suplente | E9: Yes
A10: 45897.848 | B10: Fabian Munoz | D10: Weekly Player / Jugador Semanal | E10: Yes
A11: 45897.853 | B11: Jordan toledo | C11: Jordan | D11: Weekly Player / Jugador Semanal | E11: Yes
A12: 45897.854 | B12: Nicolas Galviz | D12: Weekly Player / Jugador Semanal | E12: Yes
A13: 45897.869 | B13: Jhony Sanchez | D13: Weekly Player / Jugador Semanal | E13: Yes
A14: 45897.927 | B14: Rudy Ramirez | D14: Weekly Player / Jugador Semanal | E14: Yes
A15: 45897.934 | B15: Jose Sarza | C15: Jose | D15: Weekly Player / Jugador Semanal | E15: Yes
A16: 45897.945 | B16: luis enrique martinez | C16: Cuñis | D16: Weekly Player / Jugador Semanal | E16: Yes
A17: 45897.962 | B17: Efrain Jauregui | C17: Poli | D17: Weekly Player / Jugador Semanal | E17: Yes
A18: 45897.968 | B18: Eder Martinez | C18: Eder | D18: With a Buddy / Con un Buddy | E18: Yes
A19: 45897.998 | B19: Victor Nizama | C19: Victor N | D19: Weekly Player / Jugador Semanal | E19: Yes
A20: 45898.035 | B20: David Toro | D20: Weekly Player / Jugador Semanal | E20: Yes
A21: 45898.501 | B21: C Valverde | C21: Valverde | D21: Weekly Player / Jugador Semanal | E21: Yes
A22: 45898.703 | B22: Jesus David | C22: Chuchin | D22: With a Buddy / Con un Buddy | E22: Yes
A23: 45898.821 | B23: Asdruval Villanueva | D23: Weekly Player / Jugador Semanal | E23: Yes
A24: 45898.857 | B24: Osmin DLeon | C24: Sobras | D24: Weekly Player / Jugador Semanal | E24: Yes
A25: 45899.54 | B25: Honorio Hernandez | C25: Honorio | D25: With a Buddy / Con un Buddy | E25: Yes
A26: 45901.523 | B26: Andres Aguayo | D26: With a Buddy / Con un Buddy | E26: Yes
A27: 45901.654 | B27: Roberto Carlos Cruz | C27: Presi | D27: Weekly Player / Jugador Semanal | E27: Yes
A28: 45902.54 | B28: Cesar Lopez | D28: With a Buddy / Con un Buddy | E28: Yes
A29: 45902.651 | B29: Jeff Arce | D29: Sub / Suplente | E29: Yes
A30: 45903.972 | B30: Jose Cerf | C30: Chato | D30: Weekly Player / Jugador Semanal | E30: Yes
A31: 45904.415 | B31: Luis De La Rosa | C31: Chavito/Taliban | D31: With a Buddy / Con un Buddy | E31: Yes
A32: 45904.423 | B32: Rodolfo Toledo | D32: Weekly Player / Jugador Semanal | E32: Yes
A33: 45904.512 | B33: Luis Urueta | C33: Javier | D33: Weekly Player / Jugador Semanal | E33: Yes
A34: 45904.518 | B34: Alex Meneses | D34: With a Buddy / Con un Buddy | E34: Yes
A35: 45904.526 | B35: Gabriel Alava | C35: Gabo | D35: Weekly Player / Jugador Semanal | E35: Yes
A36: 45904.53 | B36: Guillermo Lenz | C36: Bolivia | D36: With a Buddy / Con un Buddy | E36: Yes
A37: 45904.786 | B37: Crisanto Valencia | C37: Valencia | D37: Weekly Player / Jugador Semanal | E37: Yes
A38: 45904.872 | B38: Michael Enriquez | C38: Mikey | D38: Weekly Player / Jugador Semanal | E38: Yes
A39: 45904.874 | B39: Oscar Rosales | C39: Pirlo | D39: Weekly Player / Jugador Semanal | E39: Yes
A40: 45904.965 | B40: J Enerson | D40: Weekly Player / Jugador Semanal | E40: Yes
...

Sheet WEEKLY_TEAMS
C1: MATCHDAY 1 | O1: MATCHDAY 2 | AA1: MATCHDAY 3 | AM1: MATCHDAY 4 | AY1: MATCHDAY 5 | BK1: MATCHDAY 6 | BW1: MATCHDAY 7 | CI1: MATCHDAY 8
A2: STATUS | B2: PLAYER | C2: MD 1 TEAM | D2: MD 1 TOTAL POINTS | E2: MD 1 ATTENDANCE | F2: MD 1 POINTS | G2: MD 1 (W) | H2: MD 1 (D) | I2: MD 1 (L) | J2: MD 1 GOALS | K2: MD 1 GOALIE POINT | L2: MD 1 CLEAN SHEET | M2: MD 1 RANK | N2: MD 1 FORM | O2: MD 2 TEAM | P2: MD 2 ACCUMULATED POINTS | Q2: MD 2 ATTENDANCE | R2: MD 2 POINTS | S2: MD 2 (W) | T2: MD 2 (D) | U2: MD 2 (L) | V2: MD 2 GOALS | W2: MD 2 GOALIE POINT | X2: MD 2 Clean Sheet | Y2: MD 2 RANK | Z2: MD 2 FORM | AA2: MD 3 TEAM | AB2: MD 3 ACCUMULATED POINTS | AC2: MD 3 ATTENDANCE | AD2: MD 3 POINTS | AE2: MD 3 (W) | AF2: MD 3 (D) | AG2: MD 3 (L) | AH2: MD 3 GOALS | AI2: MD 3 GOALIE POINT | AJ2: MD 3 CLEAN SHEET | AK2: MD 3 RANK | AL2: MD 3 FORM | AM2: MD 4 TEAM | AN2: MD 4 ACCUMULATED POINTS | AO2: MD 4 ATTENDANCE | AP2: MD 4 POINTS | AQ2: MD 4 (W) | AR2: MD 4 (D) | AS2: MD 4 (L) | AT2: MD 4 GOALS | AU2: MD 4 GOALIE POINT | AV2: MD 4 Clean Sheet | AW2: MD 4 RANK | AX2: MD 4 FORM | AY2: MD 5 TEAM | AZ2: MD 5 ACCUMULATED POINTS | BA2: MD 5 ATTENDANCE | BB2: MD 5 POINTS | BC2: MD 5 (W) | BD2: MD 5 (D) | BE2: MD 5 (L) | BF2: MD 5 GOALS | BG2: MD 5 GOALIE POINT | BH2: MD 5 CLEAN SHEET | BI2: MD 5 RANK | BJ2: MD 5 FORM | BK2: MD 6 TEAM | BL2: MD 6 ACCUMULATED POINTS | BM2: MD 6 ATTENDANCE | BN2: MD 6 POINTS | BO2: MD 6 (W) | BP2: MD 6 (D) | BQ2: MD 6 (L) | BR2: MD 6 GOALS | BS2: MD 6 GOALIE POINT | BT2: MD 6 Clean Sheet | BU2: MD 6 RANK | BV2: MD 6 FORM | BW2: MD 7 TEAM | BX2: MD 7 ACCUMULATED POINTS | BY2: MD 7 ATTENDANCE | BZ2: MD 7 POINTS | CA2: MD 7 (W) | CB2: MD 7 (D) | CC2: MD 7 (L) | CD2: MD 7 GOALS | CE2: MD 7 GOALIE POINT | CF2: MD 7 CLEAN SHEET | CG2: MD 7 RANK | CH2: MD 7 FORM | CI2: MD 8 TEAM | CJ2: MD 8 ACCUMULATED POINTS | CK2: MD 8 ATTENDANCE | CL2: MD 8 POINTS | CM2: MD 8 (W) | CN2: MD 8 (D) | CO2: MD 8 (L) | CP2: MD 8 GOALS | CQ2: MD 8 GOALIE POINT | CR2: MD 8 Clean Sheet | CS2: MD 8 RANK | CT2: MD 8 FORM | CU2: POINTS FOR GAMES | CV2: SEASON STATUS | CW2: PLAYER_ | CX2: TOTAL POINTS | CY2: ATTENDANCE | CZ2: WINS | DA2: DRAWS | DB2: LOSSES | DC2: GOALS | DD2: GOALIE POINT | DE2: CLEAN SHEETS
A3: 🍂🎃 | B3: Alex 👬 Gus | C3: GREEN | D3: =SUM(E3:F3)+K3 -> 4 | E3: =COUNTA(C3)*2 -> 2 | F3: =(G3*2)+(H3*1) -> 2 | G3: =IF(C3<>"", COUNTIFS(MATCH_INPUT!$K$2:$K$5,C3), 0) -> 1 | H3: =IF(C3<>"", COUNTIFS(MATCH_INPUT!$F$2:$F$5, C3, MATCH_INPUT!$K$2:$K$5, "Draw") + COUNTIFS(MATCH_INPUT!$J$2:$J$5, C3, MATCH_INPUT!$K$2:$K$5, "Draw"), 0) -> 0 | I3: =IF(C3<>"", COUNTIFS(MATCH_INPUT!$F$2:$F$5, C3, MATCH_INPUT!$K$2:$K$5, "<>"&C3, MATCH_INPUT!$K$2:$K$5, "<>Draw", MATCH_INPUT!$K$2:$K$5, "<>""") + COUNTIFS(MATCH_INPUT!$J$2:$J$5, C3, MATCH_INPUT!$K$2:$K$5, "<>"&C3, MATCH_INPUT!$K$2:$K$5, "<>Draw", MATCH_INPUT!$K$2:$K$5, "<>"""), 0) -> 1 | J3: {=IFERROR( INDEX(PLAYER_STAT!E$2:E64, MATCH(1, (PLAYER_STAT!A$2:A64 = MATCH_DATES!$A$2) * (PLAYER_STAT!D$2:D64 = $B3), 0) ), "" )} | K3: {=IFERROR( INDEX(PLAYER_STAT!F$2:F64, MATCH(1, (PLAYER_STAT!A$2:A64 = MATCH_DATES!$A$2) * (PLAYER_STAT!D$2:D64 = $B3), 0) ), "" )} | L3: {=IFERROR( INDEX(PLAYER_STAT!G$2:G64, MATCH(1, (PLAYER_STAT!A$2:A64 = MATCH_DATES!$A$2) * (PLAYER_STAT!D$2:D64 = $B3), 0) ), "" )} | M3: =RANK(D3, D$3:D$39, 0) -> 11 | N3: =IF(M3<1, "↑", IF(M3>1, "↓", "=")) -> ↓ | O3: BLUE | P3: =SUM(Q3:R3)+D3+W3 -> 9 | Q3: =COUNTA(O3)*2 -> 2 | R3: =(S3*2)+(T3*1) -> 3 | S3: =IF(O3<>"", COUNTIFS(MATCH_INPUT!$K$6:$K$9,O3), 0) -> 1 | T3: =IF(O3<>"", COUNTIFS(MATCH_INPUT!$F$6:$F$9, O3, MATCH_INPUT!$K$6:$K$9, "Draw") + COUNTIFS(MATCH_INPUT!$J$6:$J$9, O3, MATCH_INPUT!$K$6:$K$9, "Draw"), 0) -> 1 | U3: =IF(O3<>"", COUNTIFS(MATCH_INPUT!$F$6:$F$9, O3, MATCH_INPUT!$K$6:$K$9, "<>"&O3, MATCH_INPUT!$K$6:$K$9, "<>Draw", MATCH_INPUT!$K$6:$K$9, "<>""") + COUNTIFS(MATCH_INPUT!$J$6:$J$9, O3, MATCH_INPUT!$K$6:$K$9, "<>"&O3, MATCH_INPUT!$K$6:$K$9, "<>Draw", MATCH_INPUT!$K$6:$K$9, "<>"""), 0) -> 0 | V3: {=IFERROR( INDEX(PLAYER_STAT!E$2:E64, MATCH(1, (PLAYER_STAT!A$2:A64 = MATCH_DATES!$A$3) * (PLAYER_STAT!D$2:D64 = $B3), 0) ), "" )} | W3: {=IFERROR( INDEX(PLAYER_STAT!F$2:F64, MATCH(1, (PLAYER_STAT!A$2:A64 = MATCH_DATES!$A$3) * (PLAYER_STAT!D$2:D64 = $B3), 0) ), "" )} | X3: {=IFERROR( INDEX(PLAYER_STAT!G$2:G64, MATCH(1, (PLAYER_STAT!A$2:A64 = MATCH_DATES!$A$3) * (PLAYER_STAT!D$2:D64 = $B3), 0) ), "" )} | Y3: =RANK(P3, P$3:P$38, 0) -> 9 | Z3: =IF(Y3<M3, "↑", IF(Y3>M3, "↓", "=")) -> ↑ | AA3: MAGENTA | AB3: =SUM(AC3:AD3)+P3+AI3 -> 13 | AC3: =COUNTA(AA3)*2 -> 2 | AD3: =SUM(AE3*2)+(AF3*1) -> 2 | AE3: =IF(AA3<>"", COUNTIFS(MATCH_INPUT!$K$10:$K$13,AA3), 0) -> 1 | AF3: =IF(AA3<>"", COUNTIFS(MATCH_INPUT!$F$10:$F$13, AA3, MATCH_INPUT!$K$10:$K$13, "Draw") + COUNTIFS(MATCH_INPUT!$J$10:$J$13, AA3, MATCH_INPUT!$K$10:$K$13, "Draw"), 0) -> 0 | AG3: =IF(AA3<>"", COUNTIFS(MATCH_INPUT!$F$10:$F$13, AA3, MATCH_INPUT!$K$10:$K$13, "<>"&AA3, MATCH_INPUT!$K$10:$K$13, "<>Draw", MATCH_INPUT!$K$10:$K$13, "<>""") + COUNTIFS(MATCH_INPUT!$J$10:$J$13, AA3, MATCH_INPUT!$K$10:$K$13, "<>"&AA3, MATCH_INPUT!$K$10:$K$13, "<>Draw", MATCH_INPUT!$K$10:$K$13, "<>"""), 0) -> 1 | AH3: {=IFERROR( INDEX(PLAYER_STAT!E$2:E64, MATCH(1, (PLAYER_STAT!A$2:A64 = MATCH_DATES!$A$4) * (PLAYER_STAT!D$2:D64 = $B3), 0) ), "" )} | AI3: {=IFERROR( INDEX(PLAYER_STAT!F$2:F64, MATCH(1, (PLAYER_STAT!A$2:A64 = MATCH_DATES!$A$4) * (PLAYER_STAT!D$2:D64 = $B3), 0) ), "" )} | AJ3: {=IFERROR( INDEX(PLAYER_STAT!G$2:G64, MATCH(1, (PLAYER_STAT!A$2:A64 = MATCH_DATES!$A$4) * (PLAYER_STAT!D$2:D64 = $B3), 0) ), "" )} | AK3: =RANK(AB3, AB$3:AB$38, 0) -> 10 | AL3: =IF(AK3<Y3, "↑", IF(AK3>Y3, "↓", "=")) -> ↓ | AM3: MAGENTA | AN3: =SUM(AO3:AP3)+AB3+AU3 -> 15 | AO3: =COUNTA(AM3)*2 -> 2 | AP3: =SUM(AQ3*2)+(AR3*1) -> 0 | AQ3: =IF(AM3<>"", COUNTIFS(MATCH_INPUT!$K$14:$K$17,AM3), 0) -> 0 | AR3: =IF(AM3<>"", COUNTIFS(MATCH_INPUT!$F$14:$F$17, AM3, MATCH_INPUT!$K$14:$K$17, "Draw") + COUNTIFS(MATCH_INPUT!$J$14:$J$17, AM3, MATCH_INPUT!$K$14:$K$17, "Draw"), 0) -> 0 | AS3: =IF(AM3<>"", COUNTIFS(MATCH_INPUT!$F$14:$F$17, AM3, MATCH_INPUT!$K$14:$K$17, "<>"&AM3, MATCH_INPUT!$K$14:$K$17, "<>Draw", MATCH_INPUT!$K$14:$K$17, "<>""") + COUNTIFS(MATCH_INPUT!$J$14:$J$17, AM3, MATCH_INPUT!$K$14:$K$17, "<>"&AM3, MATCH_INPUT!$K$14:$K$17, "<>Draw", MATCH_INPUT!$K$14:$K$17, "<>"""), 0) -> 2 | AT3: {=IFERROR( INDEX(PLAYER_STAT!E$2:E64, MATCH(1, (PLAYER_STAT!A$2:A64 = MATCH_DATES!$A$5) * (PLAYER_STAT!D$2:D64 = $B3), 0) ), "" )} | AU3: {=IFERROR( INDEX(PLAYER_STAT!F$2:F64, MATCH(1, (PLAYER_STAT!A$2:A64 = MATCH_DATES!$A$5) * (PLAYER_STAT!D$2:D64 = $B3), 0) ), "" )} | AV3: {=IFERROR( INDEX(PLAYER_STAT!G$2:G64, MATCH(1, (PLAYER_STAT!A$2:A64 = MATCH_DATES!$A$5) * (PLAYER_STAT!D$2:D64 = $B3), 0) ), "" )} | AW3: =RANK(AN3, AN$3:AN$38, 0) -> 16 | AX3: =IF(AW3<AK3, "↑", IF(AW3>AK3, "↓", "=")) -> ↓ | AY3: ORANGE | AZ3: =SUM(BA3:BB3)+BG3+AN3 -> 18 | BA3: =COUNTA(AY3)*2 -> 2 | BB3: =SUM(BC3*2) + (BD3*1) + SUMIFS(MATCH_INPUT!$G$18:$G$21, MATCH_INPUT!$F$18:$F$21, AY3) + SUMIFS(MATCH_INPUT!$I$18:$I$21, MATCH_INPUT!$J$18:$J$21, AY3) -> 1 | BC3: =IF(AY3<>"", COUNTIFS(MATCH_INPUT!$K$18:$K$21,AY3), 0) -> 0 | BD3: =IF(AY3<>"", COUNTIFS(MATCH_INPUT!$F$18:$F$21, AY3, MATCH_INPUT!$K$18:$K$21, "Draw") + COUNTIFS(MATCH_INPUT!$J$18:$J$21, AY3, MATCH_INPUT!$K$18:$K$21, "Draw"), 0) -> 0 | BE3: =IF(AY3<>"", COUNTIFS(MATCH_INPUT!$F$18:$F$21, AY3, MATCH_INPUT!$K$18:$K$21, "<>"&AY3, MATCH_INPUT!$K$18:$K$21, "<>Draw", MATCH_INPUT!$K$18:$K$21, "<>""") + COUNTIFS(MATCH_INPUT!$J$18:$J$21, AY3, MATCH_INPUT!$K$18:$K$21, "<>"&AY3, MATCH_INPUT!$K$18:$K$21, "<>Draw", MATCH_INPUT!$K$18:$K$21, "<>"""), 0) -> 2 | BF3: {=IFERROR( INDEX(PLAYER_STAT!E$2:E64, MATCH(1, (PLAYER_STAT!A$2:A64 = MATCH_DATES!$A$6) * (PLAYER_STAT!D$2:D64 = $B3), 0) ), "" )} | BG3: {=IFERROR( INDEX(PLAYER_STAT!F$2:F64, MATCH(1, (PLAYER_STAT!A$2:A64 = MATCH_DATES!$A$6) * (PLAYER_STAT!D$2:D64 = $B3), 0) ), "" )} | BH3: {=IFERROR( INDEX(PLAYER_STAT!G$2:G64, MATCH(1, (PLAYER_STAT!A$2:A64 = MATCH_DATES!$A$6) * (PLAYER_STAT!D$2:D64 = $B3), 0) ), "" )} | BI3: =RANK(AZ3, AZ$3:AZ$38, 0) -> 24 | BJ3: =IF(BI3<AW3, "↑", IF(BI3>AW3, "↓", "=")) -> ↓ | BK3: MAGENTA | BL3: =SUM(BM3:BN3)+BS3+AZ3 -> 27 | BM3: =COUNTA(BK3)*2 -> 2 | BN3: =SUM(BO3*2) + (BP3*1) + SUMIFS(MATCH_INPUT!$G$22:$G$25, MATCH_INPUT!$F$22:$F$25, BK3) + SUMIFS(MATCH_INPUT!$I$22:$I$25, MATCH_INPUT!$J$22:$J$25, BK3) -> 7 | BO3: =IF(BK3<>"", COUNTIFS(MATCH_INPUT!$K$22:$K$25,BK3), 0) -> 1 | BP3: =IF(BK3<>"", COUNTIFS(MATCH_INPUT!$F$22:$F$25, BK3, MATCH_INPUT!$K$22:$K$25, "Draw") + COUNTIFS(MATCH_INPUT!$J$22:$J$25, BK3, MATCH_INPUT!$K$22:$K$25, "Draw"), 0) -> 1 | BQ3: =IF(BK3<>"", COUNTIFS(MATCH_INPUT!$F$22:$F$25, BK3, MATCH_INPUT!$K$22:$K$25, "<>"&BK3, MATCH_INPUT!$K$22:$K$25, "<>Draw", MATCH_INPUT!$K$22:$K$25, "<>""") + COUNTIFS(MATCH_INPUT!$J$22:$J$25, BK3, MATCH_INPUT!$K$22:$K$25, "<>"&BK3, MATCH_INPUT!$K$22:$K$25, "<>Draw", MATCH_INPUT!$K$22:$K$25, "<>"""), 0) -> 0 | BR3: {=IFERROR( INDEX(PLAYER_STAT!E$2:E64, MATCH(1, (PLAYER_STAT!A$2:A64 = MATCH_DATES!$A$7) * (PLAYER_STAT!D$2:D64 = $B3), 0) ), "" )} | BS3: {=IFERROR( INDEX(PLAYER_STAT!F$2:F64, MATCH(1, (PLAYER_STAT!A$2:A64 = MATCH_DATES!$A$7) * (PLAYER_STAT!D$2:D64 = $B3), 0) ), "" )} | BT3: {=IFERROR( INDEX(PLAYER_STAT!G$2:G64, MATCH(1, (PLAYER_STAT!A$2:A64 = MATCH_DATES!$A$7) * (PLAYER_STAT!D$2:D64 = $B3), 0) ), "" )} | BU3: =RANK(BL3, BL$3:BL$38, 0) -> 23 | BV3: =IF(BU3<BI3, "↑", IF(BU3>BI3, "↓", "=")) -> ↑ | BW3: MAGENTA | BX3: =SUM(BY3:BZ3)+CE3+BL3 -> 30 | BY3: =COUNTA(BW3)*2 -> 2 | BZ3: =SUM(CA3*2)+(CB3*1) + SUMIFS(MATCH_INPUT!$G$26:$G$29, MATCH_INPUT!$F$26:$F$29, BW3) + SUMIFS(MATCH_INPUT!$I$26:$I$29, MATCH_INPUT!$J$26:$J$29, BW3) -> 1 | CA3: =IF(BW3<>"", COUNTIFS(MATCH_INPUT!$K$26:$K$29,BW3), 0) -> 0 | CB3: =IF(BW3<>"", COUNTIFS(MATCH_INPUT!$F$26:$F$29, BW3, MATCH_INPUT!$K$26:$K$29, "Draw") + COUNTIFS(MATCH_INPUT!$J$26:$J$29, BW3, MATCH_INPUT!$K$26:$K$29, "Draw"), 0) -> 0 | CC3: =IF(BW3<>"", COUNTIFS(MATCH_INPUT!$F$26:$F$29, BW3, MATCH_INPUT!$K$26:$K$29, "<>"&BW3, MATCH_INPUT!$K$26:$K$29, "<>Draw", MATCH_INPUT!$K$26:$K$29, "<>""") + COUNTIFS(MATCH_INPUT!$J$26:$J$29, BW3, MATCH_INPUT!$K$26:$K$29, "<>"&BW3, MATCH_INPUT!$K$26:$K$29, "<>Draw", MATCH_INPUT!$K$26:$K$29, "<>"""), 0) -> 2 | CD3: {=IFERROR( INDEX(PLAYER_STAT!E$2:E64, MATCH(1, (PLAYER_STAT!A$2:A64 = MATCH_DATES!$A$8) * (PLAYER_STAT!D$2:D64 = $B3), 0) ), "" )} | CE3: {=IFERROR( INDEX(PLAYER_STAT!F$2:F64, MATCH(1, (PLAYER_STAT!A$2:A64 = MATCH_DATES!$A$8) * (PLAYER_STAT!D$2:D64 = $B3), 0) ), "" )} | CF3: {=IFERROR( INDEX(PLAYER_STAT!G$2:G64, MATCH(1, (PLAYER_STAT!A$2:A64 = MATCH_DATES!$A$8) * (PLAYER_STAT!D$2:D64 = $B3), 0) ), "" )} | CG3: =RANK(BX3, BX$3:BX$38, 0) -> 25 | CH3: =IF(CG3<BU3, "↑", IF(CG3>BU3, "↓", "=")) -> ↓ | CI3: MAGENTA | CJ3: =SUM(CK3:CL3)+CQ3+BX3 -> 39 | CK3: =COUNTA(CI3)*2 -> 2 | CL3: =SUM(CM3*2)+(CN3*1) + SUMIFS(MATCH_INPUT!$G$30:$G$33, MATCH_INPUT!$F$30:$F$33, CI3) + SUMIFS(MATCH_INPUT!$I$30:$I$33, MATCH_INPUT!$J$30:$J$33, CI3) -> 7 | CM3: =IF(CI3<>"", COUNTIFS(MATCH_INPUT!$K$30:$K$33,CI3), 0) -> 1 | CN3: =IF(CI3<>"", COUNTIFS(MATCH_INPUT!$F$30:$F$33, CI3, MATCH_INPUT!$K$30:$K$33, "Draw") + COUNTIFS(MATCH_INPUT!$J$30:$J$33, CI3, MATCH_INPUT!$K$30:$K$33, "Draw"), 0) -> 1 | CO3: =IF(CI3<>"", COUNTIFS(MATCH_INPUT!$F$30:$F$33, CI3, MATCH_INPUT!$K$30:$K$33, "<>"&CI3, MATCH_INPUT!$K$30:$K$33, "<>Draw", MATCH_INPUT!$K$30:$K$33, "<>""") + COUNTIFS(MATCH_INPUT!$J$30:$J$33, CI3, MATCH_INPUT!$K$30:$K$33, "<>"&CI3, MATCH_INPUT!$K$30:$K$33, "<>Draw", MATCH_INPUT!$K$30:$K$33, "<>"""), 0) -> 0 | CP3: {=IFERROR( INDEX(PLAYER_STAT!E$2:E64, MATCH(1, (PLAYER_STAT!A$2:A64 = MATCH_DATES!$A$9) * (PLAYER_STAT!D$2:D64 = $B3), 0) ), "" )} | CQ3: {=IFERROR( INDEX(PLAYER_STAT!F$2:F64, MATCH(1, (PLAYER_STAT!A$2:A64 = MATCH_DATES!$A$9) * (PLAYER_STAT!D$2:D64 = $B3), 0) ), "" )} | CR3: {=IFERROR( INDEX(PLAYER_STAT!G$2:G64, MATCH(1, (PLAYER_STAT!A$2:A64 = MATCH_DATES!$A$9) * (PLAYER_STAT!D$2:D64 = $B3), 0) ), "" )} | CS3: =RANK(CJ3, CJ$3:CJ$38, 0) -> 25 | CT3: =IF(CS3<CG3, "↑", IF(CS3>CG3, "↓", "=")) -> = | CU3: =SUM(F3,R3,AD3,AP3,BB3,BN3,BZ3,CL3) -> 23 | CV3: =A3 -> 🍂🎃 | CW3: =B3 -> Alex 👬 Gus | CX3: =SUM(CU3,CY3,DD3) -> 39 | CY3: =SUM( IF(AND(MATCH_DATES!$A$2 <= TODAY(), NOW() >= MATCH_DATES!$A$2 + TIME(22, 0, 0)), E3, 0), IF(AND(MATCH_DATES!$A$3 <= TODAY(), NOW() >= MATCH_DATES!$A$3 + TIME(22, 0, 0)), Q3, 0), IF(AND(MATCH_DATES!$A$4 <= TODAY(), NOW() >= MATCH_DATES!$A$4 + TIME(22, 0, 0)), AC3, 0), IF(AND(MATCH_DATES!$A$5 <= TODAY(), NOW() >= MATCH_DATES!$A$5 + TIME(22, 0, 0)), AO3, 0), IF(AND(MATCH_DATES!$A$6 <= TODAY(), NOW() >= MATCH_DATES!$A$6 + TIME(22, 0, 0)), BA3, 0), IF(AND(MATCH_DATES!$A$7 <= TODAY(), NOW() >= MATCH_DATES!$A$7 + TIME(22, 0, 0)), BM3, 0), IF(AND(MATCH_DATES!$A$8 <= TODAY(), NOW() >= MATCH_DATES!$A$8 + TIME(22, 0, 0)), BY3, 0), IF(AND(MATCH_DATES!$A$9 <= TODAY(), NOW() >= MATCH_DATES!$A$9 + TIME(22, 0, 0)), CK3, 0) ) -> 16 | CZ3: =SUM(G3,S3,AE3,AQ3,BC3,BO3,CA3,CM3) -> 5 | DA3: =SUM(H3,T3,AF3,AR3,BD3,BP3,CB3,CN3) -> 3 | DB3: =SUM( IF(AND(MATCH_DATES!$A$2 <= TODAY(), NOW() >= MATCH_DATES!$A$2 + TIME(22, 0, 0)), I3, 0), IF(AND(MATCH_DATES!$A$3 <= TODAY(), NOW() >= MATCH_DATES!$A$3 + TIME(22, 0, 0)), U3, 0), IF(AND(MATCH_DATES!$A$4 <= TODAY(), NOW() >= MATCH_DATES!$A$4 + TIME(22, 0, 0)), AG3, 0), IF(AND(MATCH_DATES!$A$5 <= TODAY(), NOW() >= MATCH_DATES!$A$5 + TIME(22, 0, 0)), AS3, 0), IF(AND(MATCH_DATES!$A$6 <= TODAY(), NOW() >= MATCH_DATES!$A$6 + TIME(22, 0, 0)), BE3, 0), IF(AND(MATCH_DATES!$A$7 <= TODAY(), NOW() >= MATCH_DATES!$A$7 + TIME(22, 0, 0)), BQ3, 0), IF(AND(MATCH_DATES!$A$8 <= TODAY(), NOW() >= MATCH_DATES!$A$8 + TIME(22, 0, 0)), CC3, 0), IF(AND(MATCH_DATES!$A$9 <= TODAY(), NOW() >= MATCH_DATES!$A$9 + TIME(22, 0, 0)), CO3, 0) ) -> 8 | DC3: =sum(J3,V3,AH3,AT3,BF3,BR3,CD3,CP3) -> 0 | DD3: =SUM(K3,W3,AI3,AU3,BG3,BS3,CE3,CQ3) -> 0 | DE3: =SUM(L3,X3,AJ3,AV3,BH3,BT3,CF3,CR3) -> 0
A4: 🍂🎃 | B4: Andrés 👬 López | C4: BLUE | D4: =SUM(E4:F4)+K4 -> 4 | E4: =COUNTA(C4)*2 -> 2 | F4: =(G4*2)+(H4*1) -> 2 | G4: =IF(C4<>"", COUNTIFS(MATCH_INPUT!$K$2:$K$5,C4), 0) -> 1 | H4: =IF(C4<>"", COUNTIFS(MATCH_INPUT!$F$2:$F$5, C4, MATCH_INPUT!$K$2:$K$5, "Draw") + COUNTIFS(MATCH_INPUT!$J$2:$J$5, C4, MATCH_INPUT!$K$2:$K$5, "Draw"), 0) -> 0 | I4: =IF(C4<>"", COUNTIFS(MATCH_INPUT!$F$2:$F$5, C4, MATCH_INPUT!$K$2:$K$5, "<>"&C4, MATCH_INPUT!$K$2:$K$5, "<>Draw", MATCH_INPUT!$K$2:$K$5, "<>""") + COUNTIFS(MATCH_INPUT!$J$2:$J$5, C4, MATCH_INPUT!$K$2:$K$5, "<>"&C4, MATCH_INPUT!$K$2:$K$5, "<>Draw", MATCH_INPUT!$K$2:$K$5, "<>"""), 0) -> 1 | J4: {=IFERROR( INDEX(PLAYER_STAT!E$2:E64, MATCH(1, (PLAYER_STAT!A$2:A64 = MATCH_DATES!$A$2) * (PLAYER_STAT!D$2:D64 = $B4), 0) ), "" )} | K4: {=IFERROR( INDEX(PLAYER_STAT!F$2:F64, MATCH(1, (PLAYER_STAT!A$2:A64 = MATCH_DATES!$A$2) * (PLAYER_STAT!D$2:D64 = $B4), 0) ), "" )} | L4: {=IFERROR( INDEX(PLAYER_STAT!G$2:G64, MATCH(1, (PLAYER_STAT!A$2:A64 = MATCH_DATES!$A$2) * (PLAYER_STAT!D$2:D64 = $B4), 0) ), "" )} | M4: =RANK(D4, D$3:D$39, 0) -> 11 | N4: =IF(M4<1, "↑", IF(M4>1, "↓", "=")) -> ↓ | O4: GREEN | P4: =SUM(Q4:R4)+D4+W4 -> 7 | Q4: =COUNTA(O4)*2 -> 2 | R4: =(S4*2)+(T4*1) -> 1 | S4: =IF(O4<>"", COUNTIFS(MATCH_INPUT!$K$6:$K$9,O4), 0) -> 0 | T4: =IF(O4<>"", COUNTIFS(MATCH_INPUT!$F$6:$F$9, O4, MATCH_INPUT!$K$6:$K$9, "Draw") + COUNTIFS(MATCH_INPUT!$J$6:$J$9, O4, MATCH_INPUT!$K$6:$K$9, "Draw"), 0) -> 1 | U4: =IF(O4<>"", COUNTIFS(MATCH_INPUT!$F$6:$F$9, O4, MATCH_INPUT!$K$6:$K$9, "<>"&O4, MATCH_INPUT!$K$6:$K$9, "<>Draw", MATCH_INPUT!$K$6:$K$9, "<>""") + COUNTIFS(MATCH_INPUT!$J$6:$J$9, O4, MATCH_INPUT!$K$6:$K$9, "<>"&O4, MATCH_INPUT!$K$6:$K$9, "<>Draw", MATCH_INPUT!$K$6:$K$9, "<>"""), 0) -> 1 | V4: {=IFERROR( INDEX(PLAYER_STAT!E$2:E64, MATCH(1, (PLAYER_STAT!A$2:A64 = MATCH_DATES!$A$3) * (PLAYER_STAT!D$2:D64 = $B4), 0) ), "" )} | W4: {=IFERROR( INDEX(PLAYER_STAT!F$2:F64, MATCH(1, (PLAYER_STAT!A$2:A64 = MATCH_DATES!$A$3) * (PLAYER_STAT!D$2:D64 = $B4), 0) ), "" )} | X4: {=IFERROR( INDEX(PLAYER_STAT!G$2:G64, MATCH(1, (PLAYER_STAT!A$2:A64 = MATCH_DATES!$A$3) * (PLAYER_STAT!D$2:D64 = $B4), 0) ), "" )} | Y4: =RANK(P4, P$3:P$38, 0) -> 20 | Z4: =IF(Y4<M4, "↑", IF(Y4>M4, "↓", "=")) -> ↓ | AA4: ORANGE | AB4: =SUM(AC4:AD4)+P4+AI4 -> 9 | AC4: =COUNTA(AA4)*2 -> 2 | AD4: =SUM(AE4*2)+(AF4*1) -> 0 | AE4: =IF(AA4<>"", COUNTIFS(MATCH_INPUT!$K$10:$K$13,AA4), 0) -> 0 | AF4: =IF(AA4<>"", COUNTIFS(MATCH_INPUT!$F$10:$F$13, AA4, MATCH_INPUT!$K$10:$K$13, "Draw") + COUNTIFS(MATCH_INPUT!$J$10:$J$13, AA4, MATCH_INPUT!$K$10:$K$13, "Draw"), 0) -> 0 | AG4: =IF(AA4<>"", COUNTIFS(MATCH_INPUT!$F$10:$F$13, AA4, MATCH_INPUT!$K$10:$K$13, "<>"&AA4, MATCH_INPUT!$K$10:$K$13, "<>Draw", MATCH_INPUT!$K$10:$K$13, "<>""") + COUNTIFS(MATCH_INPUT!$J$10:$J$13, AA4, MATCH_INPUT!$K$10:$K$13, "<>"&AA4, MATCH_INPUT!$K$10:$K$13, "<>Draw", MATCH_INPUT!$K$10:$K$13, "<>"""), 0) -> 2 | AH4: {=IFERROR( INDEX(PLAYER_STAT!E$2:E64, MATCH(1, (PLAYER_STAT!A$2:A64 = MATCH_DATES!$A$4) * (PLAYER_STAT!D$2:D64 = $B4), 0) ), "" )} | AI4: {=IFERROR( INDEX(PLAYER_STAT!F$2:F64, MATCH(1, (PLAYER_STAT!A$2:A64 = MATCH_DATES!$A$4) * (PLAYER_STAT!D$2:D64 = $B4), 0) ), "" )} | AJ4: {=IFERROR( INDEX(PLAYER_STAT!G$2:G64, MATCH(1, (PLAYER_STAT!A$2:A64 = MATCH_DATES!$A$4) * (PLAYER_STAT!D$2:D64 = $B4), 0) ), "" )} | AK4: =RANK(AB4, AB$3:AB$38, 0) -> 29 | AL4: =IF(AK4<Y4, "↑", IF(AK4>Y4, "↓", "=")) -> ↓ | AN4: =SUM(AO4:AP4)+AB4+AU4 -> 9 | AO4: =COUNTA(AM4)*2 -> 0 | AP4: =SUM(AQ4*2)+(AR4*1) -> 0 | AQ4: =IF(AM4<>"", COUNTIFS(MATCH_INPUT!$K$14:$K$17,AM4), 0) -> 0 | AR4: =IF(AM4<>"", COUNTIFS(MATCH_INPUT!$F$14:$F$17, AM4, MATCH_INPUT!$K$14:$K$17, "Draw") + COUNTIFS(MATCH_INPUT!$J$14:$J$17, AM4, MATCH_INPUT!$K$14:$K$17, "Draw"), 0) -> 0 | AS4: =IF(AM4<>"", COUNTIFS(MATCH_INPUT!$F$14:$F$17, AM4, MATCH_INPUT!$K$14:$K$17, "<>"&AM4, MATCH_INPUT!$K$14:$K$17, "<>Draw", MATCH_INPUT!$K$14:$K$17, "<>""") + COUNTIFS(MATCH_INPUT!$J$14:$J$17, AM4, MATCH_INPUT!$K$14:$K$17, "<>"&AM4, MATCH_INPUT!$K$14:$K$17, "<>Draw", MATCH_INPUT!$K$14:$K$17, "<>"""), 0) -> 0 | AT4: {=IFERROR( INDEX(PLAYER_STAT!E$2:E64, MATCH(1, (PLAYER_STAT!A$2:A64 = MATCH_DATES!$A$5) * (PLAYER_STAT!D$2:D64 = $B4), 0) ), "" )} | AU4: {=IFERROR( INDEX(PLAYER_STAT!F$2:F64, MATCH(1, (PLAYER_STAT!A$2:A64 = MATCH_DATES!$A$5) * (PLAYER_STAT!D$2:D64 = $B4), 0) ), "" )} | AV4: {=IFERROR( INDEX(PLAYER_STAT!G$2:G64, MATCH(1, (PLAYER_STAT!A$2:A64 = MATCH_DATES!$A$5) * (PLAYER_STAT!D$2:D64 = $B4), 0) ), "" )} | AW4: =RANK(AN4, AN$3:AN$38, 0) -> 34 | AX4: =IF(AW4<AK4, "↑", IF(AW4>AK4, "↓", "=")) -> ↓ | AY4: BLUE | AZ4: =SUM(BA4:BB4)+BG4+AN4 -> 14 | BA4: =COUNTA(AY4)*2 -> 2 | BB4: =SUM(BC4*2) + (BD4*1) + SUMIFS(MATCH_INPUT!$G$18:$G$21, MATCH_INPUT!$F$18:$F$21, AY4) + SUMIFS(MATCH_INPUT!$I$18:$I$21, MATCH_INPUT!$J$18:$J$21, AY4) -> 2 | BC4: =IF(AY4<>"", COUNTIFS(MATCH_INPUT!$K$18:$K$21,AY4), 0) -> 0 | BD4: =IF(AY4<>"", COUNTIFS(MATCH_INPUT!$F$18:$F$21, AY4, MATCH_INPUT!$K$18:$K$21, "Draw") + COUNTIFS(MATCH_INPUT!$J$18:$J$21, AY4, MATCH_INPUT!$K$18:$K$21, "Draw"), 0) -> 1 | BE4: =IF(AY4<>"", COUNTIFS(MATCH_INPUT!$F$18:$F$21, AY4, MATCH_INPUT!$K$18:$K$21, "<>"&AY4, MATCH_INPUT!$K$18:$K$21, "<>Draw", MATCH_INPUT!$K$18:$K$21, "<>""") + COUNTIFS(MATCH_INPUT!$J$18:$J$21, AY4, MATCH_INPUT!$K$18:$K$21, "<>"&AY4, MATCH_INPUT!$K$18:$K$21, "<>Draw", MATCH_INPUT!$K$18:$K$21, "<>"""), 0) -> 1 | BF4: {=IFERROR( INDEX(PLAYER_STAT!E$2:E64, MATCH(1, (PLAYER_STAT!A$2:A64 = MATCH_DATES!$A$6) * (PLAYER_STAT!D$2:D64 = $B4), 0) ), "" )} -> 0 | BG4: {=IFERROR( INDEX(PLAYER_STAT!F$2:F64, MATCH(1, (PLAYER_STAT!A$2:A64 = MATCH_DATES!$A$6) * (PLAYER_STAT!D$2:D64 = $B4), 0) ), "" )} -> 1 | BH4: {=IFERROR( INDEX(PLAYER_STAT!G$2:G64, MATCH(1, (PLAYER_STAT!A$2:A64 = MATCH_DATES!$A$6) * (PLAYER_STAT!D$2:D64 = $B4), 0) ), "" )} -> 1 | BI4: =RANK(AZ4, AZ$3:AZ$38, 0) -> 32 | BJ4: =IF(BI4<AW4, "↑", IF(BI4>AW4, "↓", "=")) -> ↑ | BK4: GREEN | BL4: =SUM(BM4:BN4)+BS4+AZ4 -> 17 | BM4: =COUNTA(BK4)*2 -> 2 | BN4: =SUM(BO4*2) + (BP4*1) + SUMIFS(MATCH_INPUT!$G$22:$G$25, MATCH_INPUT!$F$22:$F$25, BK4) + SUMIFS(MATCH_INPUT!$I$22:$I$25, MATCH_INPUT!$J$22:$J$25, BK4) -> 0 | BO4: =IF(BK4<>"", COUNTIFS(MATCH_INPUT!$K$22:$K$25,BK4), 0) -> 0 | BP4: =IF(BK4<>"", COUNTIFS(MATCH_INPUT!$F$22:$F$25, BK4, MATCH_INPUT!$K$22:$K$25, "Draw") + COUNTIFS(MATCH_INPUT!$J$22:$J$25, BK4, MATCH_INPUT!$K$22:$K$25, "Draw"), 0) -> 0 | BQ4: =IF(BK4<>"", COUNTIFS(MATCH_INPUT!$F$22:$F$25, BK4, MATCH_INPUT!$K$22:$K$25, "<>"&BK4, MATCH_INPUT!$K$22:$K$25, "<>Draw", MATCH_INPUT!$K$22:$K$25, "<>""") + COUNTIFS(MATCH_INPUT!$J$22:$J$25, BK4, MATCH_INPUT!$K$22:$K$25, "<>"&BK4, MATCH_INPUT!$K$22:$K$25, "<>Draw", MATCH_INPUT!$K$22:$K$25, "<>"""), 0) -> 2 | BR4: {=IFERROR( INDEX(PLAYER_STAT!E$2:E64, MATCH(1, (PLAYER_STAT!A$2:A64 = MATCH_DATES!$A$7) * (PLAYER_STAT!D$2:D64 = $B4), 0) ), "" )} -> 0 | BS4: {=IFERROR( INDEX(PLAYER_STAT!F$2:F64, MATCH(1, (PLAYER_STAT!A$2:A64 = MATCH_DATES!$A$7) * (PLAYER_STAT!D$2:D64 = $B4), 0) ), "" )} -> 1 | BT4: {=IFERROR( INDEX(PLAYER_STAT!G$2:G64, MATCH(1, (PLAYER_STAT!A$2:A64 = MATCH_DATES!$A$7) * (PLAYER_STAT!D$2:D64 = $B4), 0) ), "" )} -> 0 | BU4: =RANK(BL4, BL$3:BL$38, 0) -> 33 | BV4: =IF(BU4<BI4, "↑", IF(BU4>BI4, "↓", "=")) -> ↓ | BX4: =SUM(BY4:BZ4)+CE4+BL4 -> 17 | BY4: =COUNTA(BW4)*2 -> 0 | BZ4: =SUM(CA4*2)+(CB4*1) + SUMIFS(MATCH_INPUT!$G$26:$G$29, MATCH_INPUT!$F$26:$F$29, BW4) + SUMIFS(MATCH_INPUT!$I$26:$I$29, MATCH_INPUT!$J$26:$J$29, BW4) -> 0 | CA4: =IF(BW4<>"", COUNTIFS(MATCH_INPUT!$K$26:$K$29,BW4), 0) -> 0 | CB4: =IF(BW4<>"", COUNTIFS(MATCH_INPUT!$F$26:$F$29, BW4, MATCH_INPUT!$K$26:$K$29, "Draw") + COUNTIFS(MATCH_INPUT!$J$26:$J$29, BW4, MATCH_INPUT!$K$26:$K$29, "Draw"), 0) -> 0 | CC4: =IF(BW4<>"", COUNTIFS(MATCH_INPUT!$F$26:$F$29, BW4, MATCH_INPUT!$K$26:$K$29, "<>"&BW4, MATCH_INPUT!$K$26:$K$29, "<>Draw", MATCH_INPUT!$K$26:$K$29, "<>""") + COUNTIFS(MATCH_INPUT!$J$26:$J$29, BW4, MATCH_INPUT!$K$26:$K$29, "<>"&BW4, MATCH_INPUT!$K$26:$K$29, "<>Draw", MATCH_INPUT!$K$26:$K$29, "<>"""), 0) -> 0 | CD4: {=IFERROR( INDEX(PLAYER_STAT!E$2:E64, MATCH(1, (PLAYER_STAT!A$2:A64 = MATCH_DATES!$A$8) * (PLAYER_STAT!D$2:D64 = $B4), 0) ), "" )} | CE4: {=IFERROR( INDEX(PLAYER_STAT!F$2:F64, MATCH(1, (PLAYER_STAT!A$2:A64 = MATCH_DATES!$A$8) * (PLAYER_STAT!D$2:D64 = $B4), 0) ), "" )} | CF4: {=IFERROR( INDEX(PLAYER_STAT!G$2:G64, MATCH(1, (PLAYER_STAT!A$2:A64 = MATCH_DATES!$A$8) * (PLAYER_STAT!D$2:D64 = $B4), 0) ), "" )} | CG4: =RANK(BX4, BX$3:BX$38, 0) -> 35 | CH4: =IF(CG4<BU4, "↑", IF(CG4>BU4, "↓", "=")) -> ↓ | CI4: GREEN | CJ4: =SUM(CK4:CL4)+CQ4+BX4 -> 28 | CK4: =COUNTA(CI4)*2 -> 2 | CL4: =SUM(CM4*2)+(CN4*1) + SUMIFS(MATCH_INPUT!$G$30:$G$33, MATCH_INPUT!$F$30:$F$33, CI4) + SUMIFS(MATCH_INPUT!$I$30:$I$33, MATCH_INPUT!$J$30:$J$33, CI4) -> 9 | CM4: =IF(CI4<>"", COUNTIFS(MATCH_INPUT!$K$30:$K$33,CI4), 0) -> 1 | CN4: =IF(CI4<>"", COUNTIFS(MATCH_INPUT!$F$30:$F$33, CI4, MATCH_INPUT!$K$30:$K$33, "Draw") + COUNTIFS(MATCH_INPUT!$J$30:$J$33, CI4, MATCH_INPUT!$K$30:$K$33, "Draw"), 0) -> 1 | CO4: =IF(CI4<>"", COUNTIFS(MATCH_INPUT!$F$30:$F$33, CI4, MATCH_INPUT!$K$30:$K$33, "<>"&CI4, MATCH_INPUT!$K$30:$K$33, "<>Draw", MATCH_INPUT!$K$30:$K$33, "<>""") + COUNTIFS(MATCH_INPUT!$J$30:$J$33, CI4, MATCH_INPUT!$K$30:$K$33, "<>"&CI4, MATCH_INPUT!$K$30:$K$33, "<>Draw", MATCH_INPUT!$K$30:$K$33, "<>"""), 0) -> 0 | CP4: {=IFERROR( INDEX(PLAYER_STAT!E$2:E64, MATCH(1, (PLAYER_STAT!A$2:A64 = MATCH_DATES!$A$9) * (PLAYER_STAT!D$2:D64 = $B4), 0) ), "" )} | CQ4: {=IFERROR( INDEX(PLAYER_STAT!F$2:F64, MATCH(1, (PLAYER_STAT!A$2:A64 = MATCH_DATES!$A$9) * (PLAYER_STAT!D$2:D64 = $B4), 0) ), "" )} | CR4: {=IFERROR( INDEX(PLAYER_STAT!G$2:G64, MATCH(1, (PLAYER_STAT!A$2:A64 = MATCH_DATES!$A$9) * (PLAYER_STAT!D$2:D64 = $B4), 0) ), "" )} | CS4: =RANK(CJ4, CJ$3:CJ$38, 0) -> 34 | CT4: =IF(CS4<CG4, "↑", IF(CS4>CG4, "↓", "=")) -> ↑ | CU4: =SUM(F4,R4,AD4,AP4,BB4,BN4,BZ4,CL4) -> 14 | CV4: =A4 -> 🍂🎃 | CW4: =B4 -> Andrés 👬 López | CX4: =SUM(CU4,CY4,DD4) -> 28 | CY4: =SUM( IF(AND(MATCH_DATES!$A$2 <= TODAY(), NOW() >= MATCH_DATES!$A$2 + TIME(22, 0, 0)), E4, 0), IF(AND(MATCH_DATES!$A$3 <= TODAY(), NOW() >= MATCH_DATES!$A$3 + TIME(22, 0, 0)), Q4, 0), IF(AND(MATCH_DATES!$A$4 <= TODAY(), NOW() >= MATCH_DATES!$A$4 + TIME(22, 0, 0)), AC4, 0), IF(AND(MATCH_DATES!$A$5 <= TODAY(), NOW() >= MATCH_DATES!$A$5 + TIME(22, 0, 0)), AO4, 0), IF(AND(MATCH_DATES!$A$6 <= TODAY(), NOW() >= MATCH_DATES!$A$6 + TIME(22, 0, 0)), BA4, 0), IF(AND(MATCH_DATES!$A$7 <= TODAY(), NOW() >= MATCH_DATES!$A$7 + TIME(22, 0, 0)), BM4, 0), IF(AND(MATCH_DATES!$A$8 <= TODAY(), NOW() >= MATCH_DATES!$A$8 + TIME(22, 0, 0)), BY4, 0), IF(AND(MATCH_DATES!$A$9 <= TODAY(), NOW() >= MATCH_DATES!$A$9 + TIME(22, 0, 0)), CK4, 0) ) -> 12 | CZ4: =SUM(G4,S4,AE4,AQ4,BC4,BO4,CA4,CM4) -> 2 | DA4: =SUM(H4,T4,AF4,AR4,BD4,BP4,CB4,CN4) -> 3 | DB4: =SUM( IF(AND(MATCH_DATES!$A$2 <= TODAY(), NOW() >= MATCH_DATES!$A$2 + TIME(22, 0, 0)), I4, 0), IF(AND(MATCH_DATES!$A$3 <= TODAY(), NOW() >= MATCH_DATES!$A$3 + TIME(22, 0, 0)), U4, 0), IF(AND(MATCH_DATES!$A$4 <= TODAY(), NOW() >= MATCH_DATES!$A$4 + TIME(22, 0, 0)), AG4, 0), IF(AND(MATCH_DATES!$A$5 <= TODAY(), NOW() >= MATCH_DATES!$A$5 + TIME(22, 0, 0)), AS4, 0), IF(AND(MATCH_DATES!$A$6 <= TODAY(), NOW() >= MATCH_DATES!$A$6 + TIME(22, 0, 0)), BE4, 0), IF(AND(MATCH_DATES!$A$7 <= TODAY(), NOW() >= MATCH_DATES!$A$7 + TIME(22, 0, 0)), BQ4, 0), IF(AND(MATCH_DATES!$A$8 <= TODAY(), NOW() >= MATCH_DATES!$A$8 + TIME(22, 0, 0)), CC4, 0), IF(AND(MATCH_DATES!$A$9 <= TODAY(), NOW() >= MATCH_DATES!$A$9 + TIME(22, 0, 0)), CO4, 0) ) -> 7 | DC4: =sum(J4,V4,AH4,AT4,BF4,BR4,CD4,CP4) -> 0 | DD4: =SUM(K4,W4,AI4,AU4,BG4,BS4,CE4,CQ4) -> 2 | DE4: =SUM(L4,X4,AJ4,AV4,BH4,BT4,CF4,CR4) -> 1
A5: 🍂🎃 | B5: Carlos S | C5: ORANGE | D5: =SUM(E5:F5)+K5 -> 2 | E5: =COUNTA(C5)*2 -> 2 | F5: =(G5*2)+(H5*1) -> 0 | G5: =IF(C5<>"", COUNTIFS(MATCH_INPUT!$K$2:$K$5,C5), 0) -> 0 | H5: =IF(C5<>"", COUNTIFS(MATCH_INPUT!$F$2:$F$5, C5, MATCH_INPUT!$K$2:$K$5, "Draw") + COUNTIFS(MATCH_INPUT!$J$2:$J$5, C5, MATCH_INPUT!$K$2:$K$5, "Draw"), 0) -> 0 | I5: =IF(C5<>"", COUNTIFS(MATCH_INPUT!$F$2:$F$5, C5, MATCH_INPUT!$K$2:$K$5, "<>"&C5, MATCH_INPUT!$K$2:$K$5, "<>Draw", MATCH_INPUT!$K$2:$K$5, "<>""") + COUNTIFS(MATCH_INPUT!$J$2:$J$5, C5, MATCH_INPUT!$K$2:$K$5, "<>"&C5, MATCH_INPUT!$K$2:$K$5, "<>Draw", MATCH_INPUT!$K$2:$K$5, "<>"""), 0) -> 2 | J5: {=IFERROR( INDEX(PLAYER_STAT!E$2:E64, MATCH(1, (PLAYER_STAT!A$2:A64 = MATCH_DATES!$A$2) * (PLAYER_STAT!D$2:D64 = $B5), 0) ), "" )} | K5: {=IFERROR( INDEX(PLAYER_STAT!F$2:F64, MATCH(1, (PLAYER_STAT!A$2:A64 = MATCH_DATES!$A$2) * (PLAYER_STAT!D$2:D64 = $B5), 0) ), "" )} | L5: {=IFERROR( INDEX(PLAYER_STAT!G$2:G64, MATCH(1, (PLAYER_STAT!A$2:A64 = MATCH_DATES!$A$2) * (PLAYER_STAT!D$2:D64 = $B5), 0) ), "" )} | M5: =RANK(D5, D$3:D$39, 0) -> 26 | N5: =IF(M5<1, "↑", IF(M5>1, "↓", "=")) -> ↓ | O5: BLUE | P5: =SUM(Q5:R5)+D5+W5 -> 7 | Q5: =COUNTA(O5)*2 -> 2 | R5: =(S5*2)+(T5*1) -> 3 | S5: =IF(O5<>"", COUNTIFS(MATCH_INPUT!$K$6:$K$9,O5), 0) -> 1 | T5: =IF(O5<>"", COUNTIFS(MATCH_INPUT!$F$6:$F$9, O5, MATCH_INPUT!$K$6:$K$9, "Draw") + COUNTIFS(MATCH_INPUT!$J$6:$J$9, O5, MATCH_INPUT!$K$6:$K$9, "Draw"), 0) -> 1 | U5: =IF(O5<>"", COUNTIFS(MATCH_INPUT!$F$6:$F$9, O5, MATCH_INPUT!$K$6:$K$9, "<>"&O5, MATCH_INPUT!$K$6:$K$9, "<>Draw", MATCH_INPUT!$K$6:$K$9, "<>""") + COUNTIFS(MATCH_INPUT!$J$6:$J$9, O5, MATCH_INPUT!$K$6:$K$9, "<>"&O5, MATCH_INPUT!$K$6:$K$9, "<>Draw", MATCH_INPUT!$K$6:$K$9, "<>"""), 0) -> 0 | V5: {=IFERROR( INDEX(PLAYER_STAT!E$2:E64, MATCH(1, (PLAYER_STAT!A$2:A64 = MATCH_DATES!$A$3) * (PLAYER_STAT!D$2:D64 = $B5), 0) ), "" )} -> 1 | W5: {=IFERROR( INDEX(PLAYER_STAT!F$2:F64, MATCH(1, (PLAYER_STAT!A$2:A64 = MATCH_DATES!$A$3) * (PLAYER_STAT!D$2:D64 = $B5), 0) ), "" )} -> 0 | X5: {=IFERROR( INDEX(PLAYER_STAT!G$2:G64, MATCH(1, (PLAYER_STAT!A$2:A64 = MATCH_DATES!$A$3) * (PLAYER_STAT!D$2:D64 = $B5), 0) ), "" )} -> 0 | Y5: =RANK(P5, P$3:P$38, 0) -> 20 | Z5: =IF(Y5<M5, "↑", IF(Y5>M5, "↓", "=")) -> ↑ | AA5: GREEN | AB5: =SUM(AC5:AD5)+P5+AI5 -> 13 | AC5: =COUNTA(AA5)*2 -> 2 | AD5: =SUM(AE5*2)+(AF5*1) -> 4 | AE5: =IF(AA5<>"", COUNTIFS(MATCH_INPUT!$K$10:$K$13,AA5), 0) -> 2 | AF5: =IF(AA5<>"", COUNTIFS(MATCH_INPUT!$F$10:$F$13, AA5, MATCH_INPUT!$K$10:$K$13, "Draw") + COUNTIFS(MATCH_INPUT!$J$10:$J$13, AA5, MATCH_INPUT!$K$10:$K$13, "Draw"), 0) -> 0 | AG5: =IF(AA5<>"", COUNTIFS(MATCH_INPUT!$F$10:$F$13, AA5, MATCH_INPUT!$K$10:$K$13, "<>"&AA5, MATCH_INPUT!$K$10:$K$13, "<>Draw", MATCH_INPUT!$K$10:$K$13, "<>""") + COUNTIFS(MATCH_INPUT!$J$10:$J$13, AA5, MATCH_INPUT!$K$10:$K$13, "<>"&AA5, MATCH_INPUT!$K$10:$K$13, "<>Draw", MATCH_INPUT!$K$10:$K$13, "<>"""), 0) -> 0 | AH5: {=IFERROR( INDEX(PLAYER_STAT!E$2:E64, MATCH(1, (PLAYER_STAT!A$2:A64 = MATCH_DATES!$A$4) * (PLAYER_STAT!D$2:D64 = $B5), 0) ), "" )} -> 2 | AI5: {=IFERROR( INDEX(PLAYER_STAT!F$2:F64, MATCH(1, (PLAYER_STAT!A$2:A64 = MATCH_DATES!$A$4) * (PLAYER_STAT!D$2:D64 = $B5), 0) ), "" )} -> 0 | AJ5: {=IFERROR( INDEX(PLAYER_STAT!G$2:G64, MATCH(1, (PLAYER_STAT!A$2:A64 = MATCH_DATES!$A$4) * (PLAYER_STAT!D$2:D64 = $B5), 0) ), "" )} -> 0 | AK5: =RANK(AB5, AB$3:AB$38, 0) -> 10 | AL5: =IF(AK5<Y5, "↑", IF(AK5>Y5, "↓", "=")) -> ↑ | AM5: MAGENTA | AN5: =SUM(AO5:AP5)+AB5+AU5 -> 15 | AO5: =COUNTA(AM5)*2 -> 2 | AP5: =SUM(AQ5*2)+(AR5*1) -> 0 | AQ5: =IF(AM5<>"", COUNTIFS(MATCH_INPUT!$K$14:$K$17,AM5), 0) -> 0 | AR5: =IF(AM5<>"", COUNTIFS(MATCH_INPUT!$F$14:$F$17, AM5, MATCH_INPUT!$K$14:$K$17, "Draw") + COUNTIFS(MATCH_INPUT!$J$14:$J$17, AM5, MATCH_INPUT!$K$14:$K$17, "Draw"), 0) -> 0 | AS5: =IF(AM5<>"", COUNTIFS(MATCH_INPUT!$F$14:$F$17, AM5, MATCH_INPUT!$K$14:$K$17, "<>"&AM5, MATCH_INPUT!$K$14:$K$17, "<>Draw", MATCH_INPUT!$K$14:$K$17, "<>""") + COUNTIFS(MATCH_INPUT!$J$14:$J$17, AM5, MATCH_INPUT!$K$14:$K$17, "<>"&AM5, MATCH_INPUT!$K$14:$K$17, "<>Draw", MATCH_INPUT!$K$14:$K$17, "<>"""), 0) -> 2 | AT5: {=IFERROR( INDEX(PLAYER_STAT!E$2:E64, MATCH(1, (PLAYER_STAT!A$2:A64 = MATCH_DATES!$A$5) * (PLAYER_STAT!D$2:D64 = $B5), 0) ), "" )} -> 1 | AU5: {=IFERROR( INDEX(PLAYER_STAT!F$2:F64, MATCH(1, (PLAYER_STAT!A$2:A64 = MATCH_DATES!$A$5) * (PLAYER_STAT!D$2:D64 = $B5), 0) ), "" )} -> 0 | AV5: {=IFERROR( INDEX(PLAYER_STAT!G$2:G64, MATCH(1, (PLAYER_STAT!A$2:A64 = MATCH_DATES!$A$5) * (PLAYER_STAT!D$2:D64 = $B5), 0) ), "" )} -> 0 | AW5: =RANK(AN5, AN$3:AN$38, 0) -> 16 | AX5: =IF(AW5<AK5, "↑", IF(AW5>AK5, "↓", "=")) -> ↓ | AY5: ORANGE | AZ5: =SUM(BA5:BB5)+BG5+AN5 -> 18 | BA5: =COUNTA(AY5)*2 -> 2 | BB5: =SUM(BC5*2) + (BD5*1) + SUMIFS(MATCH_INPUT!$G$18:$G$21, MATCH_INPUT!$F$18:$F$21, AY5) + SUMIFS(MATCH_INPUT!$I$18:$I$21, MATCH_INPUT!$J$18:$J$21, AY5) -> 1 | BC5: =IF(AY5<>"", COUNTIFS(MATCH_INPUT!$K$18:$K$21,AY5), 0) -> 0 | BD5: =IF(AY5<>"", COUNTIFS(MATCH_INPUT!$F$18:$F$21, AY5, MATCH_INPUT!$K$18:$K$21, "Draw") + COUNTIFS(MATCH_INPUT!$J$18:$J$21, AY5, MATCH_INPUT!$K$18:$K$21, "Draw"), 0) -> 0 | BE5: =IF(AY5<>"", COUNTIFS(MATCH_INPUT!$F$18:$F$21, AY5, MATCH_INPUT!$K$18:$K$21, "<>"&AY5, MATCH_INPUT!$K$18:$K$21, "<>Draw", MATCH_INPUT!$K$18:$K$21, "<>""") + COUNTIFS(MATCH_INPUT!$J$18:$J$21, AY5, MATCH_INPUT!$K$18:$K$21, "<>"&AY5, MATCH_INPUT!$K$18:$K$21, "<>Draw", MATCH_INPUT!$K$18:$K$21, "<>"""), 0) -> 2 | BF5: {=IFERROR( INDEX(PLAYER_STAT!E$2:E64, MATCH(1, (PLAYER_STAT!A$2:A64 = MATCH_DATES!$A$6) * (PLAYER_STAT!D$2:D64 = $B5), 0) ), "" )} | BG5: {=IFERROR( INDEX(PLAYER_STAT!F$2:F64, MATCH(1, (PLAYER_STAT!A$2:A64 = MATCH_DATES!$A$6) * (PLAYER_STAT!D$2:D64 = $B5), 0) ), "" )} | BH5: {=IFERROR( INDEX(PLAYER_STAT!G$2:G64, MATCH(1, (PLAYER_STAT!A$2:A64 = MATCH_DATES!$A$6) * (PLAYER_STAT!D$2:D64 = $B5), 0) ), "" )} | BI5: =RANK(AZ5, AZ$3:AZ$38, 0) -> 24 | BJ5: =IF(BI5<AW5, "↑", IF(BI5>AW5, "↓", "=")) -> ↓ | BK5: ORANGE | BL5: =SUM(BM5:BN5)+BS5+AZ5 -> 32 | BM5: =COUNTA(BK5)*2 -> 2 | BN5: =SUM(BO5*2) + (BP5*1) + SUMIFS(MATCH_INPUT!$G$22:$G$25, MATCH_INPUT!$F$22:$F$25, BK5) + SUMIFS(MATCH_INPUT!$I$22:$I$25, MATCH_INPUT!$J$22:$J$25, BK5) -> 12 | BO5: =IF(BK5<>"", COUNTIFS(MATCH_INPUT!$K$22:$K$25,BK5), 0) -> 2 | BP5: =IF(BK5<>"", COUNTIFS(MATCH_INPUT!$F$22:$F$25, BK5, MATCH_INPUT!$K$22:$K$25, "Draw") + COUNTIFS(MATCH_INPUT!$J$22:$J$25, BK5, MATCH_INPUT!$K$22:$K$25, "Draw"), 0) -> 0 | BQ5: =IF(BK5<>"", COUNTIFS(MATCH_INPUT!$F$22:$F$25, BK5, MATCH_INPUT!$K$22:$K$25, "<>"&BK5, MATCH_INPUT!$K$22:$K$25, "<>Draw", MATCH_INPUT!$K$22:$K$25, "<>""") + COUNTIFS(MATCH_INPUT!$J$22:$J$25, BK5, MATCH_INPUT!$K$22:$K$25, "<>"&BK5, MATCH_INPUT!$K$22:$K$25, "<>Draw", MATCH_INPUT!$K$22:$K$25, "<>"""), 0) -> 0 | BR5: {=IFERROR( INDEX(PLAYER_STAT!E$2:E64, MATCH(1, (PLAYER_STAT!A$2:A64 = MATCH_DATES!$A$7) * (PLAYER_STAT!D$2:D64 = $B5), 0) ), "" )} | BS5: {=IFERROR( INDEX(PLAYER_STAT!F$2:F64, MATCH(1, (PLAYER_STAT!A$2:A64 = MATCH_DATES!$A$7) * (PLAYER_STAT!D$2:D64 = $B5), 0) ), "" )} | BT5: {=IFERROR( INDEX(PLAYER_STAT!G$2:G64, MATCH(1, (PLAYER_STAT!A$2:A64 = MATCH_DATES!$A$7) * (PLAYER_STAT!D$2:D64 = $B5), 0) ), "" )} | BU5: =RANK(BL5, BL$3:BL$38, 0) -> 15 | BV5: =IF(BU5<BI5, "↑", IF(BU5>BI5, "↓", "=")) -> ↑ | BW5: ORANGE | BX5: =SUM(BY5:BZ5)+CE5+BL5 -> 39 | BY5: =COUNTA(BW5)*2 -> 2 | BZ5: =SUM(CA5*2)+(CB5*1) + SUMIFS(MATCH_INPUT!$G$26:$G$29, MATCH_INPUT!$F$26:$F$29, BW5) + SUMIFS(MATCH_INPUT!$I$26:$I$29, MATCH_INPUT!$J$26:$J$29, BW5) -> 5 | CA5: =IF(BW5<>"", COUNTIFS(MATCH_INPUT!$K$26:$K$29,BW5), 0) -> 0 | CB5: =IF(BW5<>"", COUNTIFS(MATCH_INPUT!$F$26:$F$29, BW5, MATCH_INPUT!$K$26:$K$29, "Draw") + COUNTIFS(MATCH_INPUT!$J$26:$J$29, BW5, MATCH_INPUT!$K$26:$K$29, "Draw"), 0) -> 1 | CC5: =IF(BW5<>"", COUNTIFS(MATCH_INPUT!$F$26:$F$29, BW5, MATCH_INPUT!$K$26:$K$29, "<>"&BW5, MATCH_INPUT!$K$26:$K$29, "<>Draw", MATCH_INPUT!$K$26:$K$29, "<>""") + COUNTIFS(MATCH_INPUT!$J$26:$J$29, BW5, MATCH_INPUT!$K$26:$K$29, "<>"&BW5, MATCH_INPUT!$K$26:$K$29, "<>Draw", MATCH_INPUT!$K$26:$K$29, "<>"""), 0) -> 1 | CD5: {=IFERROR( INDEX(PLAYER_STAT!E$2:E64, MATCH(1, (PLAYER_STAT!A$2:A64 = MATCH_DATES!$A$8) * (PLAYER_STAT!D$2:D64 = $B5), 0) ), "" )} | CE5: {=IFERROR( INDEX(PLAYER_STAT!F$2:F64, MATCH(1, (PLAYER_STAT!A$2:A64 = MATCH_DATES!$A$8) * (PLAYER_STAT!D$2:D64 = $B5), 0) ), "" )} | CF5: {=IFERROR( INDEX(PLAYER_STAT!G$2:G64, MATCH(1, (PLAYER_STAT!A$2:A64 = MATCH_DATES!$A$8) * (PLAYER_STAT!D$2:D64 = $B5), 0) ), "" )} | CG5: =RANK(BX5, BX$3:BX$38, 0) -> 16 | CH5: =IF(CG5<BU5, "↑", IF(CG5>BU5, "↓", "=")) -> ↓ | CI5: MAGENTA | CJ5: =SUM(CK5:CL5)+CQ5+BX5 -> 48 | CK5: =COUNTA(CI5)*2 -> 2 | CL5: =SUM(CM5*2)+(CN5*1) + SUMIFS(MATCH_INPUT!$G$30:$G$33, MATCH_INPUT!$F$30:$F$33, CI5) + SUMIFS(MATCH_INPUT!$I$30:$I$33, MATCH_INPUT!$J$30:$J$33, CI5) -> 7 | CM5: =IF(CI5<>"", COUNTIFS(MATCH_INPUT!$K$30:$K$33,CI5), 0) -> 1 | CN5: =IF(CI5<>"", COUNTIFS(MATCH_INPUT!$F$30:$F$33, CI5, MATCH_INPUT!$K$30:$K$33, "Draw") + COUNTIFS(MATCH_INPUT!$J$30:$J$33, CI5, MATCH_INPUT!$K$30:$K$33, "Draw"), 0) -> 1 | CO5: =IF(CI5<>"", COUNTIFS(MATCH_INPUT!$F$30:$F$33, CI5, MATCH_INPUT!$K$30:$K$33, "<>"&CI5, MATCH_INPUT!$K$30:$K$33, "<>Draw", MATCH_INPUT!$K$30:$K$33, "<>""") + COUNTIFS(MATCH_INPUT!$J$30:$J$33, CI5, MATCH_INPUT!$K$30:$K$33, "<>"&CI5, MATCH_INPUT!$K$30:$K$33, "<>Draw", MATCH_INPUT!$K$30:$K$33, "<>"""), 0) -> 0 | CP5: {=IFERROR( INDEX(PLAYER_STAT!E$2:E64, MATCH(1, (PLAYER_STAT!A$2:A64 = MATCH_DATES!$A$9) * (PLAYER_STAT!D$2:D64 = $B5), 0) ), "" )} | CQ5: {=IFERROR( INDEX(PLAYER_STAT!F$2:F64, MATCH(1, (PLAYER_STAT!A$2:A64 = MATCH_DATES!$A$9) * (PLAYER_STAT!D$2:D64 = $B5), 0) ), "" )} | CR5: {=IFERROR( INDEX(PLAYER_STAT!G$2:G64, MATCH(1, (PLAYER_STAT!A$2:A64 = MATCH_DATES!$A$9) * (PLAYER_STAT!D$2:D64 = $B5), 0) ), "" )} | CS5: =RANK(CJ5, CJ$3:CJ$38, 0) -> 16 | CT5: =IF(CS5<CG5, "↑", IF(CS5>CG5, "↓", "=")) -> = | CU5: =SUM(F5,R5,AD5,AP5,BB5,BN5,BZ5,CL5) -> 32 | CV5: =A5 -> 🍂🎃 | CW5: =B5 -> Carlos S | CX5: =SUM(CU5,CY5,DD5) -> 48 | CY5: =SUM( IF(AND(MATCH_DATES!$A$2 <= TODAY(), NOW() >= MATCH_DATES!$A$2 + TIME(22, 0, 0)), E5, 0), IF(AND(MATCH_DATES!$A$3 <= TODAY(), NOW() >= MATCH_DATES!$A$3 + TIME(22, 0, 0)), Q5, 0), IF(AND(MATCH_DATES!$A$4 <= TODAY(), NOW() >= MATCH_DATES!$A$4 + TIME(22, 0, 0)), AC5, 0), IF(AND(MATCH_DATES!$A$5 <= TODAY(), NOW() >= MATCH_DATES!$A$5 + TIME(22, 0, 0)), AO5, 0), IF(AND(MATCH_DATES!$A$6 <= TODAY(), NOW() >= MATCH_DATES!$A$6 + TIME(22, 0, 0)), BA5, 0), IF(AND(MATCH_DATES!$A$7 <= TODAY(), NOW() >= MATCH_DATES!$A$7 + TIME(22, 0, 0)), BM5, 0), IF(AND(MATCH_DATES!$A$8 <= TODAY(), NOW() >= MATCH_DATES!$A$8 + TIME(22, 0, 0)), BY5, 0), IF(AND(MATCH_DATES!$A$9 <= TODAY(), NOW() >= MATCH_DATES!$A$9 + TIME(22, 0, 0)), CK5, 0) ) -> 16 | CZ5: =SUM(G5,S5,AE5,AQ5,BC5,BO5,CA5,CM5) -> 6 | DA5: =SUM(H5,T5,AF5,AR5,BD5,BP5,CB5,CN5) -> 3 | DB5: =SUM( IF(AND(MATCH_DATES!$A$2 <= TODAY(), NOW() >= MATCH_DATES!$A$2 + TIME(22, 0, 0)), I5, 0), IF(AND(MATCH_DATES!$A$3 <= TODAY(), NOW() >= MATCH_DATES!$A$3 + TIME(22, 0, 0)), U5, 0), IF(AND(MATCH_DATES!$A$4 <= TODAY(), NOW() >= MATCH_DATES!$A$4 + TIME(22, 0, 0)), AG5, 0), IF(AND(MATCH_DATES!$A$5 <= TODAY(), NOW() >= MATCH_DATES!$A$5 + TIME(22, 0, 0)), AS5, 0), IF(AND(MATCH_DATES!$A$6 <= TODAY(), NOW() >= MATCH_DATES!$A$6 + TIME(22, 0, 0)), BE5, 0), IF(AND(MATCH_DATES!$A$7 <= TODAY(), NOW() >= MATCH_DATES!$A$7 + TIME(22, 0, 0)), BQ5, 0), IF(AND(MATCH_DATES!$A$8 <= TODAY(), NOW() >= MATCH_DATES!$A$8 + TIME(22, 0, 0)), CC5, 0), IF(AND(MATCH_DATES!$A$9 <= TODAY(), NOW() >= MATCH_DATES!$A$9 + TIME(22, 0, 0)), CO5, 0) ) -> 7 | DC5: =sum(J5,V5,AH5,AT5,BF5,BR5,CD5,CP5) -> 4 | DD5: =SUM(K5,W5,AI5,AU5,BG5,BS5,CE5,CQ5) -> 0 | DE5: =SUM(L5,X5,AJ5,AV5,BH5,BT5,CF5,CR5) -> 0
A6: 🍂🎃 | B6: Chato | C6: ORANGE | D6: =SUM(E6:F6)+K6 -> 2 | E6: =COUNTA(C6)*2 -> 2 | F6: =(G6*2)+(H6*1) -> 0 | G6: =IF(C6<>"", COUNTIFS(MATCH_INPUT!$K$2:$K$5,C6), 0) -> 0 | H6: =IF(C6<>"", COUNTIFS(MATCH_INPUT!$F$2:$F$5, C6, MATCH_INPUT!$K$2:$K$5, "Draw") + COUNTIFS(MATCH_INPUT!$J$2:$J$5, C6, MATCH_INPUT!$K$2:$K$5, "Draw"), 0) -> 0 | I6: =IF(C6<>"", COUNTIFS(MATCH_INPUT!$F$2:$F$5, C6, MATCH_INPUT!$K$2:$K$5, "<>"&C6, MATCH_INPUT!$K$2:$K$5, "<>Draw", MATCH_INPUT!$K$2:$K$5, "<>""") + COUNTIFS(MATCH_INPUT!$J$2:$J$5, C6, MATCH_INPUT!$K$2:$K$5, "<>"&C6, MATCH_INPUT!$K$2:$K$5, "<>Draw", MATCH_INPUT!$K$2:$K$5, "<>"""), 0) -> 2 | J6: {=IFERROR( INDEX(PLAYER_STAT!E$2:E64, MATCH(1, (PLAYER_STAT!A$2:A64 = MATCH_DATES!$A$2) * (PLAYER_STAT!D$2:D64 = $B6), 0) ), "" )} -> 1 | K6: {=IFERROR( INDEX(PLAYER_STAT!F$2:F64, MATCH(1, (PLAYER_STAT!A$2:A64 = MATCH_DATES!$A$2) * (PLAYER_STAT!D$2:D64 = $B6), 0) ), "" )} -> 0 | L6: {=IFERROR( INDEX(PLAYER_STAT!G$2:G64, MATCH(1, (PLAYER_STAT!A$2:A64 = MATCH_DATES!$A$2) * (PLAYER_STAT!D$2:D64 = $B6), 0) ), "" )} -> 0 | M6: =RANK(D6, D$3:D$39, 0) -> 26 | N6: =IF(M6<1, "↑", IF(M6>1, "↓", "=")) -> ↓ | O6: BLUE | P6: =SUM(Q6:R6)+D6+W6 -> 7 | Q6: =COUNTA(O6)*2 -> 2 | R6: =(S6*2)+(T6*1) -> 3 | S6: =IF(O6<>"", COUNTIFS(MATCH_INPUT!$K$6:$K$9,O6), 0) -> 1 | T6: =IF(O6<>"", COUNTIFS(MATCH_INPUT!$F$6:$F$9, O6, MATCH_INPUT!$K$6:$K$9, "Draw") + COUNTIFS(MATCH_INPUT!$J$6:$J$9, O6, MATCH_INPUT!$K$6:$K$9, "Draw"), 0) -> 1 | U6: =IF(O6<>"", COUNTIFS(MATCH_INPUT!$F$6:$F$9, O6, MATCH_INPUT!$K$6:$K$9, "<>"&O6, MATCH_INPUT!$K$6:$K$9, "<>Draw", MATCH_INPUT!$K$6:$K$9, "<>""") + COUNTIFS(MATCH_INPUT!$J$6:$J$9, O6, MATCH_INPUT!$K$6:$K$9, "<>"&O6, MATCH_INPUT!$K$6:$K$9, "<>Draw", MATCH_INPUT!$K$6:$K$9, "<>"""), 0) -> 0 | V6: {=IFERROR( INDEX(PLAYER_STAT!E$2:E64, MATCH(1, (PLAYER_STAT!A$2:A64 = MATCH_DATES!$A$3) * (PLAYER_STAT!D$2:D64 = $B6), 0) ), "" )} | W6: {=IFERROR( INDEX(PLAYER_STAT!F$2:F64, MATCH(1, (PLAYER_STAT!A$2:A64 = MATCH_DATES!$A$3) * (PLAYER_STAT!D$2:D64 = $B6), 0) ), "" )} | X6: {=IFERROR( INDEX(PLAYER_STAT!G$2:G64, MATCH(1, (PLAYER_STAT!A$2:A64 = MATCH_DATES!$A$3) * (PLAYER_STAT!D$2:D64 = $B6), 0) ), "" )} | Y6: =RANK(P6, P$3:P$38, 0) -> 20 | Z6: =IF(Y6<M6, "↑", IF(Y6>M6, "↓", "=")) -> ↑ | AA6: GREEN | AB6: =SUM(AC6:AD6)+P6+AI6 -> 13 | AC6: =COUNTA(AA6)*2 -> 2 | AD6: =SUM(AE6*2)+(AF6*1) -> 4 | AE6: =IF(AA6<>"", COUNTIFS(MATCH_INPUT!$K$10:$K$13,AA6), 0) -> 2 | AF6: =IF(AA6<>"", COUNTIFS(MATCH_INPUT!$F$10:$F$13, AA6, MATCH_INPUT!$K$10:$K$13, "Draw") + COUNTIFS(MATCH_INPUT!$J$10:$J$13, AA6, MATCH_INPUT!$K$10:$K$13, "Draw"), 0) -> 0 | AG6: =IF(AA6<>"", COUNTIFS(MATCH_INPUT!$F$10:$F$13, AA6, MATCH_INPUT!$K$10:$K$13, "<>"&AA6, MATCH_INPUT!$K$10:$K$13, "<>Draw", MATCH_INPUT!$K$10:$K$13, "<>""") + COUNTIFS(MATCH_INPUT!$J$10:$J$13, AA6, MATCH_INPUT!$K$10:$K$13, "<>"&AA6, MATCH_INPUT!$K$10:$K$13, "<>Draw", MATCH_INPUT!$K$10:$K$13, "<>"""), 0) -> 0 | AH6: {=IFERROR( INDEX(PLAYER_STAT!E$2:E64, MATCH(1, (PLAYER_STAT!A$2:A64 = MATCH_DATES!$A$4) * (PLAYER_STAT!D$2:D64 = $B6), 0) ), "" )} -> 1 | AI6: {=IFERROR( INDEX(PLAYER_STAT!F$2:F64, MATCH(1, (PLAYER_STAT!A$2:A64 = MATCH_DATES!$A$4) * (PLAYER_STAT!D$2:D64 = $B6), 0) ), "" )} -> 0 | AJ6: {=IFERROR( INDEX(PLAYER_STAT!G$2:G64, MATCH(1, (PLAYER_STAT!A$2:A64 = MATCH_DATES!$A$4) * (PLAYER_STAT!D$2:D64 = $B6), 0) ), "" )} -> 0 | AK6: =RANK(AB6, AB$3:AB$38, 0) -> 10 | AL6: =IF(AK6<Y6, "↑", IF(AK6>Y6, "↓", "=")) -> ↑ | AM6: ORANGE | AN6: =SUM(AO6:AP6)+AB6+AU6 -> 17 | AO6: =COUNTA(AM6)*2 -> 2 | AP6: =SUM(AQ6*2)+(AR6*1) -> 2 | AQ6: =IF(AM6<>"", COUNTIFS(MATCH_INPUT!$K$14:$K$17,AM6), 0) -> 1 | AR6: =IF(AM6<>"", COUNTIFS(MATCH_INPUT!$F$14:$F$17, AM6, MATCH_INPUT!$K$14:$K$17, "Draw") + COUNTIFS(MATCH_INPUT!$J$14:$J$17, AM6, MATCH_INPUT!$K$14:$K$17, "Draw"), 0) -> 0 | AS6: =IF(AM6<>"", COUNTIFS(MATCH_INPUT!$F$14:$F$17, AM6, MATCH_INPUT!$K$14:$K$17, "<>"&AM6, MATCH_INPUT!$K$14:$K$17, "<>Draw", MATCH_INPUT!$K$14:$K$17, "<>""") + COUNTIFS(MATCH_INPUT!$J$14:$J$17, AM6, MATCH_INPUT!$K$14:$K$17, "<>"&AM6, MATCH_INPUT!$K$14:$K$17, "<>Draw", MATCH_INPUT!$K$14:$K$17, "<>"""), 0) -> 1 | AT6: {=IFERROR( INDEX(PLAYER_STAT!E$2:E64, MATCH(1, (PLAYER_STAT!A$2:A64 = MATCH_DATES!$A$5) * (PLAYER_STAT!D$2:D64 = $B6), 0) ), "" )} -> 1 | AU6: {=IFERROR( INDEX(PLAYER_STAT!F$2:F64, MATCH(1, (PLAYER_STAT!A$2:A64 = MATCH_DATES!$A$5) * (PLAYER_STAT!D$2:D64 = $B6), 0) ), "" )} -> 0 | AV6: {=IFERROR( INDEX(PLAYER_STAT!G$2:G64, MATCH(1, (PLAYER_STAT!A$2:A64 = MATCH_DATES!$A$5) * (PLAYER_STAT!D$2:D64 = $B6), 0) ), "" )} -> 0 | AW6: =RANK(AN6, AN$3:AN$38, 0) -> 11 | AX6: =IF(AW6<AK6, "↑", IF(AW6>AK6, "↓", "=")) -> ↓ | AY6: MAGENTA | AZ6: =SUM(BA6:BB6)+BG6+AN6 -> 28 | BA6: =COUNTA(AY6)*2 -> 2 | BB6: =SUM(BC6*2) + (BD6*1) + SUMIFS(MATCH_INPUT!$G$18:$G$21, MATCH_INPUT!$F$18:$F$21, AY6) + SUMIFS(MATCH_INPUT!$I$18:$I$21, MATCH_INPUT!$J$18:$J$21, AY6) -> 9 | BC6: =IF(AY6<>"", COUNTIFS(MATCH_INPUT!$K$18:$K$21,AY6), 0) -> 1 | BD6: =IF(AY6<>"", COUNTIFS(MATCH_INPUT!$F$18:$F$21, AY6, MATCH_INPUT!$K$18:$K$21, "Draw") + COUNTIFS(MATCH_INPUT!$J$18:$J$21, AY6, MATCH_INPUT!$K$18:$K$21, "Draw"), 0) -> 1 | BE6: =IF(AY6<>"", COUNTIFS(MATCH_INPUT!$F$18:$F$21, AY6, MATCH_INPUT!$K$18:$K$21, "<>"&AY6, MATCH_INPUT!$K$18:$K$21, "<>Draw", MATCH_INPUT!$K$18:$K$21, "<>""") + COUNTIFS(MATCH_INPUT!$J$18:$J$21, AY6, MATCH_INPUT!$K$18:$K$21, "<>"&AY6, MATCH_INPUT!$K$18:$K$21, "<>Draw", MATCH_INPUT!$K$18:$K$21, "<>"""), 0) -> 0 | BF6: {=IFERROR( INDEX(PLAYER_STAT!E$2:E64, MATCH(1, (PLAYER_STAT!A$2:A64 = MATCH_DATES!$A$6) * (PLAYER_STAT!D$2:D64 = $B6), 0) ), "" )} -> 2 | BG6: {=IFERROR( INDEX(PLAYER_STAT!F$2:F64, MATCH(1, (PLAYER_STAT!A$2:A64 = MATCH_DATES!$A$6) * (PLAYER_STAT!D$2:D64 = $B6), 0) ), "" )} -> 0 | BH6: {=IFERROR( INDEX(PLAYER_STAT!G$2:G64, MATCH(1, (PLAYER_STAT!A$2:A64 = MATCH_DATES!$A$6) * (PLAYER_STAT!D$2:D64 = $B6), 0) ), "" )} -> 0 | BI6: =RANK(AZ6, AZ$3:AZ$38, 0) -> 7 | BJ6: =IF(BI6<AW6, "↑", IF(BI6>AW6, "↓", "=")) -> ↑ | BK6: GREEN | BL6: =SUM(BM6:BN6)+BS6+AZ6 -> 30 | BM6: =COUNTA(BK6)*2 -> 2 | BN6: =SUM(BO6*2) + (BP6*1) + SUMIFS(MATCH_INPUT!$G$22:$G$25, MATCH_INPUT!$F$22:$F$25, BK6) + SUMIFS(MATCH_INPUT!$I$22:$I$25, MATCH_INPUT!$J$22:$J$25, BK6) -> 0 | BO6: =IF(BK6<>"", COUNTIFS(MATCH_INPUT!$K$22:$K$25,BK6), 0) -> 0 | BP6: =IF(BK6<>"", COUNTIFS(MATCH_INPUT!$F$22:$F$25, BK6, MATCH_INPUT!$K$22:$K$25, "Draw") + COUNTIFS(MATCH_INPUT!$J$22:$J$25, BK6, MATCH_INPUT!$K$22:$K$25, "Draw"), 0) -> 0 | BQ6: =IF(BK6<>"", COUNTIFS(MATCH_INPUT!$F$22:$F$25, BK6, MATCH_INPUT!$K$22:$K$25, "<>"&BK6, MATCH_INPUT!$K$22:$K$25, "<>Draw", MATCH_INPUT!$K$22:$K$25, "<>""") + COUNTIFS(MATCH_INPUT!$J$22:$J$25, BK6, MATCH_INPUT!$K$22:$K$25, "<>"&BK6, MATCH_INPUT!$K$22:$K$25, "<>Draw", MATCH_INPUT!$K$22:$K$25, "<>"""), 0) -> 2 | BR6: {=IFERROR( INDEX(PLAYER_STAT!E$2:E64, MATCH(1, (PLAYER_STAT!A$2:A64 = MATCH_DATES!$A$7) * (PLAYER_STAT!D$2:D64 = $B6), 0) ), "" )} | BS6: {=IFERROR( INDEX(PLAYER_STAT!F$2:F64, MATCH(1, (PLAYER_STAT!A$2:A64 = MATCH_DATES!$A$7) * (PLAYER_STAT!D$2:D64 = $B6), 0) ), "" )} | BT6: {=IFERROR( INDEX(PLAYER_STAT!G$2:G64, MATCH(1, (PLAYER_STAT!A$2:A64 = MATCH_DATES!$A$7) * (PLAYER_STAT!D$2:D64 = $B6), 0) ), "" )} | BU6: =RANK(BL6, BL$3:BL$38, 0) -> 17 | BV6: =IF(BU6<BI6, "↑", IF(BU6>BI6, "↓", "=")) -> ↓ | BW6: MAGENTA | BX6: =SUM(BY6:BZ6)+CE6+BL6 -> 33 | BY6: =COUNTA(BW6)*2 -> 2 | BZ6: =SUM(CA6*2)+(CB6*1) + SUMIFS(MATCH_INPUT!$G$26:$G$29, MATCH_INPUT!$F$26:$F$29, BW6) + SUMIFS(MATCH_INPUT!$I$26:$I$29, MATCH_INPUT!$J$26:$J$29, BW6) -> 1 | CA6: =IF(BW6<>"", COUNTIFS(MATCH_INPUT!$K$26:$K$29,BW6), 0) -> 0 | CB6: =IF(BW6<>"", COUNTIFS(MATCH_INPUT!$F$26:$F$29, BW6, MATCH_INPUT!$K$26:$K$29, "Draw") + COUNTIFS(MATCH_INPUT!$J$26:$J$29, BW6, MATCH_INPUT!$K$26:$K$29, "Draw"), 0) -> 0 | CC6: =IF(BW6<>"", COUNTIFS(MATCH_INPUT!$F$26:$F$29, BW6, MATCH_INPUT!$K$26:$K$29, "<>"&BW6, MATCH_INPUT!$K$26:$K$29, "<>Draw", MATCH_INPUT!$K$26:$K$29, "<>""") + COUNTIFS(MATCH_INPUT!$J$26:$J$29, BW6, MATCH_INPUT!$K$26:$K$29, "<>"&BW6, MATCH_INPUT!$K$26:$K$29, "<>Draw", MATCH_INPUT!$K$26:$K$29, "<>"""), 0) -> 2 | CD6: {=IFERROR( INDEX(PLAYER_STAT!E$2:E64, MATCH(1, (PLAYER_STAT!A$2:A64 = MATCH_DATES!$A$8) * (PLAYER_STAT!D$2:D64 = $B6), 0) ), "" )} | CE6: {=IFERROR( INDEX(PLAYER_STAT!F$2:F64, MATCH(1, (PLAYER_STAT!A$2:A64 = MATCH_DATES!$A$8) * (PLAYER_STAT!D$2:D64 = $B6), 0) ), "" )} | CF6: {=IFERROR( INDEX(PLAYER_STAT!G$2:G64, MATCH(1, (PLAYER_STAT!A$2:A64 = MATCH_DATES!$A$8) * (PLAYER_STAT!D$2:D64 = $B6), 0) ), "" )} | CG6: =RANK(BX6, BX$3:BX$38, 0) -> 23 | CH6: =IF(CG6<BU6, "↑", IF(CG6>BU6, "↓", "=")) -> ↓ | CI6: BLUE | CJ6: =SUM(CK6:CL6)+CQ6+BX6 -> 43 | CK6: =COUNTA(CI6)*2 -> 2 | CL6: =SUM(CM6*2)+(CN6*1) + SUMIFS(MATCH_INPUT!$G$30:$G$33, MATCH_INPUT!$F$30:$F$33, CI6) + SUMIFS(MATCH_INPUT!$I$30:$I$33, MATCH_INPUT!$J$30:$J$33, CI6) -> 8 | CM6: =IF(CI6<>"", COUNTIFS(MATCH_INPUT!$K$30:$K$33,CI6), 0) -> 1 | CN6: =IF(CI6<>"", COUNTIFS(MATCH_INPUT!$F$30:$F$33, CI6, MATCH_INPUT!$K$30:$K$33, "Draw") + COUNTIFS(MATCH_INPUT!$J$30:$J$33, CI6, MATCH_INPUT!$K$30:$K$33, "Draw"), 0) -> 0 | CO6: =IF(CI6<>"", COUNTIFS(MATCH_INPUT!$F$30:$F$33, CI6, MATCH_INPUT!$K$30:$K$33, "<>"&CI6, MATCH_INPUT!$K$30:$K$33, "<>Draw", MATCH_INPUT!$K$30:$K$33, "<>""") + COUNTIFS(MATCH_INPUT!$J$30:$J$33, CI6, MATCH_INPUT!$K$30:$K$33, "<>"&CI6, MATCH_INPUT!$K$30:$K$33, "<>Draw", MATCH_INPUT!$K$30:$K$33, "<>"""), 0) -> 1 | CP6: {=IFERROR( INDEX(PLAYER_STAT!E$2:E64, MATCH(1, (PLAYER_STAT!A$2:A64 = MATCH_DATES!$A$9) * (PLAYER_STAT!D$2:D64 = $B6), 0) ), "" )} | CQ6: {=IFERROR( INDEX(PLAYER_STAT!F$2:F64, MATCH(1, (PLAYER_STAT!A$2:A64 = MATCH_DATES!$A$9) * (PLAYER_STAT!D$2:D64 = $B6), 0) ), "" )} | CR6: {=IFERROR( INDEX(PLAYER_STAT!G$2:G64, MATCH(1, (PLAYER_STAT!A$2:A64 = MATCH_DATES!$A$9) * (PLAYER_STAT!D$2:D64 = $B6), 0) ), "" )} | CS6: =RANK(CJ6, CJ$3:CJ$38, 0) -> 21 | CT6: =IF(CS6<CG6, "↑", IF(CS6>CG6, "↓", "=")) -> ↑ | CU6: =SUM(F6,R6,AD6,AP6,BB6,BN6,BZ6,CL6) -> 27 | CV6: =A6 -> 🍂🎃 | CW6: =B6 -> Chato | CX6: =SUM(CU6,CY6,DD6) -> 43 | CY6: =SUM( IF(AND(MATCH_DATES!$A$2 <= TODAY(), NOW() >= MATCH_DATES!$A$2 + TIME(22, 0, 0)), E6, 0), IF(AND(MATCH_DATES!$A$3 <= TODAY(), NOW() >= MATCH_DATES!$A$3 + TIME(22, 0, 0)), Q6, 0), IF(AND(MATCH_DATES!$A$4 <= TODAY(), NOW() >= MATCH_DATES!$A$4 + TIME(22, 0, 0)), AC6, 0), IF(AND(MATCH_DATES!$A$5 <= TODAY(), NOW() >= MATCH_DATES!$A$5 + TIME(22, 0, 0)), AO6, 0), IF(AND(MATCH_DATES!$A$6 <= TODAY(), NOW() >= MATCH_DATES!$A$6 + TIME(22, 0, 0)), BA6, 0), IF(AND(MATCH_DATES!$A$7 <= TODAY(), NOW() >= MATCH_DATES!$A$7 + TIME(22, 0, 0)), BM6, 0), IF(AND(MATCH_DATES!$A$8 <= TODAY(), NOW() >= MATCH_DATES!$A$8 + TIME(22, 0, 0)), BY6, 0), IF(AND(MATCH_DATES!$A$9 <= TODAY(), NOW() >= MATCH_DATES!$A$9 + TIME(22, 0, 0)), CK6, 0) ) -> 16 | CZ6: =SUM(G6,S6,AE6,AQ6,BC6,BO6,CA6,CM6) -> 6 | DA6: =SUM(H6,T6,AF6,AR6,BD6,BP6,CB6,CN6) -> 2 | DB6: =SUM( IF(AND(MATCH_DATES!$A$2 <= TODAY(), NOW() >= MATCH_DATES!$A$2 + TIME(22, 0, 0)), I6, 0), IF(AND(MATCH_DATES!$A$3 <= TODAY(), NOW() >= MATCH_DATES!$A$3 + TIME(22, 0, 0)), U6, 0), IF(AND(MATCH_DATES!$A$4 <= TODAY(), NOW() >= MATCH_DATES!$A$4 + TIME(22, 0, 0)), AG6, 0), IF(AND(MATCH_DATES!$A$5 <= TODAY(), NOW() >= MATCH_DATES!$A$5 + TIME(22, 0, 0)), AS6, 0), IF(AND(MATCH_DATES!$A$6 <= TODAY(), NOW() >= MATCH_DATES!$A$6 + TIME(22, 0, 0)), BE6, 0), IF(AND(MATCH_DATES!$A$7 <= TODAY(), NOW() >= MATCH_DATES!$A$7 + TIME(22, 0, 0)), BQ6, 0), IF(AND(MATCH_DATES!$A$8 <= TODAY(), NOW() >= MATCH_DATES!$A$8 + TIME(22, 0, 0)), CC6, 0), IF(AND(MATCH_DATES!$A$9 <= TODAY(), NOW() >= MATCH_DATES!$A$9 + TIME(22, 0, 0)), CO6, 0) ) -> 8 | DC6: =sum(J6,V6,AH6,AT6,BF6,BR6,CD6,CP6) -> 5 | DD6: =SUM(K6,W6,AI6,AU6,BG6,BS6,CE6,CQ6) -> 0 | DE6: =SUM(L6,X6,AJ6,AV6,BH6,BT6,CF6,CR6) -> 0
