Workbook
Name MANDARINA_SEASON: WEEKLY_TEAMS!$A$1:$CY$53
Name LeagueStandingsTable: LEAGUE_STANDINGS!$B$13:$L$110

Sheet MATCH DATES
B1: Season to start 3/6/25
A2: 45722 | B2: MATCH DAY 1
A3: 45729 | B3: MATCH DAY 2
A4: 45736 | B4: MATCH DAY 3
A5: 45743 | B5: MATCH DAY 4
A6: 45750 | B6: MATCH DAY 5
A7: 45757 | B7: MATCH DAY 6
A8: 45764 | B8: MATCH DAY 7
A9: 45771 | B9: MATCH DAY 8
A15: WHAT IS THE PRIORITY SORTING FOR THIS
A17: With the updated formula I provided, the priority sorting is as follows:
A19: Total Points (CQ) - Highest priority, sorted in descending order.
A21: Wins (CR) - Second priority, sorted in descending order.
A23: Draws (CS) - Third priority, sorted in descending order.
A25: Losses (CT) - Fourth priority, sorted in descending order.
A27: Goals (CU) - Fifth priority, sorted in descending order.
A29: Clean Sheets (CV) - Sixth priority, sorted in descending order.
A31: Attendance (Matches Played) (CP) - Last priority, sorted in descending order.
A33: This order ensures that Total Points will always take precedence, followed by the other criteria in the order specified. This way, even if a player or team has high values in goals or clean sheets, the primary sorting criterion will still be Total Points.

Sheet WEEKLY_TEAMS
C1: MATCHDAY 1 | O1: MATCHDAY 2 | AA1: MATCHDAY 3 | AM1: MATCHDAY 4 | AY1: MATCHDAY 5 | BK1: MATCHDAY 6 | BW1: MATCHDAY 7 | CI1: MATCHDAY 8
A2: STATUS | B2: PLAYER | C2: MD 1 TEAM | D2: MD 1 TOTAL POINTS | E2: MD 1 ATTENDANCE | F2: MD 1 POINTS | G2: MD 1 (W) | H2: MD 1 (D) | I2: MD 1 (L) | J2: MD 1 GOALS | K2: MD 1 GOALIE POINT | L2: MD 1 CLEAN SHEET | M2: MD 1 RANK | N2: MD 1 FORM | O2: MD 2 TEAM | P2: MD 2 ACCUMULATED POINTS | Q2: MD 2 ATTENDANCE | R2: MD 2 POINTS | S2: MD 2 (W) | T2: MD 2 (D) | U2: MD 2 (L) | V2: MD 2 GOALS | W2: MD 2 GOALIE POINT | X2: MD 2 Clean Sheet | Y2: MD 2 RANK | Z2: MD 2 FORM | AA2: MD 3 TEAM | AB2: MD 3 ACCUMULATED POINTS | AC2: MD 3 ATTENDANCE | AD2: MD 3 POINTS | AE2: MD 3 (W) | AF2: MD 3 (D) | AG2: MD 3 (L) | AH2: MD 3 GOALS | AI2: MD 3 GOALIE POINT | AJ2: MD 3 CLEAN SHEET | AK2: MD 3 RANK | AL2: MD 3 FORM | AM2: MD 4 TEAM | AN2: MD 4 ACCUMULATED POINTS | AO2: MD 4 ATTENDANCE | AP2: MD 4 POINTS | AQ2: MD 4 (W) | AR2: MD 4 (D) | AS2: MD 4 (L) | AT2: MD 4 GOALS | AU2: MD 4 GOALIE POINT | AV2: MD 4 Clean Sheet | AW2: MD 4 RANK | AX2: MD 4 FORM | AY2: MD 5 TEAM | AZ2: MD 5 ACCUMULATED POINTS | BA2: MD 5 ATTENDANCE | BB2: MD 5 POINTS | BC2: MD 5 (W) | BD2: MD 5 (D) | BE2: MD 5 (L) | BF2: MD 5 GOALS | BG2: MD 5 GOALIE POINT | BH2: MD 5 CLEAN SHEET | BI2: MD 5 RANK | BJ2: MD 5 FORM | BK2: MD 6 TEAM | BL2: MD 6 ACCUMULATED POINTS | BM2: MD 6 ATTENDANCE | BN2: MD 6 POINTS | BO2: MD 6 (W) | BP2: MD 6 (D) | BQ2: MD 6 (L) | BR2: MD 6 GOALS | BS2: MD 6 GOALIE POINT | BT2: MD 6 Clean Sheet | BU2: MD 6 RANK | BV2: MD 6 FORM | BW2: MD 7 TEAM | BX2: MD 7 ACCUMULATED POINTS | BY2: MD 7 ATTENDANCE | BZ2: MD 7 POINTS | CA2: MD 7 (W) | CB2: MD 7 (D) | CC2: MD 7 (L) | CD2: MD 7 GOALS | CE2: MD 7 GOALIE POINT | CF2: MD 7 CLEAN SHEET | CG2: MD 7 RANK | CH2: MD 7 FORM | CI2: MD 8 TEAM | CJ2: MD 8 ACCUMULATED POINTS | CK2: MD 8 ATTENDANCE | CL2: MD 8 POINTS | CM2: MD 8 (W) | CN2: MD 8 (D) | CO2: MD 8 (L) | CP2: MD 8 GOALS | CQ2: MD 8 GOALIE POINT | CR2: MD 8 Clean Sheet | CS2: MD 8 RANK | CT2: MD 8 FORM | CU2: POINTS FOR GAMES | CV2: SEASON STATUS | CW2: PLAYER_ | CX2: TOTAL POINTS | CY2: ATTENDANCE | CZ2: WINS | DA2: DRAWS | DB2: LOSSES | DC2: Column 110 | DD2: GOALIE POINT | DE2: Column 109 | DF2: CLEAN SHEETS
A3: 🍀 | B3: 🏆 Asdruval | C3: BLUE | D3: =SUM(E3:F3)+K3 -> 6 | E3: =COUNTA(C3)*2 -> 2 | F3: =(G3*2)+(H3*1) -> 4 | G3: =IF(C3<>"", COUNTIFS(MATCH_INPUT!$K$2:$K$5,C3), 0) -> 2 | H3: =IF(C3<>"", COUNTIFS(MATCH_INPUT!$F$2:$F$5, C3, MATCH_INPUT!$K$2:$K$5, "Draw") + COUNTIFS(MATCH_INPUT!$J$2:$J$5, C3, MATCH_INPUT!$K$2:$K$5, "Draw"), 0) -> 0 | I3: =IF(C3<>"", COUNTIFS(MATCH_INPUT!$F$2:$F$5, C3, MATCH_INPUT!$K$2:$K$5, "<>"&C3, MATCH_INPUT!$K$2:$K$5, "<>Draw", MATCH_INPUT!$K$2:$K$5, "<>""") + COUNTIFS(MATCH_INPUT!$J$2:$J$5, C3, MATCH_INPUT!$K$2:$K$5, "<>"&C3, MATCH_INPUT!$K$2:$K$5, "<>Draw", MATCH_INPUT!$K$2:$K$5, "<>"""), 0) -> 0 | M3: =RANK(D3, D$3:D$38, 0) -> 2 | N3: =IF(M3<1, "↑", IF(M3>1, "↓", "=")) -> ↓ | O3: MAGENTA | P3: =SUM(Q3:R3)+D3+W3 -> 9 | Q3: =COUNTA(O3)*2 -> 2 | R3: =(S3*2)+(T3*1) -> 1 | S3: =IF(O3<>"", COUNTIFS(MATCH_INPUT!$K$6:$K$9,O3), 0) -> 0 | T3: =IF(O3<>"", COUNTIFS(MATCH_INPUT!$F$6:$F$9, O3, MATCH_INPUT!$K$6:$K$9, "Draw") + COUNTIFS(MATCH_INPUT!$J$6:$J$9, O3, MATCH_INPUT!$K$6:$K$9, "Draw"), 0) -> 1 | U3: =IF(O3<>"", COUNTIFS(MATCH_INPUT!$F$6:$F$9, O3, MATCH_INPUT!$K$6:$K$9, "<>"&O3, MATCH_INPUT!$K$6:$K$9, "<>Draw", MATCH_INPUT!$K$6:$K$9, "<>""") + COUNTIFS(MATCH_INPUT!$J$6:$J$9, O3, MATCH_INPUT!$K$6:$K$9, "<>"&O3, MATCH_INPUT!$K$6:$K$9, "<>Draw", MATCH_INPUT!$K$6:$K$9, "<>"""), 0) -> 1 | Y3: =RANK(P3, P$3:P$38, 0) -> 10 | Z3: =IF(Y3<M3, "↑", IF(Y3>M3, "↓", "=")) -> ↓ | AA3: BLUE | AB3: =SUM(AC3:AD3)+P3+AI3 -> 13 | AC3: =COUNTA(AA3)*2 -> 2 | AD3: =SUM(AE3*2)+(AF3*1) -> 2 | AE3: =IF(AA3<>"", COUNTIFS(MATCH_INPUT!$K$10:$K$13,AA3), 0) -> 0 | AF3: =IF(AA3<>"", COUNTIFS(MATCH_INPUT!$F$10:$F$13, AA3, MATCH_INPUT!$K$10:$K$13, "Draw") + COUNTIFS(MATCH_INPUT!$J$10:$J$13, AA3, MATCH_INPUT!$K$10:$K$13, "Draw"), 0) -> 2 | AG3: =IF(AA3<>"", COUNTIFS(MATCH_INPUT!$F$10:$F$13, AA3, MATCH_INPUT!$K$10:$K$13, "<>"&AA3, MATCH_INPUT!$K$10:$K$13, "<>Draw", MATCH_INPUT!$K$10:$K$13, "<>""") + COUNTIFS(MATCH_INPUT!$J$10:$J$13, AA3, MATCH_INPUT!$K$10:$K$13, "<>"&AA3, MATCH_INPUT!$K$10:$K$13, "<>Draw", MATCH_INPUT!$K$10:$K$13, "<>"""), 0) -> 0 | AH3: 1 | AK3: =RANK(AB3, AB$3:AB$38, 0) -> 9 | AL3: =IF(AK3<Y3, "↑", IF(AK3>Y3, "↓", "=")) -> ↑ | AM3: BLUE | AN3: =SUM(AO3:AP3)+AB3+AU3 -> 17 | AO3: =COUNTA(AM3)*2 -> 2 | AP3: =SUM(AQ3*2)+(AR3*1) -> 1 | AQ3: =IF(AM3<>"", COUNTIFS(MATCH_INPUT!$K$14:$K$17,AM3), 0) -> 0 | AR3: =IF(AM3<>"", COUNTIFS(MATCH_INPUT!$F$14:$F$17, AM3, MATCH_INPUT!$K$14:$K$17, "Draw") + COUNTIFS(MATCH_INPUT!$J$14:$J$17, AM3, MATCH_INPUT!$K$14:$K$17, "Draw"), 0) -> 1 | AS3: =IF(AM3<>"", COUNTIFS(MATCH_INPUT!$F$14:$F$17, AM3, MATCH_INPUT!$K$14:$K$17, "<>"&AM3, MATCH_INPUT!$K$14:$K$17, "<>Draw", MATCH_INPUT!$K$14:$K$17, "<>""") + COUNTIFS(MATCH_INPUT!$J$14:$J$17, AM3, MATCH_INPUT!$K$14:$K$17, "<>"&AM3, MATCH_INPUT!$K$14:$K$17, "<>Draw", MATCH_INPUT!$K$14:$K$17, "<>"""), 0) -> 1 | AU3: 1 | AW3: =RANK(AN3, AN$3:AN$38, 0) -> 9 | AX3: =IF(AW3<AK3, "↑", IF(AW3>AK3, "↓", "=")) -> = | AY3: ORANGE | AZ3: =SUM(BA3:BB3)+BG3+AN3 -> 30 | BA3: =COUNTA(AY3)*2 -> 2 | BB3: =SUM(BC3*2) + (BD3*1) + SUMIFS(MATCH_INPUT!$G$18:$G$21, MATCH_INPUT!$F$18:$F$21, AY3) + SUMIFS(MATCH_INPUT!$I$18:$I$21, MATCH_INPUT!$J$18:$J$21, AY3) -> 10 | BC3: =IF(AY3<>"", COUNTIFS(MATCH_INPUT!$K$18:$K$21,AY3), 0) -> 2 | BD3: =IF(AY3<>"", COUNTIFS(MATCH_INPUT!$F$18:$F$21, AY3, MATCH_INPUT!$K$18:$K$21, "Draw") + COUNTIFS(MATCH_INPUT!$J$18:$J$21, AY3, MATCH_INPUT!$K$18:$K$21, "Draw"), 0) -> 0 | BE3: =IF(AY3<>"", COUNTIFS(MATCH_INPUT!$F$18:$F$21, AY3, MATCH_INPUT!$K$18:$K$21, "<>"&AY3, MATCH_INPUT!$K$18:$K$21, "<>Draw", MATCH_INPUT!$K$18:$K$21, "<>""") + COUNTIFS(MATCH_INPUT!$J$18:$J$21, AY3, MATCH_INPUT!$K$18:$K$21, "<>"&AY3, MATCH_INPUT!$K$18:$K$21, "<>Draw", MATCH_INPUT!$K$18:$K$21, "<>"""), 0) -> 0 | BG3: 1 | BI3: =RANK(AZ3, AZ$3:AZ$38, 0) -> 2 | BJ3: =IF(BI3<AW3, "↑", IF(BI3>AW3, "↓", "=")) -> ↑ | BK3: GREEN | BL3: =SUM(BM3:BN3)+BS3+AZ3 -> 37 | BM3: =COUNTA(BK3)*2 -> 2 | BN3: =SUM(BO3*2) + (BP3*1) + SUMIFS(MATCH_INPUT!$G$22:$G$25, MATCH_INPUT!$F$22:$F$25, BK3) + SUMIFS(MATCH_INPUT!$I$22:$I$25, MATCH_INPUT!$J$22:$J$25, BK3) -> 5 | BO3: =IF(BK3<>"", COUNTIFS(MATCH_INPUT!$K$22:$K$25,BK3), 0) -> 1 | BP3: =IF(BK3<>"", COUNTIFS(MATCH_INPUT!$F$22:$F$25, BK3, MATCH_INPUT!$K$22:$K$25, "Draw") + COUNTIFS(MATCH_INPUT!$J$22:$J$25, BK3, MATCH_INPUT!$K$22:$K$25, "Draw"), 0) -> 1 | BQ3: =IF(BK3<>"", COUNTIFS(MATCH_INPUT!$F$22:$F$25, BK3, MATCH_INPUT!$K$22:$K$25, "<>"&BK3, MATCH_INPUT!$K$22:$K$25, "<>Draw", MATCH_INPUT!$K$22:$K$25, "<>""") + COUNTIFS(MATCH_INPUT!$J$22:$J$25, BK3, MATCH_INPUT!$K$22:$K$25, "<>"&BK3, MATCH_INPUT!$K$22:$K$25, "<>Draw", MATCH_INPUT!$K$22:$K$25, "<>"""), 0) -> 0 | BU3: =RANK(BL3, BL$3:BL$38, 0) -> 1 | BV3: =IF(BU3<BI3, "↑", IF(BU3>BI3, "↓", "=")) -> ↑ | BW3: GREEN | BX3: =SUM(BY3:BZ3)+CE3+BL3 -> 42 | BY3: =COUNTA(BW3)*2 -> 2 | BZ3: =SUM(CA3*2)+(CB3*1) + SUMIFS(MATCH_INPUT!$G$26:$G$29, MATCH_INPUT!$F$26:$F$29, BW3) + SUMIFS(MATCH_INPUT!$I$26:$I$29, MATCH_INPUT!$J$26:$J$29, BW3) -> 3 | CA3: =IF(BW3<>"", COUNTIFS(MATCH_INPUT!$K$26:$K$29,BW3), 0) -> 0 | CB3: =IF(BW3<>"", COUNTIFS(MATCH_INPUT!$F$26:$F$29, BW3, MATCH_INPUT!$K$26:$K$29, "Draw") + COUNTIFS(MATCH_INPUT!$J$26:$J$29, BW3, MATCH_INPUT!$K$26:$K$29, "Draw"), 0) -> 2 | CC3: =IF(BW3<>"", COUNTIFS(MATCH_INPUT!$F$26:$F$29, BW3, MATCH_INPUT!$K$26:$K$29, "<>"&BW3, MATCH_INPUT!$K$26:$K$29, "<>Draw", MATCH_INPUT!$K$26:$K$29, "<>""") + COUNTIFS(MATCH_INPUT!$J$26:$J$29, BW3, MATCH_INPUT!$K$26:$K$29, "<>"&BW3, MATCH_INPUT!$K$26:$K$29, "<>Draw", MATCH_INPUT!$K$26:$K$29, "<>"""), 0) -> 0 | CG3: =RANK(BX3, BX$3:BX$38, 0) -> 2 | CH3: =IF(CG3<BU3, "↑", IF(CG3>BU3, "↓", "=")) -> ↓ | CI3: ORANGE | CJ3: =SUM(CK3:CL3)+CQ3+BX3 -> 51 | CK3: =COUNTA(CI3)*2 -> 2 | CL3: =SUM(CM3*2)+(CN3*1) + SUMIFS(MATCH_INPUT!$G$30:$G$33, MATCH_INPUT!$F$30:$F$33, CI3) + SUMIFS(MATCH_INPUT!$I$30:$I$33, MATCH_INPUT!$J$30:$J$33, CI3) -> 7 | CM3: =IF(CI3<>"", COUNTIFS(MATCH_INPUT!$K$30:$K$33,CI3), 0) -> 2 | CN3: =IF(CI3<>"", COUNTIFS(MATCH_INPUT!$F$30:$F$33, CI3, MATCH_INPUT!$K$30:$K$33, "Draw") + COUNTIFS(MATCH_INPUT!$J$30:$J$33, CI3, MATCH_INPUT!$K$30:$K$33, "Draw"), 0) -> 0 | CO3: =IF(CI3<>"", COUNTIFS(MATCH_INPUT!$F$30:$F$33, CI3, MATCH_INPUT!$K$30:$K$33, "<>"&CI3, MATCH_INPUT!$K$30:$K$33, "<>Draw", MATCH_INPUT!$K$30:$K$33, "<>""") + COUNTIFS(MATCH_INPUT!$J$30:$J$33, CI3, MATCH_INPUT!$K$30:$K$33, "<>"&CI3, MATCH_INPUT!$K$30:$K$33, "<>Draw", MATCH_INPUT!$K$30:$K$33, "<>"""), 0) -> 0 | CS3: =RANK(CJ3, CJ$3:CJ$38, 0) -> 1 | CT3: =IF(CS3<CG3, "↑", IF(CS3>CG3, "↓", "=")) -> ↑ | CU3: =SUM(F3,R3,AD3,AP3,BB3,BN3,BZ3,CL3) -> 33 | CV3: =A3 -> 🍀 | CW3: =B3 -> 🏆 Asdruval | CX3: =SUM(CU3,CY3,DD3) -> 51 | CY3: =SUM( IF(AND('MATCH DATES'!$A$2 <= TODAY(), NOW() >= 'MATCH DATES'!$A$2 + TIME(22, 0, 0)), E3, 0), IF(AND('MATCH DATES'!$A$3 <= TODAY(), NOW() >= 'MATCH DATES'!$A$3 + TIME(22, 0, 0)), Q3, 0), IF(AND('MATCH DATES'!$A$4 <= TODAY(), NOW() >= 'MATCH DATES'!$A$4 + TIME(22, 0, 0)), AC3, 0), IF(AND('MATCH DATES'!$A$5 <= TODAY(), NOW() >= 'MATCH DATES'!$A$5 + TIME(22, 0, 0)), AO3, 0), IF(AND('MATCH DATES'!$A$6 <= TODAY(), NOW() >= 'MATCH DATES'!$A$6 + TIME(22, 0, 0)), BA3, 0), IF(AND('MATCH DATES'!$A$7 <= TODAY(), NOW() >= 'MATCH DATES'!$A$7 + TIME(22, 0, 0)), BM3, 0), IF(AND('MATCH DATES'!$A$8 <= TODAY(), NOW() >= 'MATCH DATES'!$A$8 + TIME(22, 0, 0)), BY3, 0), IF(AND('MATCH DATES'!$A$9 <= TODAY(), NOW() >= 'MATCH DATES'!$A$9 + TIME(22, 0, 0)), CK3, 0) ) -> 16 | CZ3: =SUM(G3,S3,AE3,AQ3,BC3,BO3,CA3,CM3) -> 7 | DA3: =SUM(H3,T3,AF3,AR3,BD3,BP3,CB3,CN3) -> 7 | DB3: =SUM( IF(AND('MATCH DATES'!$A$2 <= TODAY(), NOW() >= 'MATCH DATES'!$A$2 + TIME(22, 0, 0)), I3, 0), IF(AND('MATCH DATES'!$A$3 <= TODAY(), NOW() >= 'MATCH DATES'!$A$3 + TIME(22, 0, 0)), U3, 0), IF(AND('MATCH DATES'!$A$4 <= TODAY(), NOW() >= 'MATCH DATES'!$A$4 + TIME(22, 0, 0)), AG3, 0), IF(AND('MATCH DATES'!$A$5 <= TODAY(), NOW() >= 'MATCH DATES'!$A$5 + TIME(22, 0, 0)), AS3, 0), IF(AND('MATCH DATES'!$A$6 <= TODAY(), NOW() >= 'MATCH DATES'!$A$6 + TIME(22, 0, 0)), BE3, 0), IF(AND('MATCH DATES'!$A$7 <= TODAY(), NOW() >= 'MATCH DATES'!$A$7 + TIME(22, 0, 0)), BQ3, 0), IF(AND('MATCH DATES'!$A$8 <= TODAY(), NOW() >= 'MATCH DATES'!$A$8 + TIME(22, 0, 0)), CC3, 0), IF(AND('MATCH DATES'!$A$9 <= TODAY(), NOW() >= 'MATCH DATES'!$A$9 + TIME(22, 0, 0)), CO3, 0) ) -> 2 | DD3: =SUM(K3,W3,AI3,AU3,BG3,BS3,CE3,CQ3) -> 2 | DF3: =SUM(L3,X3,AJ3,AV3,BH3,BT3,CF3,CR3) -> 0
A4: 🍀 | B4: 🥈 Carlos S. | C4: GREEN | D4: =SUM(E4:F4)+K4 -> 2 | E4: =COUNTA(C4)*2 -> 2 | F4: =(G4*2)+(H4*1) -> 0 | G4: =IF(C4<>"", COUNTIFS(MATCH_INPUT!$K$2:$K$5,C4), 0) -> 0 | H4: =IF(C4<>"", COUNTIFS(MATCH_INPUT!$F$2:$F$5, C4, MATCH_INPUT!$K$2:$K$5, "Draw") + COUNTIFS(MATCH_INPUT!$J$2:$J$5, C4, MATCH_INPUT!$K$2:$K$5, "Draw"), 0) -> 0 | I4: =IF(C4<>"", COUNTIFS(MATCH_INPUT!$F$2:$F$5, C4, MATCH_INPUT!$K$2:$K$5, "<>"&C4, MATCH_INPUT!$K$2:$K$5, "<>Draw", MATCH_INPUT!$K$2:$K$5, "<>""") + COUNTIFS(MATCH_INPUT!$J$2:$J$5, C4, MATCH_INPUT!$K$2:$K$5, "<>"&C4, MATCH_INPUT!$K$2:$K$5, "<>Draw", MATCH_INPUT!$K$2:$K$5, "<>"""), 0) -> 2 | J4: 1 | M4: =RANK(D4, D$3:D$38, 0) -> 26 | N4: =IF(M4<1, "↑", IF(M4>1, "↓", "=")) -> ↓ | O4: ORANGE | P4: =SUM(Q4:R4)+D4+W4 -> 4 | Q4: =COUNTA(O4)*2 -> 2 | R4: =(S4*2)+(T4*1) -> 0 | S4: =IF(O4<>"", COUNTIFS(MATCH_INPUT!$K$6:$K$9,O4), 0) -> 0 | T4: =IF(O4<>"", COUNTIFS(MATCH_INPUT!$F$6:$F$9, O4, MATCH_INPUT!$K$6:$K$9, "Draw") + COUNTIFS(MATCH_INPUT!$J$6:$J$9, O4, MATCH_INPUT!$K$6:$K$9, "Draw"), 0) -> 0 | U4: =IF(O4<>"", COUNTIFS(MATCH_INPUT!$F$6:$F$9, O4, MATCH_INPUT!$K$6:$K$9, "<>"&O4, MATCH_INPUT!$K$6:$K$9, "<>Draw", MATCH_INPUT!$K$6:$K$9, "<>""") + COUNTIFS(MATCH_INPUT!$J$6:$J$9, O4, MATCH_INPUT!$K$6:$K$9, "<>"&O4, MATCH_INPUT!$K$6:$K$9, "<>Draw", MATCH_INPUT!$K$6:$K$9, "<>"""), 0) -> 2 | Y4: =RANK(P4, P$3:P$38, 0) -> 31 | Z4: =IF(Y4<M4, "↑", IF(Y4>M4, "↓", "=")) -> ↓ | AA4: ORANGE | AB4: =SUM(AC4:AD4)+P4+AI4 -> 9 | AC4: =COUNTA(AA4)*2 -> 2 | AD4: =SUM(AE4*2)+(AF4*1) -> 3 | AE4: =IF(AA4<>"", COUNTIFS(MATCH_INPUT!$K$10:$K$13,AA4), 0) -> 1 | AF4: =IF(AA4<>"", COUNTIFS(MATCH_INPUT!$F$10:$F$13, AA4, MATCH_INPUT!$K$10:$K$13, "Draw") + COUNTIFS(MATCH_INPUT!$J$10:$J$13, AA4, MATCH_INPUT!$K$10:$K$13, "Draw"), 0) -> 1 | AG4: =IF(AA4<>"", COUNTIFS(MATCH_INPUT!$F$10:$F$13, AA4, MATCH_INPUT!$K$10:$K$13, "<>"&AA4, MATCH_INPUT!$K$10:$K$13, "<>Draw", MATCH_INPUT!$K$10:$K$13, "<>""") + COUNTIFS(MATCH_INPUT!$J$10:$J$13, AA4, MATCH_INPUT!$K$10:$K$13, "<>"&AA4, MATCH_INPUT!$K$10:$K$13, "<>Draw", MATCH_INPUT!$K$10:$K$13, "<>"""), 0) -> 0 | AH4: 1 | AK4: =RANK(AB4, AB$3:AB$38, 0) -> 28 | AL4: =IF(AK4<Y4, "↑", IF(AK4>Y4, "↓", "=")) -> ↑ | AM4: ORANGE | AN4: =SUM(AO4:AP4)+AB4+AU4 -> 13 | AO4: =COUNTA(AM4)*2 -> 2 | AP4: =SUM(AQ4*2)+(AR4*1) -> 2 | AQ4: =IF(AM4<>"", COUNTIFS(MATCH_INPUT!$K$14:$K$17,AM4), 0) -> 0 | AR4: =IF(AM4<>"", COUNTIFS(MATCH_INPUT!$F$14:$F$17, AM4, MATCH_INPUT!$K$14:$K$17, "Draw") + COUNTIFS(MATCH_INPUT!$J$14:$J$17, AM4, MATCH_INPUT!$K$14:$K$17, "Draw"), 0) -> 2 | AS4: =IF(AM4<>"", COUNTIFS(MATCH_INPUT!$F$14:$F$17, AM4, MATCH_INPUT!$K$14:$K$17, "<>"&AM4, MATCH_INPUT!$K$14:$K$17, "<>Draw", MATCH_INPUT!$K$14:$K$17, "<>""") + COUNTIFS(MATCH_INPUT!$J$14:$J$17, AM4, MATCH_INPUT!$K$14:$K$17, "<>"&AM4, MATCH_INPUT!$K$14:$K$17, "<>Draw", MATCH_INPUT!$K$14:$K$17, "<>"""), 0) -> 0 | AW4: =RANK(AN4, AN$3:AN$38, 0) -> 26 | AX4: =IF(AW4<AK4, "↑", IF(AW4>AK4, "↓", "=")) -> ↑ | AY4: ORANGE | AZ4: =SUM(BA4:BB4)+BG4+AN4 -> 25 | BA4: =COUNTA(AY4)*2 -> 2 | BB4: =SUM(BC4*2) + (BD4*1) + SUMIFS(MATCH_INPUT!$G$18:$G$21, MATCH_INPUT!$F$18:$F$21, AY4) + SUMIFS(MATCH_INPUT!$I$18:$I$21, MATCH_INPUT!$J$18:$J$21, AY4) -> 10 | BC4: =IF(AY4<>"", COUNTIFS(MATCH_INPUT!$K$18:$K$21,AY4), 0) -> 2 | BD4: =IF(AY4<>"", COUNTIFS(MATCH_INPUT!$F$18:$F$21, AY4, MATCH_INPUT!$K$18:$K$21, "Draw") + COUNTIFS(MATCH_INPUT!$J$18:$J$21, AY4, MATCH_INPUT!$K$18:$K$21, "Draw"), 0) -> 0 | BE4: =IF(AY4<>"", COUNTIFS(MATCH_INPUT!$F$18:$F$21, AY4, MATCH_INPUT!$K$18:$K$21, "<>"&AY4, MATCH_INPUT!$K$18:$K$21, "<>Draw", MATCH_INPUT!$K$18:$K$21, "<>""") + COUNTIFS(MATCH_INPUT!$J$18:$J$21, AY4, MATCH_INPUT!$K$18:$K$21, "<>"&AY4, MATCH_INPUT!$K$18:$K$21, "<>Draw", MATCH_INPUT!$K$18:$K$21, "<>"""), 0) -> 0 | BI4: =RANK(AZ4, AZ$3:AZ$38, 0) -> 8 | BJ4: =IF(BI4<AW4, "↑", IF(BI4>AW4, "↓", "=")) -> ↑ | BK4: BLUE | BL4: =SUM(BM4:BN4)+BS4+AZ4 -> 33 | BM4: =COUNTA(BK4)*2 -> 2 | BN4: =SUM(BO4*2) + (BP4*1) + SUMIFS(MATCH_INPUT!$G$22:$G$25, MATCH_INPUT!$F$22:$F$25, BK4) + SUMIFS(MATCH_INPUT!$I$22:$I$25, MATCH_INPUT!$J$22:$J$25, BK4) -> 6 | BO4: =IF(BK4<>"", COUNTIFS(MATCH_INPUT!$K$22:$K$25,BK4), 0) -> 1 | BP4: =IF(BK4<>"", COUNTIFS(MATCH_INPUT!$F$22:$F$25, BK4, MATCH_INPUT!$K$22:$K$25, "Draw") + COUNTIFS(MATCH_INPUT!$J$22:$J$25, BK4, MATCH_INPUT!$K$22:$K$25, "Draw"), 0) -> 1 | BQ4: =IF(BK4<>"", COUNTIFS(MATCH_INPUT!$F$22:$F$25, BK4, MATCH_INPUT!$K$22:$K$25, "<>"&BK4, MATCH_INPUT!$K$22:$K$25, "<>Draw", MATCH_INPUT!$K$22:$K$25, "<>""") + COUNTIFS(MATCH_INPUT!$J$22:$J$25, BK4, MATCH_INPUT!$K$22:$K$25, "<>"&BK4, MATCH_INPUT!$K$22:$K$25, "<>Draw", MATCH_INPUT!$K$22:$K$25, "<>"""), 0) -> 0 | BU4: =RANK(BL4, BL$3:BL$38, 0) -> 5 | BV4: =IF(BU4<BI4, "↑", IF(BU4>BI4, "↓", "=")) -> ↑ | BW4: BLUE | BX4: =SUM(BY4:BZ4)+CE4+BL4 -> 40 | BY4: =COUNTA(BW4)*2 -> 2 | BZ4: =SUM(CA4*2)+(CB4*1) + SUMIFS(MATCH_INPUT!$G$26:$G$29, MATCH_INPUT!$F$26:$F$29, BW4) + SUMIFS(MATCH_INPUT!$I$26:$I$29, MATCH_INPUT!$J$26:$J$29, BW4) -> 5 | CA4: =IF(BW4<>"", COUNTIFS(MATCH_INPUT!$K$26:$K$29,BW4), 0) -> 1 | CB4: =IF(BW4<>"", COUNTIFS(MATCH_INPUT!$F$26:$F$29, BW4, MATCH_INPUT!$K$26:$K$29, "Draw") + COUNTIFS(MATCH_INPUT!$J$26:$J$29, BW4, MATCH_INPUT!$K$26:$K$29, "Draw"), 0) -> 0 | CC4: =IF(BW4<>"", COUNTIFS(MATCH_INPUT!$F$26:$F$29, BW4, MATCH_INPUT!$K$26:$K$29, "<>"&BW4, MATCH_INPUT!$K$26:$K$29, "<>Draw", MATCH_INPUT!$K$26:$K$29, "<>""") + COUNTIFS(MATCH_INPUT!$J$26:$J$29, BW4, MATCH_INPUT!$K$26:$K$29, "<>"&BW4, MATCH_INPUT!$K$26:$K$29, "<>Draw", MATCH_INPUT!$K$26:$K$29, "<>"""), 0) -> 1 | CD4: 1 | CG4: =RANK(BX4, BX$3:BX$38, 0) -> 5 | CH4: =IF(CG4<BU4, "↑", IF(CG4>BU4, "↓", "=")) -> = | CI4: ORANGE | CJ4: =SUM(CK4:CL4)+CQ4+BX4 -> 49 | CK4: =COUNTA(CI4)*2 -> 2 | CL4: =SUM(CM4*2)+(CN4*1) + SUMIFS(MATCH_INPUT!$G$30:$G$33, MATCH_INPUT!$F$30:$F$33, CI4) + SUMIFS(MATCH_INPUT!$I$30:$I$33, MATCH_INPUT!$J$30:$J$33, CI4) -> 7 | CM4: =IF(CI4<>"", COUNTIFS(MATCH_INPUT!$K$30:$K$33,CI4), 0) -> 2 | CN4: =IF(CI4<>"", COUNTIFS(MATCH_INPUT!$F$30:$F$33, CI4, MATCH_INPUT!$K$30:$K$33, "Draw") + COUNTIFS(MATCH_INPUT!$J$30:$J$33, CI4, MATCH_INPUT!$K$30:$K$33, "Draw"), 0) -> 0 | CO4: =IF(CI4<>"", COUNTIFS(MATCH_INPUT!$F$30:$F$33, CI4, MATCH_INPUT!$K$30:$K$33, "<>"&CI4, MATCH_INPUT!$K$30:$K$33, "<>Draw", MATCH_INPUT!$K$30:$K$33, "<>""") + COUNTIFS(MATCH_INPUT!$J$30:$J$33, CI4, MATCH_INPUT!$K$30:$K$33, "<>"&CI4, MATCH_INPUT!$K$30:$K$33, "<>Draw", MATCH_INPUT!$K$30:$K$33, "<>"""), 0) -> 0 | CS4: =RANK(CJ4, CJ$3:CJ$38, 0) -> 2 | CT4: =IF(CS4<CG4, "↑", IF(CS4>CG4, "↓", "=")) -> ↑ | CU4: =SUM(F4,R4,AD4,AP4,BB4,BN4,BZ4,CL4) -> 33 | CV4: =A4 -> 🍀 | CW4: =B4 -> 🥈 Carlos S. | CX4: =SUM(CU4,CY4,DD4) -> 49 | CY4: =SUM( IF(AND('MATCH DATES'!$A$2 <= TODAY(), NOW() >= 'MATCH DATES'!$A$2 + TIME(22, 0, 0)), E4, 0), IF(AND('MATCH DATES'!$A$3 <= TODAY(), NOW() >= 'MATCH DATES'!$A$3 + TIME(22, 0, 0)), Q4, 0), IF(AND('MATCH DATES'!$A$4 <= TODAY(), NOW() >= 'MATCH DATES'!$A$4 + TIME(22, 0, 0)), AC4, 0), IF(AND('MATCH DATES'!$A$5 <= TODAY(), NOW() >= 'MATCH DATES'!$A$5 + TIME(22, 0, 0)), AO4, 0), IF(AND('MATCH DATES'!$A$6 <= TODAY(), NOW() >= 'MATCH DATES'!$A$6 + TIME(22, 0, 0)), BA4, 0), IF(AND('MATCH DATES'!$A$7 <= TODAY(), NOW() >= 'MATCH DATES'!$A$7 + TIME(22, 0, 0)), BM4, 0), IF(AND('MATCH DATES'!$A$8 <= TODAY(), NOW() >= 'MATCH DATES'!$A$8 + TIME(22, 0, 0)), BY4, 0), IF(AND('MATCH DATES'!$A$9 <= TODAY(), NOW() >= 'MATCH DATES'!$A$9 + TIME(22, 0, 0)), CK4, 0) ) -> 16 | CZ4: =SUM(G4,S4,AE4,AQ4,BC4,BO4,CA4,CM4) -> 7 | DA4: =SUM(H4,T4,AF4,AR4,BD4,BP4,CB4,CN4) -> 4 | DB4: =SUM( IF(AND('MATCH DATES'!$A$2 <= TODAY(), NOW() >= 'MATCH DATES'!$A$2 + TIME(22, 0, 0)), I4, 0), IF(AND('MATCH DATES'!$A$3 <= TODAY(), NOW() >= 'MATCH DATES'!$A$3 + TIME(22, 0, 0)), U4, 0), IF(AND('MATCH DATES'!$A$4 <= TODAY(), NOW() >= 'MATCH DATES'!$A$4 + TIME(22, 0, 0)), AG4, 0), IF(AND('MATCH DATES'!$A$5 <= TODAY(), NOW() >= 'MATCH DATES'!$A$5 + TIME(22, 0, 0)), AS4, 0), IF(AND('MATCH DATES'!$A$6 <= TODAY(), NOW() >= 'MATCH DATES'!$A$6 + TIME(22, 0, 0)), BE4, 0), IF(AND('MATCH DATES'!$A$7 <= TODAY(), NOW() >= 'MATCH DATES'!$A$7 + TIME(22, 0, 0)), BQ4, 0), IF(AND('MATCH DATES'!$A$8 <= TODAY(), NOW() >= 'MATCH DATES'!$A$8 + TIME(22, 0, 0)), CC4, 0), IF(AND('MATCH DATES'!$A$9 <= TODAY(), NOW() >= 'MATCH DATES'!$A$9 + TIME(22, 0, 0)), CO4, 0) ) -> 5 | DD4: =SUM(K4,W4,AI4,AU4,BG4,BS4,CE4,CQ4) -> 0 | DF4: =SUM(L4,X4,AJ4,AV4,BH4,BT4,CF4,CR4) -> 0
A5: 🍀 | B5: 🥉 Andres | C5: BLUE | D5: =SUM(E5:F5)+K5 -> 6 | E5: =COUNTA(C5)*2 -> 2 | F5: =(G5*2)+(H5*1) -> 4 | G5: =IF(C5<>"", COUNTIFS(MATCH_INPUT!$K$2:$K$5,C5), 0) -> 2 | H5: =IF(C5<>"", COUNTIFS(MATCH_INPUT!$F$2:$F$5, C5, MATCH_INPUT!$K$2:$K$5, "Draw") + COUNTIFS(MATCH_INPUT!$J$2:$J$5, C5, MATCH_INPUT!$K$2:$K$5, "Draw"), 0) -> 0 | I5: =IF(C5<>"", COUNTIFS(MATCH_INPUT!$F$2:$F$5, C5, MATCH_INPUT!$K$2:$K$5, "<>"&C5, MATCH_INPUT!$K$2:$K$5, "<>Draw", MATCH_INPUT!$K$2:$K$5, "<>""") + COUNTIFS(MATCH_INPUT!$J$2:$J$5, C5, MATCH_INPUT!$K$2:$K$5, "<>"&C5, MATCH_INPUT!$K$2:$K$5, "<>Draw", MATCH_INPUT!$K$2:$K$5, "<>"""), 0) -> 0 | J5: 1 | M5: =RANK(D5, D$3:D$38, 0) -> 2 | N5: =IF(M5<1, "↑", IF(M5>1, "↓", "=")) -> ↓ | O5: GREEN | P5: =SUM(Q5:R5)+D5+W5 -> 12 | Q5: =COUNTA(O5)*2 -> 2 | R5: =(S5*2)+(T5*1) -> 4 | S5: =IF(O5<>"", COUNTIFS(MATCH_INPUT!$K$6:$K$9,O5), 0) -> 2 | T5: =IF(O5<>"", COUNTIFS(MATCH_INPUT!$F$6:$F$9, O5, MATCH_INPUT!$K$6:$K$9, "Draw") + COUNTIFS(MATCH_INPUT!$J$6:$J$9, O5, MATCH_INPUT!$K$6:$K$9, "Draw"), 0) -> 0 | U5: =IF(O5<>"", COUNTIFS(MATCH_INPUT!$F$6:$F$9, O5, MATCH_INPUT!$K$6:$K$9, "<>"&O5, MATCH_INPUT!$K$6:$K$9, "<>Draw", MATCH_INPUT!$K$6:$K$9, "<>""") + COUNTIFS(MATCH_INPUT!$J$6:$J$9, O5, MATCH_INPUT!$K$6:$K$9, "<>"&O5, MATCH_INPUT!$K$6:$K$9, "<>Draw", MATCH_INPUT!$K$6:$K$9, "<>"""), 0) -> 0 | Y5: =RANK(P5, P$3:P$38, 0) -> 1 | Z5: =IF(Y5<M5, "↑", IF(Y5>M5, "↓", "=")) -> ↑ | AA5: MAGENTA | AB5: =SUM(AC5:AD5)+P5+AI5 -> 15 | AC5: =COUNTA(AA5)*2 -> 2 | AD5: =SUM(AE5*2)+(AF5*1) -> 1 | AE5: =IF(AA5<>"", COUNTIFS(MATCH_INPUT!$K$10:$K$13,AA5), 0) -> 0 | AF5: =IF(AA5<>"", COUNTIFS(MATCH_INPUT!$F$10:$F$13, AA5, MATCH_INPUT!$K$10:$K$13, "Draw") + COUNTIFS(MATCH_INPUT!$J$10:$J$13, AA5, MATCH_INPUT!$K$10:$K$13, "Draw"), 0) -> 1 | AG5: =IF(AA5<>"", COUNTIFS(MATCH_INPUT!$F$10:$F$13, AA5, MATCH_INPUT!$K$10:$K$13, "<>"&AA5, MATCH_INPUT!$K$10:$K$13, "<>Draw", MATCH_INPUT!$K$10:$K$13, "<>""") + COUNTIFS(MATCH_INPUT!$J$10:$J$13, AA5, MATCH_INPUT!$K$10:$K$13, "<>"&AA5, MATCH_INPUT!$K$10:$K$13, "<>Draw", MATCH_INPUT!$K$10:$K$13, "<>"""), 0) -> 1 | AH5: 1 | AK5: =RANK(AB5, AB$3:AB$38, 0) -> 3 | AL5: =IF(AK5<Y5, "↑", IF(AK5>Y5, "↓", "=")) -> ↓ | AM5: GREEN | AN5: =SUM(AO5:AP5)+AB5+AU5 -> 18 | AO5: =COUNTA(AM5)*2 -> 2 | AP5: =SUM(AQ5*2)+(AR5*1) -> 1 | AQ5: =IF(AM5<>"", COUNTIFS(MATCH_INPUT!$K$14:$K$17,AM5), 0) -> 0 | AR5: =IF(AM5<>"", COUNTIFS(MATCH_INPUT!$F$14:$F$17, AM5, MATCH_INPUT!$K$14:$K$17, "Draw") + COUNTIFS(MATCH_INPUT!$J$14:$J$17, AM5, MATCH_INPUT!$K$14:$K$17, "Draw"), 0) -> 1 | AS5: =IF(AM5<>"", COUNTIFS(MATCH_INPUT!$F$14:$F$17, AM5, MATCH_INPUT!$K$14:$K$17, "<>"&AM5, MATCH_INPUT!$K$14:$K$17, "<>Draw", MATCH_INPUT!$K$14:$K$17, "<>""") + COUNTIFS(MATCH_INPUT!$J$14:$J$17, AM5, MATCH_INPUT!$K$14:$K$17, "<>"&AM5, MATCH_INPUT!$K$14:$K$17, "<>Draw", MATCH_INPUT!$K$14:$K$17, "<>"""), 0) -> 1 | AW5: =RANK(AN5, AN$3:AN$38, 0) -> 4 | AX5: =IF(AW5<AK5, "↑", IF(AW5>AK5, "↓", "=")) -> ↓ | AY5: ORANGE | AZ5: =SUM(BA5:BB5)+BG5+AN5 -> 31 | BA5: =COUNTA(AY5)*2 -> 2 | BB5: =SUM(BC5*2) + (BD5*1) + SUMIFS(MATCH_INPUT!$G$18:$G$21, MATCH_INPUT!$F$18:$F$21, AY5) + SUMIFS(MATCH_INPUT!$I$18:$I$21, MATCH_INPUT!$J$18:$J$21, AY5) -> 10 | BC5: =IF(AY5<>"", COUNTIFS(MATCH_INPUT!$K$18:$K$21,AY5), 0) -> 2 | BD5: =IF(AY5<>"", COUNTIFS(MATCH_INPUT!$F$18:$F$21, AY5, MATCH_INPUT!$K$18:$K$21, "Draw") + COUNTIFS(MATCH_INPUT!$J$18:$J$21, AY5, MATCH_INPUT!$K$18:$K$21, "Draw"), 0) -> 0 | BE5: =IF(AY5<>"", COUNTIFS(MATCH_INPUT!$F$18:$F$21, AY5, MATCH_INPUT!$K$18:$K$21, "<>"&AY5, MATCH_INPUT!$K$18:$K$21, "<>Draw", MATCH_INPUT!$K$18:$K$21, "<>""") + COUNTIFS(MATCH_INPUT!$J$18:$J$21, AY5, MATCH_INPUT!$K$18:$K$21, "<>"&AY5, MATCH_INPUT!$K$18:$K$21, "<>Draw", MATCH_INPUT!$K$18:$K$21, "<>"""), 0) -> 0 | BG5: 1 | BH5: 1 | BI5: =RANK(AZ5, AZ$3:AZ$38, 0) -> 1 | BJ5: =IF(BI5<AW5, "↑", IF(BI5>AW5, "↓", "=")) -> ↑ | BK5: MAGENTA | BL5: =SUM(BM5:BN5)+BS5+AZ5 -> 37 | BM5: =COUNTA(BK5)*2 -> 2 | BN5: =SUM(BO5*2) + (BP5*1) + SUMIFS(MATCH_INPUT!$G$22:$G$25, MATCH_INPUT!$F$22:$F$25, BK5) + SUMIFS(MATCH_INPUT!$I$22:$I$25, MATCH_INPUT!$J$22:$J$25, BK5) -> 4 | BO5: =IF(BK5<>"", COUNTIFS(MATCH_INPUT!$K$22:$K$25,BK5), 0) -> 0 | BP5: =IF(BK5<>"", COUNTIFS(MATCH_INPUT!$F$22:$F$25, BK5, MATCH_INPUT!$K$22:$K$25, "Draw") + COUNTIFS(MATCH_INPUT!$J$22:$J$25, BK5, MATCH_INPUT!$K$22:$K$25, "Draw"), 0) -> 2 | BQ5: =IF(BK5<>"", COUNTIFS(MATCH_INPUT!$F$22:$F$25, BK5, MATCH_INPUT!$K$22:$K$25, "<>"&BK5, MATCH_INPUT!$K$22:$K$25, "<>Draw", MATCH_INPUT!$K$22:$K$25, "<>""") + COUNTIFS(MATCH_INPUT!$J$22:$J$25, BK5, MATCH_INPUT!$K$22:$K$25, "<>"&BK5, MATCH_INPUT!$K$22:$K$25, "<>Draw", MATCH_INPUT!$K$22:$K$25, "<>"""), 0) -> 0 | BU5: =RANK(BL5, BL$3:BL$38, 0) -> 1 | BV5: =IF(BU5<BI5, "↑", IF(BU5>BI5, "↓", "=")) -> = | BW5: MAGENTA | BX5: =SUM(BY5:BZ5)+CE5+BL5 -> 42 | BY5: =COUNTA(BW5)*2 -> 2 | BZ5: =SUM(CA5*2)+(CB5*1) + SUMIFS(MATCH_INPUT!$G$26:$G$29, MATCH_INPUT!$F$26:$F$29, BW5) + SUMIFS(MATCH_INPUT!$I$26:$I$29, MATCH_INPUT!$J$26:$J$29, BW5) -> 3 | CA5: =IF(BW5<>"", COUNTIFS(MATCH_INPUT!$K$26:$K$29,BW5), 0) -> 0 | CB5: =IF(BW5<>"", COUNTIFS(MATCH_INPUT!$F$26:$F$29, BW5, MATCH_INPUT!$K$26:$K$29, "Draw") + COUNTIFS(MATCH_INPUT!$J$26:$J$29, BW5, MATCH_INPUT!$K$26:$K$29, "Draw"), 0) -> 1 | CC5: =IF(BW5<>"", COUNTIFS(MATCH_INPUT!$F$26:$F$29, BW5, MATCH_INPUT!$K$26:$K$29, "<>"&BW5, MATCH_INPUT!$K$26:$K$29, "<>Draw", MATCH_INPUT!$K$26:$K$29, "<>""") + COUNTIFS(MATCH_INPUT!$J$26:$J$29, BW5, MATCH_INPUT!$K$26:$K$29, "<>"&BW5, MATCH_INPUT!$K$26:$K$29, "<>Draw", MATCH_INPUT!$K$26:$K$29, "<>"""), 0) -> 1 | CG5: =RANK(BX5, BX$3:BX$38, 0) -> 2 | CH5: =IF(CG5<BU5, "↑", IF(CG5>BU5, "↓", "=")) -> ↓ | CI5: MAGENTA | CJ5: =SUM(CK5:CL5)+CQ5+BX5 -> 46 | CK5: =COUNTA(CI5)*2 -> 2 | CL5: =SUM(CM5*2)+(CN5*1) + SUMIFS(MATCH_INPUT!$G$30:$G$33, MATCH_INPUT!$F$30:$F$33, CI5) + SUMIFS(MATCH_INPUT!$I$30:$I$33, MATCH_INPUT!$J$30:$J$33, CI5) -> 2 | CM5: =IF(CI5<>"", COUNTIFS(MATCH_INPUT!$K$30:$K$33,CI5), 0) -> 0 | CN5: =IF(CI5<>"", COUNTIFS(MATCH_INPUT!$F$30:$F$33, CI5, MATCH_INPUT!$K$30:$K$33, "Draw") + COUNTIFS(MATCH_INPUT!$J$30:$J$33, CI5, MATCH_INPUT!$K$30:$K$33, "Draw"), 0) -> 1 | CO5: =IF(CI5<>"", COUNTIFS(MATCH_INPUT!$F$30:$F$33, CI5, MATCH_INPUT!$K$30:$K$33, "<>"&CI5, MATCH_INPUT!$K$30:$K$33, "<>Draw", MATCH_INPUT!$K$30:$K$33, "<>""") + COUNTIFS(MATCH_INPUT!$J$30:$J$33, CI5, MATCH_INPUT!$K$30:$K$33, "<>"&CI5, MATCH_INPUT!$K$30:$K$33, "<>Draw", MATCH_INPUT!$K$30:$K$33, "<>"""), 0) -> 1 | CS5: =RANK(CJ5, CJ$3:CJ$38, 0) -> 3 | CT5: =IF(CS5<CG5, "↑", IF(CS5>CG5, "↓", "=")) -> ↓ | CU5: =SUM(F5,R5,AD5,AP5,BB5,BN5,BZ5,CL5) -> 29 | CV5: =A5 -> 🍀 | CW5: =B5 -> 🥉 Andres | CX5: =SUM(CU5,CY5,DD5) -> 46 | CY5: =SUM( IF(AND('MATCH DATES'!$A$2 <= TODAY(), NOW() >= 'MATCH DATES'!$A$2 + TIME(22, 0, 0)), E5, 0), IF(AND('MATCH DATES'!$A$3 <= TODAY(), NOW() >= 'MATCH DATES'!$A$3 + TIME(22, 0, 0)), Q5, 0), IF(AND('MATCH DATES'!$A$4 <= TODAY(), NOW() >= 'MATCH DATES'!$A$4 + TIME(22, 0, 0)), AC5, 0), IF(AND('MATCH DATES'!$A$5 <= TODAY(), NOW() >= 'MATCH DATES'!$A$5 + TIME(22, 0, 0)), AO5, 0), IF(AND('MATCH DATES'!$A$6 <= TODAY(), NOW() >= 'MATCH DATES'!$A$6 + TIME(22, 0, 0)), BA5, 0), IF(AND('MATCH DATES'!$A$7 <= TODAY(), NOW() >= 'MATCH DATES'!$A$7 + TIME(22, 0, 0)), BM5, 0), IF(AND('MATCH DATES'!$A$8 <= TODAY(), NOW() >= 'MATCH DATES'!$A$8 + TIME(22, 0, 0)), BY5, 0), IF(AND('MATCH DATES'!$A$9 <= TODAY(), NOW() >= 'MATCH DATES'!$A$9 + TIME(22, 0, 0)), CK5, 0) ) -> 16 | CZ5: =SUM(G5,S5,AE5,AQ5,BC5,BO5,CA5,CM5) -> 6 | DA5: =SUM(H5,T5,AF5,AR5,BD5,BP5,CB5,CN5) -> 6 | DB5: =SUM( IF(AND('MATCH DATES'!$A$2 <= TODAY(), NOW() >= 'MATCH DATES'!$A$2 + TIME(22, 0, 0)), I5, 0), IF(AND('MATCH DATES'!$A$3 <= TODAY(), NOW() >= 'MATCH DATES'!$A$3 + TIME(22, 0, 0)), U5, 0), IF(AND('MATCH DATES'!$A$4 <= TODAY(), NOW() >= 'MATCH DATES'!$A$4 + TIME(22, 0, 0)), AG5, 0), IF(AND('MATCH DATES'!$A$5 <= TODAY(), NOW() >= 'MATCH DATES'!$A$5 + TIME(22, 0, 0)), AS5, 0), IF(AND('MATCH DATES'!$A$6 <= TODAY(), NOW() >= 'MATCH DATES'!$A$6 + TIME(22, 0, 0)), BE5, 0), IF(AND('MATCH DATES'!$A$7 <= TODAY(), NOW() >= 'MATCH DATES'!$A$7 + TIME(22, 0, 0)), BQ5, 0), IF(AND('MATCH DATES'!$A$8 <= TODAY(), NOW() >= 'MATCH DATES'!$A$8 + TIME(22, 0, 0)), CC5, 0), IF(AND('MATCH DATES'!$A$9 <= TODAY(), NOW() >= 'MATCH DATES'!$A$9 + TIME(22, 0, 0)), CO5, 0) ) -> 4 | DD5: =SUM(K5,W5,AI5,AU5,BG5,BS5,CE5,CQ5) -> 1 | DF5: =SUM(L5,X5,AJ5,AV5,BH5,BT5,CF5,CR5) -> 1
A6: 🍀 | B6: Mikey | C6: ORANGE | D6: =SUM(E6:F6)+K6 -> 4 | E6: =COUNTA(C6)*2 -> 2 | F6: =(G6*2)+(H6*1) -> 2 | G6: =IF(C6<>"", COUNTIFS(MATCH_INPUT!$K$2:$K$5,C6), 0) -> 1 | H6: =IF(C6<>"", COUNTIFS(MATCH_INPUT!$F$2:$F$5, C6, MATCH_INPUT!$K$2:$K$5, "Draw") + COUNTIFS(MATCH_INPUT!$J$2:$J$5, C6, MATCH_INPUT!$K$2:$K$5, "Draw"), 0) -> 0 | I6: =IF(C6<>"", COUNTIFS(MATCH_INPUT!$F$2:$F$5, C6, MATCH_INPUT!$K$2:$K$5, "<>"&C6, MATCH_INPUT!$K$2:$K$5, "<>Draw", MATCH_INPUT!$K$2:$K$5, "<>""") + COUNTIFS(MATCH_INPUT!$J$2:$J$5, C6, MATCH_INPUT!$K$2:$K$5, "<>"&C6, MATCH_INPUT!$K$2:$K$5, "<>Draw", MATCH_INPUT!$K$2:$K$5, "<>"""), 0) -> 1 | M6: =RANK(D6, D$3:D$38, 0) -> 11 | N6: =IF(M6<1, "↑", IF(M6>1, "↓", "=")) -> ↓ | O6: BLUE | P6: =SUM(Q6:R6)+D6+W6 -> 9 | Q6: =COUNTA(O6)*2 -> 2 | R6: =(S6*2)+(T6*1) -> 3 | S6: =IF(O6<>"", COUNTIFS(MATCH_INPUT!$K$6:$K$9,O6), 0) -> 1 | T6: =IF(O6<>"", COUNTIFS(MATCH_INPUT!$F$6:$F$9, O6, MATCH_INPUT!$K$6:$K$9, "Draw") + COUNTIFS(MATCH_INPUT!$J$6:$J$9, O6, MATCH_INPUT!$K$6:$K$9, "Draw"), 0) -> 1 | U6: =IF(O6<>"", COUNTIFS(MATCH_INPUT!$F$6:$F$9, O6, MATCH_INPUT!$K$6:$K$9, "<>"&O6, MATCH_INPUT!$K$6:$K$9, "<>Draw", MATCH_INPUT!$K$6:$K$9, "<>""") + COUNTIFS(MATCH_INPUT!$J$6:$J$9, O6, MATCH_INPUT!$K$6:$K$9, "<>"&O6, MATCH_INPUT!$K$6:$K$9, "<>Draw", MATCH_INPUT!$K$6:$K$9, "<>"""), 0) -> 0 | Y6: =RANK(P6, P$3:P$38, 0) -> 10 | Z6: =IF(Y6<M6, "↑", IF(Y6>M6, "↓", "=")) -> ↑ | AA6: BLUE | AB6: =SUM(AC6:AD6)+P6+AI6 -> 13 | AC6: =COUNTA(AA6)*2 -> 2 | AD6: =SUM(AE6*2)+(AF6*1) -> 2 | AE6: =IF(AA6<>"", COUNTIFS(MATCH_INPUT!$K$10:$K$13,AA6), 0) -> 0 | AF6: =IF(AA6<>"", COUNTIFS(MATCH_INPUT!$F$10:$F$13, AA6, MATCH_INPUT!$K$10:$K$13, "Draw") + COUNTIFS(MATCH_INPUT!$J$10:$J$13, AA6, MATCH_INPUT!$K$10:$K$13, "Draw"), 0) -> 2 | AG6: =IF(AA6<>"", COUNTIFS(MATCH_INPUT!$F$10:$F$13, AA6, MATCH_INPUT!$K$10:$K$13, "<>"&AA6, MATCH_INPUT!$K$10:$K$13, "<>Draw", MATCH_INPUT!$K$10:$K$13, "<>""") + COUNTIFS(MATCH_INPUT!$J$10:$J$13, AA6, MATCH_INPUT!$K$10:$K$13, "<>"&AA6, MATCH_INPUT!$K$10:$K$13, "<>Draw", MATCH_INPUT!$K$10:$K$13, "<>"""), 0) -> 0 | AK6: =RANK(AB6, AB$3:AB$38, 0) -> 9 | AL6: =IF(AK6<Y6, "↑", IF(AK6>Y6, "↓", "=")) -> ↑ | AM6: BLUE | AN6: =SUM(AO6:AP6)+AB6+AU6 -> 16 | AO6: =COUNTA(AM6)*2 -> 2 | AP6: =SUM(AQ6*2)+(AR6*1) -> 1 | AQ6: =IF(AM6<>"", COUNTIFS(MATCH_INPUT!$K$14:$K$17,AM6), 0) -> 0 | AR6: =IF(AM6<>"", COUNTIFS(MATCH_INPUT!$F$14:$F$17, AM6, MATCH_INPUT!$K$14:$K$17, "Draw") + COUNTIFS(MATCH_INPUT!$J$14:$J$17, AM6, MATCH_INPUT!$K$14:$K$17, "Draw"), 0) -> 1 | AS6: =IF(AM6<>"", COUNTIFS(MATCH_INPUT!$F$14:$F$17, AM6, MATCH_INPUT!$K$14:$K$17, "<>"&AM6, MATCH_INPUT!$K$14:$K$17, "<>Draw", MATCH_INPUT!$K$14:$K$17, "<>""") + COUNTIFS(MATCH_INPUT!$J$14:$J$17, AM6, MATCH_INPUT!$K$14:$K$17, "<>"&AM6, MATCH_INPUT!$K$14:$K$17, "<>Draw", MATCH_INPUT!$K$14:$K$17, "<>"""), 0) -> 1 | AW6: =RANK(AN6, AN$3:AN$38, 0) -> 15 | AX6: =IF(AW6<AK6, "↑", IF(AW6>AK6, "↓", "=")) -> ↓ | AY6: ORANGE | AZ6: =SUM(BA6:BB6)+BG6+AN6 -> 28 | BA6: =COUNTA(AY6)*2 -> 2 | BB6: =SUM(BC6*2) + (BD6*1) + SUMIFS(MATCH_INPUT!$G$18:$G$21, MATCH_INPUT!$F$18:$F$21, AY6) + SUMIFS(MATCH_INPUT!$I$18:$I$21, MATCH_INPUT!$J$18:$J$21, AY6) -> 10 | BC6: =IF(AY6<>"", COUNTIFS(MATCH_INPUT!$K$18:$K$21,AY6), 0) -> 2 | BD6: =IF(AY6<>"", COUNTIFS(MATCH_INPUT!$F$18:$F$21, AY6, MATCH_INPUT!$K$18:$K$21, "Draw") + COUNTIFS(MATCH_INPUT!$J$18:$J$21, AY6, MATCH_INPUT!$K$18:$K$21, "Draw"), 0) -> 0 | BE6: =IF(AY6<>"", COUNTIFS(MATCH_INPUT!$F$18:$F$21, AY6, MATCH_INPUT!$K$18:$K$21, "<>"&AY6, MATCH_INPUT!$K$18:$K$21, "<>Draw", MATCH_INPUT!$K$18:$K$21, "<>""") + COUNTIFS(MATCH_INPUT!$J$18:$J$21, AY6, MATCH_INPUT!$K$18:$K$21, "<>"&AY6, MATCH_INPUT!$K$18:$K$21, "<>Draw", MATCH_INPUT!$K$18:$K$21, "<>"""), 0) -> 0 | BI6: =RANK(AZ6, AZ$3:AZ$38, 0) -> 4 | BJ6: =IF(BI6<AW6, "↑", IF(BI6>AW6, "↓", "=")) -> ↑ | BK6: BLUE | BL6: =SUM(BM6:BN6)+BS6+AZ6 -> 36 | BM6: =COUNTA(BK6)*2 -> 2 | BN6: =SUM(BO6*2) + (BP6*1) + SUMIFS(MATCH_INPUT!$G$22:$G$25, MATCH_INPUT!$F$22:$F$25, BK6) + SUMIFS(MATCH_INPUT!$I$22:$I$25, MATCH_INPUT!$J$22:$J$25, BK6) -> 6 | BO6: =IF(BK6<>"", COUNTIFS(MATCH_INPUT!$K$22:$K$25,BK6), 0) -> 1 | BP6: =IF(BK6<>"", COUNTIFS(MATCH_INPUT!$F$22:$F$25, BK6, MATCH_INPUT!$K$22:$K$25, "Draw") + COUNTIFS(MATCH_INPUT!$J$22:$J$25, BK6, MATCH_INPUT!$K$22:$K$25, "Draw"), 0) -> 1 | BQ6: =IF(BK6<>"", COUNTIFS(MATCH_INPUT!$F$22:$F$25, BK6, MATCH_INPUT!$K$22:$K$25, "<>"&BK6, MATCH_INPUT!$K$22:$K$25, "<>Draw", MATCH_INPUT!$K$22:$K$25, "<>""") + COUNTIFS(MATCH_INPUT!$J$22:$J$25, BK6, MATCH_INPUT!$K$22:$K$25, "<>"&BK6, MATCH_INPUT!$K$22:$K$25, "<>Draw", MATCH_INPUT!$K$22:$K$25, "<>"""), 0) -> 0 | BU6: =RANK(BL6, BL$3:BL$38, 0) -> 3 | BV6: =IF(BU6<BI6, "↑", IF(BU6>BI6, "↓", "=")) -> ↑ | BW6: ORANGE | BX6: =SUM(BY6:BZ6)+CE6+BL6 -> 45 | BY6: =COUNTA(BW6)*2 -> 2 | BZ6: =SUM(CA6*2)+(CB6*1) + SUMIFS(MATCH_INPUT!$G$26:$G$29, MATCH_INPUT!$F$26:$F$29, BW6) + SUMIFS(MATCH_INPUT!$I$26:$I$29, MATCH_INPUT!$J$26:$J$29, BW6) -> 7 | CA6: =IF(BW6<>"", COUNTIFS(MATCH_INPUT!$K$26:$K$29,BW6), 0) -> 1 | CB6: =IF(BW6<>"", COUNTIFS(MATCH_INPUT!$F$26:$F$29, BW6, MATCH_INPUT!$K$26:$K$29, "Draw") + COUNTIFS(MATCH_INPUT!$J$26:$J$29, BW6, MATCH_INPUT!$K$26:$K$29, "Draw"), 0) -> 1 | CC6: =IF(BW6<>"", COUNTIFS(MATCH_INPUT!$F$26:$F$29, BW6, MATCH_INPUT!$K$26:$K$29, "<>"&BW6, MATCH_INPUT!$K$26:$K$29, "<>Draw", MATCH_INPUT!$K$26:$K$29, "<>""") + COUNTIFS(MATCH_INPUT!$J$26:$J$29, BW6, MATCH_INPUT!$K$26:$K$29, "<>"&BW6, MATCH_INPUT!$K$26:$K$29, "<>Draw", MATCH_INPUT!$K$26:$K$29, "<>"""), 0) -> 0 | CG6: =RANK(BX6, BX$3:BX$38, 0) -> 1 | CH6: =IF(CG6<BU6, "↑", IF(CG6>BU6, "↓", "=")) -> ↑ | CJ6: =SUM(CK6:CL6)+CQ6+BX6 -> 45 | CK6: =COUNTA(CI6)*2 -> 0 | CL6: =SUM(CM6*2)+(CN6*1) + SUMIFS(MATCH_INPUT!$G$30:$G$33, MATCH_INPUT!$F$30:$F$33, CI6) + SUMIFS(MATCH_INPUT!$I$30:$I$33, MATCH_INPUT!$J$30:$J$33, CI6) -> 0 | CM6: =IF(CI6<>"", COUNTIFS(MATCH_INPUT!$K$30:$K$33,CI6), 0) -> 0 | CN6: =IF(CI6<>"", COUNTIFS(MATCH_INPUT!$F$30:$F$33, CI6, MATCH_INPUT!$K$30:$K$33, "Draw") + COUNTIFS(MATCH_INPUT!$J$30:$J$33, CI6, MATCH_INPUT!$K$30:$K$33, "Draw"), 0) -> 0 | CO6: =IF(CI6<>"", COUNTIFS(MATCH_INPUT!$F$30:$F$33, CI6, MATCH_INPUT!$K$30:$K$33, "<>"&CI6, MATCH_INPUT!$K$30:$K$33, "<>Draw", MATCH_INPUT!$K$30:$K$33, "<>""") + COUNTIFS(MATCH_INPUT!$J$30:$J$33, CI6, MATCH_INPUT!$K$30:$K$33, "<>"&CI6, MATCH_INPUT!$K$30:$K$33, "<>Draw", MATCH_INPUT!$K$30:$K$33, "<>"""), 0) -> 0 | CS6: =RANK(CJ6, CJ$3:CJ$38, 0) -> 4 | CT6: =IF(CS6<CG6, "↑", IF(CS6>CG6, "↓", "=")) -> ↓ | CU6: =SUM(F6,R6,AD6,AP6,BB6,BN6,BZ6,CL6) -> 31 | CV6: =A6 -> 🍀 | CW6: =B6 -> Mikey | CX6: =SUM(CU6,CY6,DD6) -> 45 | CY6: =SUM( IF(AND('MATCH DATES'!$A$2 <= TODAY(), NOW() >= 'MATCH DATES'!$A$2 + TIME(22, 0, 0)), E6, 0), IF(AND('MATCH DATES'!$A$3 <= TODAY(), NOW() >= 'MATCH DATES'!$A$3 + TIME(22, 0, 0)), Q6, 0), IF(AND('MATCH DATES'!$A$4 <= TODAY(), NOW() >= 'MATCH DATES'!$A$4 + TIME(22, 0, 0)), AC6, 0), IF(AND('MATCH DATES'!$A$5 <= TODAY(), NOW() >= 'MATCH DATES'!$A$5 + TIME(22, 0, 0)), AO6, 0), IF(AND('MATCH DATES'!$A$6 <= TODAY(), NOW() >= 'MATCH DATES'!$A$6 + TIME(22, 0, 0)), BA6, 0), IF(AND('MATCH DATES'!$A$7 <= TODAY(), NOW() >= 'MATCH DATES'!$A$7 + TIME(22, 0, 0)), BM6, 0), IF(AND('MATCH DATES'!$A$8 <= TODAY(), NOW() >= 'MATCH DATES'!$A$8 + TIME(22, 0, 0)), BY6, 0), IF(AND('MATCH DATES'!$A$9 <= TODAY(), NOW() >= 'MATCH DATES'!$A$9 + TIME(22, 0, 0)), CK6, 0) ) -> 14 | CZ6: =SUM(G6,S6,AE6,AQ6,BC6,BO6,CA6,CM6) -> 6 | DA6: =SUM(H6,T6,AF6,AR6,BD6,BP6,CB6,CN6) -> 6 | DB6: =SUM( IF(AND('MATCH DATES'!$A$2 <= TODAY(), NOW() >= 'MATCH DATES'!$A$2 + TIME(22, 0, 0)), I6, 0), IF(AND('MATCH DATES'!$A$3 <= TODAY(), NOW() >= 'MATCH DATES'!$A$3 + TIME(22, 0, 0)), U6, 0), IF(AND('MATCH DATES'!$A$4 <= TODAY(), NOW() >= 'MATCH DATES'!$A$4 + TIME(22, 0, 0)), AG6, 0), IF(AND('MATCH DATES'!$A$5 <= TODAY(), NOW() >= 'MATCH DATES'!$A$5 + TIME(22, 0, 0)), AS6, 0), IF(AND('MATCH DATES'!$A$6 <= TODAY(), NOW() >= 'MATCH DATES'!$A$6 + TIME(22, 0, 0)), BE6, 0), IF(AND('MATCH DATES'!$A$7 <= TODAY(), NOW() >= 'MATCH DATES'!$A$7 + TIME(22, 0, 0)), BQ6, 0), IF(AND('MATCH DATES'!$A$8 <= TODAY(), NOW() >= 'MATCH DATES'!$A$8 + TIME(22, 0, 0)), CC6, 0), IF(AND('MATCH DATES'!$A$9 <= TODAY(), NOW() >= 'MATCH DATES'!$A$9 + TIME(22, 0, 0)), CO6, 0) ) -> 2 | DD6: =SUM(K6,W6,AI6,AU6,BG6,BS6,CE6,CQ6) -> 0 | DF6: =SUM(L6,X6,AJ6,AV6,BH6,BT6,CF6,CR6) -> 0
A7: 🍀 | B7: Jose Blanco | C7: GREEN | D7: =SUM(E7:F7)+K7 -> 2 | E7: =COUNTA(C7)*2 -> 2 | F7: =(G7*2)+(H7*1) -> 0 | G7: =IF(C7<>"", COUNTIFS(MATCH_INPUT!$K$2:$K$5,C7), 0) -> 0 | H7: =IF(C7<>"", COUNTIFS(MATCH_INPUT!$F$2:$F$5, C7, MATCH_INPUT!$K$2:$K$5, "Draw") + COUNTIFS(MATCH_INPUT!$J$2:$J$5, C7, MATCH_INPUT!$K$2:$K$5, "Draw"), 0) -> 0 | I7: =IF(C7<>"", COUNTIFS(MATCH_INPUT!$F$2:$F$5, C7, MATCH_INPUT!$K$2:$K$5, "<>"&C7, MATCH_INPUT!$K$2:$K$5, "<>Draw", MATCH_INPUT!$K$2:$K$5, "<>""") + COUNTIFS(MATCH_INPUT!$J$2:$J$5, C7, MATCH_INPUT!$K$2:$K$5, "<>"&C7, MATCH_INPUT!$K$2:$K$5, "<>Draw", MATCH_INPUT!$K$2:$K$5, "<>"""), 0) -> 2 | J7: 1 | M7: =RANK(D7, D$3:D$38, 0) -> 26 | N7: =IF(M7<1, "↑", IF(M7>1, "↓", "=")) -> ↓ | O7: BLUE | P7: =SUM(Q7:R7)+D7+W7 -> 7 | Q7: =COUNTA(O7)*2 -> 2 | R7: =(S7*2)+(T7*1) -> 3 | S7: =IF(O7<>"", COUNTIFS(MATCH_INPUT!$K$6:$K$9,O7), 0) -> 1 | T7: =IF(O7<>"", COUNTIFS(MATCH_INPUT!$F$6:$F$9, O7, MATCH_INPUT!$K$6:$K$9, "Draw") + COUNTIFS(MATCH_INPUT!$J$6:$J$9, O7, MATCH_INPUT!$K$6:$K$9, "Draw"), 0) -> 1 | U7: =IF(O7<>"", COUNTIFS(MATCH_INPUT!$F$6:$F$9, O7, MATCH_INPUT!$K$6:$K$9, "<>"&O7, MATCH_INPUT!$K$6:$K$9, "<>Draw", MATCH_INPUT!$K$6:$K$9, "<>""") + COUNTIFS(MATCH_INPUT!$J$6:$J$9, O7, MATCH_INPUT!$K$6:$K$9, "<>"&O7, MATCH_INPUT!$K$6:$K$9, "<>Draw", MATCH_INPUT!$K$6:$K$9, "<>"""), 0) -> 0 | V7: 1 | Y7: =RANK(P7, P$3:P$38, 0) -> 20 | Z7: =IF(Y7<M7, "↑", IF(Y7>M7, "↓", "=")) -> ↑ | AA7: ORANGE | AB7: =SUM(AC7:AD7)+P7+AI7 -> 12 | AC7: =COUNTA(AA7)*2 -> 2 | AD7: =SUM(AE7*2)+(AF7*1) -> 3 | AE7: =IF(AA7<>"", COUNTIFS(MATCH_INPUT!$K$10:$K$13,AA7), 0) -> 1 | AF7: =IF(AA7<>"", COUNTIFS(MATCH_INPUT!$F$10:$F$13, AA7, MATCH_INPUT!$K$10:$K$13, "Draw") + COUNTIFS(MATCH_INPUT!$J$10:$J$13, AA7, MATCH_INPUT!$K$10:$K$13, "Draw"), 0) -> 1 | AG7: =IF(AA7<>"", COUNTIFS(MATCH_INPUT!$F$10:$F$13, AA7, MATCH_INPUT!$K$10:$K$13, "<>"&AA7, MATCH_INPUT!$K$10:$K$13, "<>Draw", MATCH_INPUT!$K$10:$K$13, "<>""") + COUNTIFS(MATCH_INPUT!$J$10:$J$13, AA7, MATCH_INPUT!$K$10:$K$13, "<>"&AA7, MATCH_INPUT!$K$10:$K$13, "<>Draw", MATCH_INPUT!$K$10:$K$13, "<>"""), 0) -> 0 | AH7: 2 | AK7: =RANK(AB7, AB$3:AB$38, 0) -> 17 | AL7: =IF(AK7<Y7, "↑", IF(AK7>Y7, "↓", "=")) -> ↑ | AM7: BLUE | AN7: =SUM(AO7:AP7)+AB7+AU7 -> 15 | AO7: =COUNTA(AM7)*2 -> 2 | AP7: =SUM(AQ7*2)+(AR7*1) -> 1 | AQ7: =IF(AM7<>"", COUNTIFS(MATCH_INPUT!$K$14:$K$17,AM7), 0) -> 0 | AR7: =IF(AM7<>"", COUNTIFS(MATCH_INPUT!$F$14:$F$17, AM7, MATCH_INPUT!$K$14:$K$17, "Draw") + COUNTIFS(MATCH_INPUT!$J$14:$J$17, AM7, MATCH_INPUT!$K$14:$K$17, "Draw"), 0) -> 1 | AS7: =IF(AM7<>"", COUNTIFS(MATCH_INPUT!$F$14:$F$17, AM7, MATCH_INPUT!$K$14:$K$17, "<>"&AM7, MATCH_INPUT!$K$14:$K$17, "<>Draw", MATCH_INPUT!$K$14:$K$17, "<>""") + COUNTIFS(MATCH_INPUT!$J$14:$J$17, AM7, MATCH_INPUT!$K$14:$K$17, "<>"&AM7, MATCH_INPUT!$K$14:$K$17, "<>Draw", MATCH_INPUT!$K$14:$K$17, "<>"""), 0) -> 1 | AW7: =RANK(AN7, AN$3:AN$38, 0) -> 19 | AX7: =IF(AW7<AK7, "↑", IF(AW7>AK7, "↓", "=")) -> ↓ | AY7: MAGENTA | AZ7: =SUM(BA7:BB7)+BG7+AN7 -> 21 | BA7: =COUNTA(AY7)*2 -> 2 | BB7: =SUM(BC7*2) + (BD7*1) + SUMIFS(MATCH_INPUT!$G$18:$G$21, MATCH_INPUT!$F$18:$F$21, AY7) + SUMIFS(MATCH_INPUT!$I$18:$I$21, MATCH_INPUT!$J$18:$J$21, AY7) -> 4 | BC7: =IF(AY7<>"", COUNTIFS(MATCH_INPUT!$K$18:$K$21,AY7), 0) -> 0 | BD7: =IF(AY7<>"", COUNTIFS(MATCH_INPUT!$F$18:$F$21, AY7, MATCH_INPUT!$K$18:$K$21, "Draw") + COUNTIFS(MATCH_INPUT!$J$18:$J$21, AY7, MATCH_INPUT!$K$18:$K$21, "Draw"), 0) -> 1 | BE7: =IF(AY7<>"", COUNTIFS(MATCH_INPUT!$F$18:$F$21, AY7, MATCH_INPUT!$K$18:$K$21, "<>"&AY7, MATCH_INPUT!$K$18:$K$21, "<>Draw", MATCH_INPUT!$K$18:$K$21, "<>""") + COUNTIFS(MATCH_INPUT!$J$18:$J$21, AY7, MATCH_INPUT!$K$18:$K$21, "<>"&AY7, MATCH_INPUT!$K$18:$K$21, "<>Draw", MATCH_INPUT!$K$18:$K$21, "<>"""), 0) -> 1 | BF7: 1 | BI7: =RANK(AZ7, AZ$3:AZ$38, 0) -> 20 | BJ7: =IF(BI7<AW7, "↑", IF(BI7>AW7, "↓", "=")) -> ↓ | BK7: BLUE | BL7: =SUM(BM7:BN7)+BS7+AZ7 -> 29 | BM7: =COUNTA(BK7)*2 -> 2 | BN7: =SUM(BO7*2) + (BP7*1) + SUMIFS(MATCH_INPUT!$G$22:$G$25, MATCH_INPUT!$F$22:$F$25, BK7) + SUMIFS(MATCH_INPUT!$I$22:$I$25, MATCH_INPUT!$J$22:$J$25, BK7) -> 6 | BO7: =IF(BK7<>"", COUNTIFS(MATCH_INPUT!$K$22:$K$25,BK7), 0) -> 1 | BP7: =IF(BK7<>"", COUNTIFS(MATCH_INPUT!$F$22:$F$25, BK7, MATCH_INPUT!$K$22:$K$25, "Draw") + COUNTIFS(MATCH_INPUT!$J$22:$J$25, BK7, MATCH_INPUT!$K$22:$K$25, "Draw"), 0) -> 1 | BQ7: =IF(BK7<>"", COUNTIFS(MATCH_INPUT!$F$22:$F$25, BK7, MATCH_INPUT!$K$22:$K$25, "<>"&BK7, MATCH_INPUT!$K$22:$K$25, "<>Draw", MATCH_INPUT!$K$22:$K$25, "<>""") + COUNTIFS(MATCH_INPUT!$J$22:$J$25, BK7, MATCH_INPUT!$K$22:$K$25, "<>"&BK7, MATCH_INPUT!$K$22:$K$25, "<>Draw", MATCH_INPUT!$K$22:$K$25, "<>"""), 0) -> 0 | BU7: =RANK(BL7, BL$3:BL$38, 0) -> 11 | BV7: =IF(BU7<BI7, "↑", IF(BU7>BI7, "↓", "=")) -> ↑ | BW7: ORANGE | BX7: =SUM(BY7:BZ7)+CE7+BL7 -> 38 | BY7: =COUNTA(BW7)*2 -> 2 | BZ7: =SUM(CA7*2)+(CB7*1) + SUMIFS(MATCH_INPUT!$G$26:$G$29, MATCH_INPUT!$F$26:$F$29, BW7) + SUMIFS(MATCH_INPUT!$I$26:$I$29, MATCH_INPUT!$J$26:$J$29, BW7) -> 7 | CA7: =IF(BW7<>"", COUNTIFS(MATCH_INPUT!$K$26:$K$29,BW7), 0) -> 1 | CB7: =IF(BW7<>"", COUNTIFS(MATCH_INPUT!$F$26:$F$29, BW7, MATCH_INPUT!$K$26:$K$29, "Draw") + COUNTIFS(MATCH_INPUT!$J$26:$J$29, BW7, MATCH_INPUT!$K$26:$K$29, "Draw"), 0) -> 1 | CC7: =IF(BW7<>"", COUNTIFS(MATCH_INPUT!$F$26:$F$29, BW7, MATCH_INPUT!$K$26:$K$29, "<>"&BW7, MATCH_INPUT!$K$26:$K$29, "<>Draw", MATCH_INPUT!$K$26:$K$29, "<>""") + COUNTIFS(MATCH_INPUT!$J$26:$J$29, BW7, MATCH_INPUT!$K$26:$K$29, "<>"&BW7, MATCH_INPUT!$K$26:$K$29, "<>Draw", MATCH_INPUT!$K$26:$K$29, "<>"""), 0) -> 0 | CD7: 1 | CG7: =RANK(BX7, BX$3:BX$38, 0) -> 6 | CH7: =IF(CG7<BU7, "↑", IF(CG7>BU7, "↓", "=")) -> ↑ | CI7: GREEN | CJ7: =SUM(CK7:CL7)+CQ7+BX7 -> 44 | CK7: =COUNTA(CI7)*2 -> 2 | CL7: =SUM(CM7*2)+(CN7*1) + SUMIFS(MATCH_INPUT!$G$30:$G$33, MATCH_INPUT!$F$30:$F$33, CI7) + SUMIFS(MATCH_INPUT!$I$30:$I$33, MATCH_INPUT!$J$30:$J$33, CI7) -> 4 | CM7: =IF(CI7<>"", COUNTIFS(MATCH_INPUT!$K$30:$K$33,CI7), 0) -> 1 | CN7: =IF(CI7<>"", COUNTIFS(MATCH_INPUT!$F$30:$F$33, CI7, MATCH_INPUT!$K$30:$K$33, "Draw") + COUNTIFS(MATCH_INPUT!$J$30:$J$33, CI7, MATCH_INPUT!$K$30:$K$33, "Draw"), 0) -> 0 | CO7: =IF(CI7<>"", COUNTIFS(MATCH_INPUT!$F$30:$F$33, CI7, MATCH_INPUT!$K$30:$K$33, "<>"&CI7, MATCH_INPUT!$K$30:$K$33, "<>Draw", MATCH_INPUT!$K$30:$K$33, "<>""") + COUNTIFS(MATCH_INPUT!$J$30:$J$33, CI7, MATCH_INPUT!$K$30:$K$33, "<>"&CI7, MATCH_INPUT!$K$30:$K$33, "<>Draw", MATCH_INPUT!$K$30:$K$33, "<>"""), 0) -> 1 | CS7: =RANK(CJ7, CJ$3:CJ$38, 0) -> 5 | CT7: =IF(CS7<CG7, "↑", IF(CS7>CG7, "↓", "=")) -> ↑ | CU7: =SUM(F7,R7,AD7,AP7,BB7,BN7,BZ7,CL7) -> 28 | CV7: =A7 -> 🍀 | CW7: =B7 -> Jose Blanco | CX7: =SUM(CU7,CY7,DD7) -> 44 | CY7: =SUM( IF(AND('MATCH DATES'!$A$2 <= TODAY(), NOW() >= 'MATCH DATES'!$A$2 + TIME(22, 0, 0)), E7, 0), IF(AND('MATCH DATES'!$A$3 <= TODAY(), NOW() >= 'MATCH DATES'!$A$3 + TIME(22, 0, 0)), Q7, 0), IF(AND('MATCH DATES'!$A$4 <= TODAY(), NOW() >= 'MATCH DATES'!$A$4 + TIME(22, 0, 0)), AC7, 0), IF(AND('MATCH DATES'!$A$5 <= TODAY(), NOW() >= 'MATCH DATES'!$A$5 + TIME(22, 0, 0)), AO7, 0), IF(AND('MATCH DATES'!$A$6 <= TODAY(), NOW() >= 'MATCH DATES'!$A$6 + TIME(22, 0, 0)), BA7, 0), IF(AND('MATCH DATES'!$A$7 <= TODAY(), NOW() >= 'MATCH DATES'!$A$7 + TIME(22, 0, 0)), BM7, 0), IF(AND('MATCH DATES'!$A$8 <= TODAY(), NOW() >= 'MATCH DATES'!$A$8 + TIME(22, 0, 0)), BY7, 0), IF(AND('MATCH DATES'!$A$9 <= TODAY(), NOW() >= 'MATCH DATES'!$A$9 + TIME(22, 0, 0)), CK7, 0) ) -> 16 | CZ7: =SUM(G7,S7,AE7,AQ7,BC7,BO7,CA7,CM7) -> 5 | DA7: =SUM(H7,T7,AF7,AR7,BD7,BP7,CB7,CN7) -> 6 | DB7: =SUM( IF(AND('MATCH DATES'!$A$2 <= TODAY(), NOW() >= 'MATCH DATES'!$A$2 + TIME(22, 0, 0)), I7, 0), IF(AND('MATCH DATES'!$A$3 <= TODAY(), NOW() >= 'MATCH DATES'!$A$3 + TIME(22, 0, 0)), U7, 0), IF(AND('MATCH DATES'!$A$4 <= TODAY(), NOW() >= 'MATCH DATES'!$A$4 + TIME(22, 0, 0)), AG7, 0), IF(AND('MATCH DATES'!$A$5 <= TODAY(), NOW() >= 'MATCH DATES'!$A$5 + TIME(22, 0, 0)), AS7, 0), IF(AND('MATCH DATES'!$A$6 <= TODAY(), NOW() >= 'MATCH DATES'!$A$6 + TIME(22, 0, 0)), BE7, 0), IF(AND('MATCH DATES'!$A$7 <= TODAY(), NOW() >= 'MATCH DATES'!$A$7 + TIME(22, 0, 0)), BQ7, 0), IF(AND('MATCH DATES'!$A$8 <= TODAY(), NOW() >= 'MATCH DATES'!$A$8 + TIME(22, 0, 0)), CC7, 0), IF(AND('MATCH DATES'!$A$9 <= TODAY(), NOW() >= 'MATCH DATES'!$A$9 + TIME(22, 0, 0)), CO7, 0) ) -> 5 | DD7: =SUM(K7,W7,AI7,AU7,BG7,BS7,CE7,CQ7) -> 0 | DF7: =SUM(L7,X7,AJ7,AV7,BH7,BT7,CF7,CR7) -> 0
A8: 🍀 | B8: Rodrigo | C8: MAGENTA | D8: =SUM(E8:F8)+K8 -> 4 | E8: =COUNTA(C8)*2 -> 2 | F8: =(G8*2)+(H8*1) -> 2 | G8: =IF(C8<>"", COUNTIFS(MATCH_INPUT!$K$2:$K$5,C8), 0) -> 1 | H8: =IF(C8<>"", COUNTIFS(MATCH_INPUT!$F$2:$F$5, C8, MATCH_INPUT!$K$2:$K$5, "Draw") + COUNTIFS(MATCH_INPUT!$J$2:$J$5, C8, MATCH_INPUT!$K$2:$K$5, "Draw"), 0) -> 0 | I8: =IF(C8<>"", COUNTIFS(MATCH_INPUT!$F$2:$F$5, C8, MATCH_INPUT!$K$2:$K$5, "<>"&C8, MATCH_INPUT!$K$2:$K$5, "<>Draw", MATCH_INPUT!$K$2:$K$5, "<>""") + COUNTIFS(MATCH_INPUT!$J$2:$J$5, C8, MATCH_INPUT!$K$2:$K$5, "<>"&C8, MATCH_INPUT!$K$2:$K$5, "<>Draw", MATCH_INPUT!$K$2:$K$5, "<>"""), 0) -> 1 | M8: =RANK(D8, D$3:D$38, 0) -> 11 | N8: =IF(M8<1, "↑", IF(M8>1, "↓", "=")) -> ↓ | O8: MAGENTA | P8: =SUM(Q8:R8)+D8+W8 -> 7 | Q8: =COUNTA(O8)*2 -> 2 | R8: =(S8*2)+(T8*1) -> 1 | S8: =IF(O8<>"", COUNTIFS(MATCH_INPUT!$K$6:$K$9,O8), 0) -> 0 | T8: =IF(O8<>"", COUNTIFS(MATCH_INPUT!$F$6:$F$9, O8, MATCH_INPUT!$K$6:$K$9, "Draw") + COUNTIFS(MATCH_INPUT!$J$6:$J$9, O8, MATCH_INPUT!$K$6:$K$9, "Draw"), 0) -> 1 | U8: =IF(O8<>"", COUNTIFS(MATCH_INPUT!$F$6:$F$9, O8, MATCH_INPUT!$K$6:$K$9, "<>"&O8, MATCH_INPUT!$K$6:$K$9, "<>Draw", MATCH_INPUT!$K$6:$K$9, "<>""") + COUNTIFS(MATCH_INPUT!$J$6:$J$9, O8, MATCH_INPUT!$K$6:$K$9, "<>"&O8, MATCH_INPUT!$K$6:$K$9, "<>Draw", MATCH_INPUT!$K$6:$K$9, "<>"""), 0) -> 1 | Y8: =RANK(P8, P$3:P$38, 0) -> 20 | Z8: =IF(Y8<M8, "↑", IF(Y8>M8, "↓", "=")) -> ↓ | AA8: ORANGE | AB8: =SUM(AC8:AD8)+P8+AI8 -> 12 | AC8: =COUNTA(AA8)*2 -> 2 | AD8: =SUM(AE8*2)+(AF8*1) -> 3 | AE8: =IF(AA8<>"", COUNTIFS(MATCH_INPUT!$K$10:$K$13,AA8), 0) -> 1 | AF8: =IF(AA8<>"", COUNTIFS(MATCH_INPUT!$F$10:$F$13, AA8, MATCH_INPUT!$K$10:$K$13, "Draw") + COUNTIFS(MATCH_INPUT!$J$10:$J$13, AA8, MATCH_INPUT!$K$10:$K$13, "Draw"), 0) -> 1 | AG8: =IF(AA8<>"", COUNTIFS(MATCH_INPUT!$F$10:$F$13, AA8, MATCH_INPUT!$K$10:$K$13, "<>"&AA8, MATCH_INPUT!$K$10:$K$13, "<>Draw", MATCH_INPUT!$K$10:$K$13, "<>""") + COUNTIFS(MATCH_INPUT!$J$10:$J$13, AA8, MATCH_INPUT!$K$10:$K$13, "<>"&AA8, MATCH_INPUT!$K$10:$K$13, "<>Draw", MATCH_INPUT!$K$10:$K$13, "<>"""), 0) -> 0 | AK8: =RANK(AB8, AB$3:AB$38, 0) -> 17 | AL8: =IF(AK8<Y8, "↑", IF(AK8>Y8, "↓", "=")) -> ↑ | AM8: BLUE | AN8: =SUM(AO8:AP8)+AB8+AU8 -> 15 | AO8: =COUNTA(AM8)*2 -> 2 | AP8: =SUM(AQ8*2)+(AR8*1) -> 1 | AQ8: =IF(AM8<>"", COUNTIFS(MATCH_INPUT!$K$14:$K$17,AM8), 0) -> 0 | AR8: =IF(AM8<>"", COUNTIFS(MATCH_INPUT!$F$14:$F$17, AM8, MATCH_INPUT!$K$14:$K$17, "Draw") + COUNTIFS(MATCH_INPUT!$J$14:$J$17, AM8, MATCH_INPUT!$K$14:$K$17, "Draw"), 0) -> 1 | AS8: =IF(AM8<>"", COUNTIFS(MATCH_INPUT!$F$14:$F$17, AM8, MATCH_INPUT!$K$14:$K$17, "<>"&AM8, MATCH_INPUT!$K$14:$K$17, "<>Draw", MATCH_INPUT!$K$14:$K$17, "<>""") + COUNTIFS(MATCH_INPUT!$J$14:$J$17, AM8, MATCH_INPUT!$K$14:$K$17, "<>"&AM8, MATCH_INPUT!$K$14:$K$17, "<>Draw", MATCH_INPUT!$K$14:$K$17, "<>"""), 0) -> 1 | AW8: =RANK(AN8, AN$3:AN$38, 0) -> 19 | AX8: =IF(AW8<AK8, "↑", IF(AW8>AK8, "↓", "=")) -> ↓ | AY8: GREEN | AZ8: =SUM(BA8:BB8)+BG8+AN8 -> 22 | BA8: =COUNTA(AY8)*2 -> 2 | BB8: =SUM(BC8*2) + (BD8*1) + SUMIFS(MATCH_INPUT!$G$18:$G$21, MATCH_INPUT!$F$18:$F$21, AY8) + SUMIFS(MATCH_INPUT!$I$18:$I$21, MATCH_INPUT!$J$18:$J$21, AY8) -> 5 | BC8: =IF(AY8<>"", COUNTIFS(MATCH_INPUT!$K$18:$K$21,AY8), 0) -> 1 | BD8: =IF(AY8<>"", COUNTIFS(MATCH_INPUT!$F$18:$F$21, AY8, MATCH_INPUT!$K$18:$K$21, "Draw") + COUNTIFS(MATCH_INPUT!$J$18:$J$21, AY8, MATCH_INPUT!$K$18:$K$21, "Draw"), 0) -> 0 | BE8: =IF(AY8<>"", COUNTIFS(MATCH_INPUT!$F$18:$F$21, AY8, MATCH_INPUT!$K$18:$K$21, "<>"&AY8, MATCH_INPUT!$K$18:$K$21, "<>Draw", MATCH_INPUT!$K$18:$K$21, "<>""") + COUNTIFS(MATCH_INPUT!$J$18:$J$21, AY8, MATCH_INPUT!$K$18:$K$21, "<>"&AY8, MATCH_INPUT!$K$18:$K$21, "<>Draw", MATCH_INPUT!$K$18:$K$21, "<>"""), 0) -> 1 | BI8: =RANK(AZ8, AZ$3:AZ$38, 0) -> 17 | BJ8: =IF(BI8<AW8, "↑", IF(BI8>AW8, "↓", "=")) -> ↑ | BK8: MAGENTA | BL8: =SUM(BM8:BN8)+BS8+AZ8 -> 28 | BM8: =COUNTA(BK8)*2 -> 2 | BN8: =SUM(BO8*2) + (BP8*1) + SUMIFS(MATCH_INPUT!$G$22:$G$25, MATCH_INPUT!$F$22:$F$25, BK8) + SUMIFS(MATCH_INPUT!$I$22:$I$25, MATCH_INPUT!$J$22:$J$25, BK8) -> 4 | BO8: =IF(BK8<>"", COUNTIFS(MATCH_INPUT!$K$22:$K$25,BK8), 0) -> 0 | BP8: =IF(BK8<>"", COUNTIFS(MATCH_INPUT!$F$22:$F$25, BK8, MATCH_INPUT!$K$22:$K$25, "Draw") + COUNTIFS(MATCH_INPUT!$J$22:$J$25, BK8, MATCH_INPUT!$K$22:$K$25, "Draw"), 0) -> 2 | BQ8: =IF(BK8<>"", COUNTIFS(MATCH_INPUT!$F$22:$F$25, BK8, MATCH_INPUT!$K$22:$K$25, "<>"&BK8, MATCH_INPUT!$K$22:$K$25, "<>Draw", MATCH_INPUT!$K$22:$K$25, "<>""") + COUNTIFS(MATCH_INPUT!$J$22:$J$25, BK8, MATCH_INPUT!$K$22:$K$25, "<>"&BK8, MATCH_INPUT!$K$22:$K$25, "<>Draw", MATCH_INPUT!$K$22:$K$25, "<>"""), 0) -> 0 | BU8: =RANK(BL8, BL$3:BL$38, 0) -> 15 | BV8: =IF(BU8<BI8, "↑", IF(BU8>BI8, "↓", "=")) -> ↑ | BW8: MAGENTA | BX8: =SUM(BY8:BZ8)+CE8+BL8 -> 33 | BY8: =COUNTA(BW8)*2 -> 2 | BZ8: =SUM(CA8*2)+(CB8*1) + SUMIFS(MATCH_INPUT!$G$26:$G$29, MATCH_INPUT!$F$26:$F$29, BW8) + SUMIFS(MATCH_INPUT!$I$26:$I$29, MATCH_INPUT!$J$26:$J$29, BW8) -> 3 | CA8: =IF(BW8<>"", COUNTIFS(MATCH_INPUT!$K$26:$K$29,BW8), 0) -> 0 | CB8: =IF(BW8<>"", COUNTIFS(MATCH_INPUT!$F$26:$F$29, BW8, MATCH_INPUT!$K$26:$K$29, "Draw") + COUNTIFS(MATCH_INPUT!$J$26:$J$29, BW8, MATCH_INPUT!$K$26:$K$29, "Draw"), 0) -> 1 | CC8: =IF(BW8<>"", COUNTIFS(MATCH_INPUT!$F$26:$F$29, BW8, MATCH_INPUT!$K$26:$K$29, "<>"&BW8, MATCH_INPUT!$K$26:$K$29, "<>Draw", MATCH_INPUT!$K$26:$K$29, "<>""") + COUNTIFS(MATCH_INPUT!$J$26:$J$29, BW8, MATCH_INPUT!$K$26:$K$29, "<>"&BW8, MATCH_INPUT!$K$26:$K$29, "<>Draw", MATCH_INPUT!$K$26:$K$29, "<>"""), 0) -> 1 | CG8: =RANK(BX8, BX$3:BX$38, 0) -> 19 | CH8: =IF(CG8<BU8, "↑", IF(CG8>BU8, "↓", "=")) -> ↓ | CI8: ORANGE | CJ8: =SUM(CK8:CL8)+CQ8+BX8 -> 42 | CK8: =COUNTA(CI8)*2 -> 2 | CL8: =SUM(CM8*2)+(CN8*1) + SUMIFS(MATCH_INPUT!$G$30:$G$33, MATCH_INPUT!$F$30:$F$33, CI8) + SUMIFS(MATCH_INPUT!$I$30:$I$33, MATCH_INPUT!$J$30:$J$33, CI8) -> 7 | CM8: =IF(CI8<>"", COUNTIFS(MATCH_INPUT!$K$30:$K$33,CI8), 0) -> 2 | CN8: =IF(CI8<>"", COUNTIFS(MATCH_INPUT!$F$30:$F$33, CI8, MATCH_INPUT!$K$30:$K$33, "Draw") + COUNTIFS(MATCH_INPUT!$J$30:$J$33, CI8, MATCH_INPUT!$K$30:$K$33, "Draw"), 0) -> 0 | CO8: =IF(CI8<>"", COUNTIFS(MATCH_INPUT!$F$30:$F$33, CI8, MATCH_INPUT!$K$30:$K$33, "<>"&CI8, MATCH_INPUT!$K$30:$K$33, "<>Draw", MATCH_INPUT!$K$30:$K$33, "<>""") + COUNTIFS(MATCH_INPUT!$J$30:$J$33, CI8, MATCH_INPUT!$K$30:$K$33, "<>"&CI8, MATCH_INPUT!$K$30:$K$33, "<>Draw", MATCH_INPUT!$K$30:$K$33, "<>"""), 0) -> 0 | CS8: =RANK(CJ8, CJ$3:CJ$38, 0) -> 6 | CT8: =IF(CS8<CG8, "↑", IF(CS8>CG8, "↓", "=")) -> ↑ | CU8: =SUM(F8,R8,AD8,AP8,BB8,BN8,BZ8,CL8) -> 26 | CV8: =A8 -> 🍀 | CW8: =B8 -> Rodrigo | CX8: =SUM(CU8,CY8,DD8) -> 42 | CY8: =SUM( IF(AND('MATCH DATES'!$A$2 <= TODAY(), NOW() >= 'MATCH DATES'!$A$2 + TIME(22, 0, 0)), E8, 0), IF(AND('MATCH DATES'!$A$3 <= TODAY(), NOW() >= 'MATCH DATES'!$A$3 + TIME(22, 0, 0)), Q8, 0), IF(AND('MATCH DATES'!$A$4 <= TODAY(), NOW() >= 'MATCH DATES'!$A$4 + TIME(22, 0, 0)), AC8, 0), IF(AND('MATCH DATES'!$A$5 <= TODAY(), NOW() >= 'MATCH DATES'!$A$5 + TIME(22, 0, 0)), AO8, 0), IF(AND('MATCH DATES'!$A$6 <= TODAY(), NOW() >= 'MATCH DATES'!$A$6 + TIME(22, 0, 0)), BA8, 0), IF(AND('MATCH DATES'!$A$7 <= TODAY(), NOW() >= 'MATCH DATES'!$A$7 + TIME(22, 0, 0)), BM8, 0), IF(AND('MATCH DATES'!$A$8 <= TODAY(), NOW() >= 'MATCH DATES'!$A$8 + TIME(22, 0, 0)), BY8, 0), IF(AND('MATCH DATES'!$A$9 <= TODAY(), NOW() >= 'MATCH DATES'!$A$9 + TIME(22, 0, 0)), CK8, 0) ) -> 16 | CZ8: =SUM(G8,S8,AE8,AQ8,BC8,BO8,CA8,CM8) -> 5 | DA8: =SUM(H8,T8,AF8,AR8,BD8,BP8,CB8,CN8) -> 6 | DB8: =SUM( IF(AND('MATCH DATES'!$A$2 <= TODAY(), NOW() >= 'MATCH DATES'!$A$2 + TIME(22, 0, 0)), I8, 0), IF(AND('MATCH DATES'!$A$3 <= TODAY(), NOW() >= 'MATCH DATES'!$A$3 + TIME(22, 0, 0)), U8, 0), IF(AND('MATCH DATES'!$A$4 <= TODAY(), NOW() >= 'MATCH DATES'!$A$4 + TIME(22, 0, 0)), AG8, 0), IF(AND('MATCH DATES'!$A$5 <= TODAY(), NOW() >= 'MATCH DATES'!$A$5 + TIME(22, 0, 0)), AS8, 0), IF(AND('MATCH DATES'!$A$6 <= TODAY(), NOW() >= 'MATCH DATES'!$A$6 + TIME(22, 0, 0)), BE8, 0), IF(AND('MATCH DATES'!$A$7 <= TODAY(), NOW() >= 'MATCH DATES'!$A$7 + TIME(22, 0, 0)), BQ8, 0), IF(AND('MATCH DATES'!$A$8 <= TODAY(), NOW() >= 'MATCH DATES'!$A$8 + TIME(22, 0, 0)), CC8, 0), IF(AND('MATCH DATES'!$A$9 <= TODAY(), NOW() >= 'MATCH DATES'!$A$9 + TIME(22, 0, 0)), CO8, 0) ) -> 5 | DD8: =SUM(K8,W8,AI8,AU8,BG8,BS8,CE8,CQ8) -> 0 | DF8: =SUM(L8,X8,AJ8,AV8,BH8,BT8,CF8,CR8) -> 0
